Workbook

Sheet Dashboard (2)
A1: ISZE — FY2027 GPS Extended Target | K1: GPS stretch FY27 (pt) | N1: 0.018 | O1: Cap at 100%? YES/NO | Q1: NO | R1: Price FY28-31 / yr | T1: 0.03 | V1: Blue / yellow = input. Q1 = NO: the same stretch for every distributor. Q1 = YES: stretch capped so no GPS share passes 100%.
A2: ISZE to distributor level. Stretch inputs on Dashboard (2) row 1. Every number on this sheet is live. | K2: GPS stretch FY28-31 / yr (pt) | N2: 0.01 | V2: FY27 stretch must stay >= ~1.1% to cover the EUR 952K the waterfall needs (Dashboard C25).
K3: 2025年度 | L3: FY2026 | Q3: 販社 = distributor sales to its dealers. Amounts only: KPI sales-to-dealer run 2.2-3.7x ISZE billing, so a share would read above 100%. | U3: 2026年度 | V3: FY2027 | AE3: 2027年度 | AF3: FY2028 | AO3: 2028年度 | AP3: FY2029 | AY3: 2029年度 | AZ3: FY2030 | BI3: 2030年度 | BJ3: FY2031
A4: DB | B4: Segment | C4: BP FY27 | D4: Max spend | E4: GPS % | F4: Stretch% | G4: Stretch EUR | H4: New GPS | I4: EXT TARGET | J4: Note | K4: ISZE台当たり単価 | M4: UIO | N4: ISZE部品販売 ポテンシャル | O4: ISZE部品売上実績 | P4: ISZE部品カバー率 (実績) | Q4: 販社台当たり単価 | R4: 販社部品販売ポテンシャル | S4: 販社部品販売 (実績) | T4: 販社部品カバー率 (実績) | U4: ISZE台当たり単価 | W4: UIO | X4: ISZE 部品販売 ポテンシャル | Y4: ISZE 部品カバー率 (目標) | Z4: ISZE部品売上目標 | AA4: 販社台当たり単価 | AB4: 販社部品販売ポテンシャル | AC4: 販社部品販売目標 | AD4: 販社部品カバー率(目標) | AE4: ISZE台当たり単価 | AG4: UIO | AH4: ISZE 部品販売 ポテンシャル | AI4: ISZE 部品カバー率 (目標) | AJ4: ISZE部品売上目標 | AK4: 販社台当たり単価 | AL4: 販社部品販売ポテンシャル | AM4: 販社部品販売目標 | AN4: 販社部品カバー率(目標) | AO4: ISZE台当たり単価 | AQ4: UIO | AR4: ISZE 部品販売 ポテンシャル | AS4: ISZE 部品カバー率 (目標) | AT4: ISZE部品売上目標 | AU4: 販社台当たり単価 | AV4: 販社部品販売ポテンシャル | AW4: 販社部品販売目標 | AX4: 販社部品カバー率(目標) | AY4: ISZE台当たり単価 | BA4: UIO | BB4: ISZE 部品販売 ポテンシャル | BC4: ISZE 部品カバー率 (目標) | BD4: ISZE部品売上目標 | BE4: 販社台当たり単価 | BF4: 販社部品販売ポテンシャル | BG4: 販社部品販売目標 | BH4: 販社部品カバー率(目標) | BI4: ISZE台当たり単価 | BK4: UIO | BL4: ISZE 部品販売 ポテンシャル | BM4: ISZE 部品カバー率 (目標) | BN4: ISZE部品売上目標 | BO4: 販社台当たり単価 | BP4: 販社部品販売ポテンシャル | BQ4: 販社部品販売目標 | BR4: 販社部品カバー率(目標)
K5: ISZE Parts Sales per Unit | N5: ISZE Parts Sles Potential | O5: ISZE Parts Sales Actual | P5: ISZE Share Actual | Q5: Distributor's Parts Sales per Unit | R5: Distributor's Parts Sales Potential | S5: Distributor Parts Sales Actual | T5: Dist Parts Share Actual | U5: ISZE Parts Sales per Unit | X5: ISZE Parts Sles Potential | Y5: ISZE Target Share | Z5: ISZE Parts Sales Target | AA5: Distributor's Parts Sales per Unit | AB5: Distributor's Parts Sales Potential | AC5: Distributor Parts Sales Target | AD5: Distributor Parts Share target | AE5: ISZE Parts Sales per Unit | AH5: ISZE Parts Sles Potential | AI5: ISZE Target Share | AJ5: ISZE Parts Sales Target | AK5: Distributor's Parts Sales per Unit | AL5: Distributor's Parts Sales Potential | AM5: Distributor Parts Sales Target | AN5: Distributor Parts Share target | AO5: ISZE Parts Sales per Unit | AR5: ISZE Parts Sles Potential | AS5: ISZE Target Share | AT5: ISZE Parts Sales Target | AU5: Distributor's Parts Sales per Unit | AV5: Distributor's Parts Sales Potential | AW5: Distributor Parts Sales Target | AX5: Distributor Parts Share target | AY5: ISZE Parts Sales per Unit | BB5: ISZE Parts Sles Potential | BC5: ISZE Target Share | BD5: ISZE Parts Sales Target | BE5: Distributor's Parts Sales per Unit | BF5: Distributor's Parts Sales Potential | BG5: Distributor Parts Sales Target | BH5: Distributor Parts Share target | BI5: ISZE Parts Sales per Unit | BL5: ISZE Parts Sles Potential | BM5: ISZE Target Share | BN5: ISZE Parts Sales Target | BO5: Distributor's Parts Sales per Unit | BP5: Distributor's Parts Sales Potential | BQ5: Distributor Parts Sales Target | BR5: Distributor Parts Share target
A6: ITUK | B6: presented | C6: =Dashboard!C5 -> 6974170.1 | D6: =Dashboard!D5 -> 12535797 | E6: =Dashboard!E5 -> 0.55634037 | F6: =Dashboard!F5 -> 0 | G6: =Dashboard!G5 -> 376073.91 | H6: =Dashboard!H5 -> 0 | I6: =Dashboard!I5 -> 7350244 | J6: Max spend on IML data (2026 vehicles, +5%); target as presented in July | K6: N35 | L6: 281.6 | M6: 11444 | N6: =L6*M6 -> 3222630.4 | Q6: =Inputs!$C$13 -> 448 | R6: =Q6*M6 -> 5126912 | U6: N35 | V6: =L6*(1+Inputs!$B$9) -> 295.68 | W6: 12345 | X6: =V6*W6 -> 3650169.6 | AA6: =Q6*(1+Inputs!$B$11) -> 461.44 | AB6: =AA6*W6 -> 5696476.8 | AE6: N35 | AF6: =V6*(1+'Dashboard (2)'!$T$1) -> 304.5504 | AG6: =ROUND(Inputs!E26*($W$6/($W$6+$W$7)),0) -> 12944 | AH6: =AF6*AG6 -> 3942100.4 | AK6: =AA6*(1+'Dashboard (2)'!$T$1) -> 475.2832 | AL6: =AK6*AG6 -> 6152065.7 | AO6: N35 | AP6: =AF6*(1+'Dashboard (2)'!$T$1) -> 313.68691 | AQ6: =ROUND(Inputs!F26*($W$6/($W$6+$W$7)),0) -> 13453 | AR6: =AP6*AQ6 -> 4220030 | AU6: =AK6*(1+'Dashboard (2)'!$T$1) -> 489.5417 | AV6: =AU6*AQ6 -> 6585804.4 | AY6: N35 | AZ6: =AP6*(1+'Dashboard (2)'!$T$1) -> 323.09752 | BA6: =ROUND(Inputs!G26*($W$6/($W$6+$W$7)),0) -> 13907 | BB6: =AZ6*BA6 -> 4493317.2 | BE6: =AU6*(1+'Dashboard (2)'!$T$1) -> 504.22795 | BF6: =BE6*BA6 -> 7012298.1 | BI6: N35 | BJ6: =AZ6*(1+'Dashboard (2)'!$T$1) -> 332.79044 | BK6: =ROUND(Inputs!H26*($W$6/($W$6+$W$7)),0) -> 14320 | BL6: =BJ6*BK6 -> 4765559.2 | BO6: =BE6*(1+'Dashboard (2)'!$T$1) -> 519.35479 | BP6: =BO6*BK6 -> 7437160.5
K7: N75 | L7: 704 | M7: 10747 | N7: =L7*M7 -> 7565888 | Q7: =Inputs!$C$14 -> 1120 | R7: =Q7*M7 -> 12036640 | U7: N75 | V7: =L7*(1+Inputs!$B$9) -> 739.2 | W7: 10865 | X7: =V7*W7 -> 8031408 | AA7: =Q7*(1+Inputs!$B$11) -> 1153.6 | AB7: =AA7*W7 -> 12533864 | AE7: N75 | AF7: =V7*(1+'Dashboard (2)'!$T$1) -> 761.376 | AG7: =Inputs!E26-AG6 -> 11392 | AH7: =AF7*AG7 -> 8673595.4 | AK7: =AA7*(1+'Dashboard (2)'!$T$1) -> 1188.208 | AL7: =AK7*AG7 -> 13536066 | AO7: N75 | AP7: =AF7*(1+'Dashboard (2)'!$T$1) -> 784.21728 | AQ7: =Inputs!F26-AQ6 -> 11841 | AR7: =AP7*AQ7 -> 9285916.8 | AU7: =AK7*(1+'Dashboard (2)'!$T$1) -> 1223.8542 | AV7: =AU7*AQ7 -> 14491658 | AY7: N75 | AZ7: =AP7*(1+'Dashboard (2)'!$T$1) -> 807.7438 | BA7: =Inputs!G26-BA6 -> 12239 | BB7: =AZ7*BA7 -> 9885976.3 | BE7: =AU7*(1+'Dashboard (2)'!$T$1) -> 1260.5699 | BF7: =BE7*BA7 -> 15428115 | BI7: N75 | BJ7: =AZ7*(1+'Dashboard (2)'!$T$1) -> 831.97611 | BK7: =Inputs!H26-BK6 -> 12603 | BL7: =BJ7*BK7 -> 10485395 | BO7: =BE7*(1+'Dashboard (2)'!$T$1) -> 1298.387 | BP7: =BO7*BK7 -> 16363571
K8: F | L8: 844.8 | M8: 877 | N8: =L8*M8 -> 740889.6 | Q8: =Inputs!$C$15 -> 1344 | R8: =Q8*M8 -> 1178688 | U8: F | V8: =L8*(1+Inputs!$B$9) -> 887.04 | W8: 963 | X8: =V8*W8 -> 854219.52 | AA8: =Q8*(1+Inputs!$B$11) -> 1384.32 | AB8: =AA8*W8 -> 1333100.2 | AE8: F | AF8: =V8*(1+'Dashboard (2)'!$T$1) -> 913.6512 | AG8: =Inputs!E27 -> 1055 | AH8: =AF8*AG8 -> 963902.02 | AK8: =AA8*(1+'Dashboard (2)'!$T$1) -> 1425.8496 | AL8: =AK8*AG8 -> 1504271.3 | AO8: F | AP8: =AF8*(1+'Dashboard (2)'!$T$1) -> 941.06074 | AQ8: =Inputs!F27 -> 1141 | AR8: =AP8*AQ8 -> 1073750.3 | AU8: =AK8*(1+'Dashboard (2)'!$T$1) -> 1468.6251 | AV8: =AU8*AQ8 -> 1675701.2 | AY8: F | AZ8: =AP8*(1+'Dashboard (2)'!$T$1) -> 969.29256 | BA8: =Inputs!G27 -> 1218 | BB8: =AZ8*BA8 -> 1180598.3 | BE8: =AU8*(1+'Dashboard (2)'!$T$1) -> 1512.6838 | BF8: =BE8*BA8 -> 1842448.9 | BI8: F | BJ8: =AZ8*(1+'Dashboard (2)'!$T$1) -> 998.37133 | BK8: =Inputs!H27 -> 1286 | BL8: =BJ8*BK8 -> 1283905.5 | BO8: =BE8*(1+'Dashboard (2)'!$T$1) -> 1558.0644 | BP8: =BO8*BK8 -> 2003670.8
M9: =SUM(M6:M8) -> 23068 | N9: =SUM(N6:N8) -> 11529408 | O9: 6805719.6 | P9: =O9/N9 -> 0.5902922 | R9: =SUM(R6:R8) -> 18342240 | S9: =Inputs!$B$34*Inputs!$B$16 -> 14418877 | T9: =S9/R9 -> 0.78610232 | W9: =SUM(W6:W8) -> 24173 | X9: =SUM(X6:X8) -> 12535797 | Y9: =Z9/X9 -> 0.58634037 | Z9: =Dashboard!I5 -> 7350244 | AB9: =SUM(AB6:AB8) -> 19563441 | AC9: =AB9*AD9 -> 15731008 | AD9: =IF(T9>=Inputs!$B$38,T9,MIN(T9+'Dashboard (2)'!$N$1,Inputs!$B$38)) -> 0.80410232 | AG9: =SUM(AG6:AG8) -> 25391 | AH9: =SUM(AH6:AH8) -> 13579598 | AI9: =IF(Y9>=Inputs!$B$38,Y9,MIN(Y9+'Dashboard (2)'!$N$2,Inputs!$B$38)) -> 0.59634037 | AJ9: =AH9*AI9 -> 8098062.4 | AL9: =SUM(AL6:AL8) -> 21192403 | AM9: =AL9*AN9 -> 17252784 | AN9: =IF(AD9>=Inputs!$B$38,AD9,MIN(AD9+'Dashboard (2)'!$N$2,Inputs!$B$38)) -> 0.81410232 | AQ9: =SUM(AQ6:AQ8) -> 26435 | AR9: =SUM(AR6:AR8) -> 14579697 | AS9: =IF(AI9>=Inputs!$B$38,AI9,MIN(AI9+'Dashboard (2)'!$N$2,Inputs!$B$38)) -> 0.60634037 | AT9: =AR9*AS9 -> 8840259 | AV9: =SUM(AV6:AV8) -> 22753164 | AW9: =AV9*AX9 -> 18750935 | AX9: =IF(AN9>=Inputs!$B$38,AN9,MIN(AN9+'Dashboard (2)'!$N$2,Inputs!$B$38)) -> 0.82410232 | BA9: =SUM(BA6:BA8) -> 27364 | BB9: =SUM(BB6:BB8) -> 15559892 | BC9: =IF(AS9>=Inputs!$B$38,AS9,MIN(AS9+'Dashboard (2)'!$N$2,Inputs!$B$38)) -> 0.61634037 | BD9: =BB9*BC9 -> 9590189.6 | BF9: =SUM(BF6:BF8) -> 24282862 | BG9: =BF9*BH9 -> 20254391 | BH9: =IF(AX9>=Inputs!$B$38,AX9,MIN(AX9+'Dashboard (2)'!$N$2,Inputs!$B$38)) -> 0.83410232 | BK9: =SUM(BK6:BK8) -> 28209 | BL9: =SUM(BL6:BL8) -> 16534860 | BM9: =IF(BC9>=Inputs!$B$38,BC9,MIN(BC9+'Dashboard (2)'!$N$2,Inputs!$B$38)) -> 0.62634037 | BN9: =BL9*BM9 -> 10356450 | BP9: =SUM(BP6:BP8) -> 25804402 | BQ9: =BP9*BR9 -> 21781556 | BR9: =IF(BH9>=Inputs!$B$38,BH9,MIN(BH9+'Dashboard (2)'!$N$2,Inputs!$B$38)) -> 0.84410232
A10: UTI | B10: presented | C10: =Dashboard!C6 -> 3098113.5 | D10: =Dashboard!D6 -> 8485129 | E10: =Dashboard!E6 -> 0.36512274 | F10: =Dashboard!F6 -> 0 | G10: =Dashboard!G6 -> 159024.46 | H10: =Dashboard!H6 -> 0 | I10: =Dashboard!I6 -> 3257138 | J10: Max spend on IML data (2026 vehicles, +5%); target as presented in July | K10: CV | L10: =V10/(1+Inputs!$B$9) -> 751.02929 | M10: 10336 | N10: =L10*M10 -> 7762638.8 | O10: 3056797.1 | P10: =O10/N10 -> 0.39378324 | Q10: =IFERROR(R10/(Inputs!C29+Inputs!C30),0) -> 1212.6904 | R10: =Inputs!$C$14*Inputs!C29+Inputs!$C$15*Inputs!C30 -> 12534368 | S10: =IF(ISNUMBER(Dashboard!Q6),Dashboard!Q6,"no KPI data") -> no KPI data | T10: n/a | U10: CV | V10: =X10/W10 -> 788.58076 | W10: 10760 | X10: 8485129 | Y10: =Z10/X10 -> 0.38386428 | Z10: =Dashboard!I6 -> 3257138 | AA10: =IFERROR(AB10/(Inputs!D29+Inputs!D30),0) -> 1277.8399 | AB10: =Inputs!$C$14*(1+Inputs!$B$9)*Inputs!D29+Inputs!$C$15*(1+Inputs!$B$9)*Inputs!D30 -> 13749557 | AC10: =IF(ISNUMBER(S10),S10+Dashboard!G6/(1-Inputs!$B$18),"no KPI data") -> no KPI data | AD10: n/a | AE10: CV | AF10: =V10*(1+'Dashboard (2)'!$T$1) -> 812.23818 | AG10: =Inputs!E29+Inputs!E30 -> 10972 | AH10: =AF10*AG10 -> 8911877.3 | AI10: =IF(Y10>=Inputs!$B$38,Y10,MIN(Y10+'Dashboard (2)'!$N$2,Inputs!$B$38)) -> 0.39386428 | AJ10: =AH10*AI10 -> 3510070.2 | AK10: =IFERROR(AL10/(Inputs!E29+Inputs!E30),0) -> 1319.6461 | AL10: =Inputs!$C$14*(1+Inputs!$B$9)*(1+'Dashboard (2)'!$T$1)*Inputs!E29+Inputs!$C$15*(1+Inputs!$B$9)*(1+'Dashboard (2)'!$T$1)*Inputs!E30 -> 14479157 | AM10: =IF(ISNUMBER(AC10),AC10*AJ10/Z10,"no KPI data") -> no KPI data | AN10: n/a | AO10: CV | AP10: =AF10*(1+'Dashboard (2)'!$T$1) -> 836.60533 | AQ10: =Inputs!F29+Inputs!F30 -> 11280 | AR10: =AP10*AQ10 -> 9436908.1 | AS10: =IF(AI10>=Inputs!$B$38,AI10,MIN(AI10+'Dashboard (2)'!$N$2,Inputs!$B$38)) -> 0.40386428 | AT10: =AR10*AS10 -> 3811230.1 | AU10: =IFERROR(AV10/(Inputs!F29+Inputs!F30),0) -> 1362.3595 | AV10: =Inputs!$C$14*(1+Inputs!$B$9)*(1+'Dashboard (2)'!$T$1)*(1+'Dashboard (2)'!$T$1)*Inputs!F29+Inputs!$C$15*(1+Inputs!$B$9)*(1+'Dashboard (2)'!$T$1)*(1+'Dashboard (2)'!$T$1)*Inputs!F30 -> 15367415 | AW10: =IF(ISNUMBER(AM10),AM10*AT10/AJ10,"no KPI data") -> no KPI data | AX10: n/a | AY10: CV | AZ10: =AP10*(1+'Dashboard (2)'!$T$1) -> 861.70349 | BA10: =Inputs!G29+Inputs!G30 -> 11581 | BB10: =AZ10*BA10 -> 9979388.1 | BC10: =IF(AS10>=Inputs!$B$38,AS10,MIN(AS10+'Dashboard (2)'!$N$2,Inputs!$B$38)) -> 0.41386428 | BD10: =BB10*BC10 -> 4130112.3 | BE10: =IFERROR(BF10/(Inputs!G29+Inputs!G30),0) -> 1406.4612 | BF10: =Inputs!$C$14*(1+Inputs!$B$9)*(1+'Dashboard (2)'!$T$1)*(1+'Dashboard (2)'!$T$1)*(1+'Dashboard (2)'!$T$1)*Inputs!G29+Inputs!$C$15*(1+Inputs!$B$9)*(1+'Dashboard (2)'!$T$1)*(1+'Dashboard (2)'!$T$1)*(1+'Dashboard (2)'!$T$1)*Inputs!G30 -> 16288227 | BG10: =IF(ISNUMBER(AW10),AW10*BD10/AT10,"no KPI data") -> no KPI data | BH10: n/a | BI10: CV | BJ10: =AZ10*(1+'Dashboard (2)'!$T$1) -> 887.55459 | BK10: =Inputs!H29+Inputs!H30 -> 11882 | BL10: =BJ10*BK10 -> 10545924 | BM10: =IF(BC10>=Inputs!$B$38,BC10,MIN(BC10+'Dashboard (2)'!$N$2,Inputs!$B$38)) -> 0.42386428 | BN10: =BL10*BM10 -> 4470040.4 | BO10: =IFERROR(BP10/(Inputs!H29+Inputs!H30),0) -> 1451.8811 | BP10: =Inputs!$C$14*(1+Inputs!$B$9)*(1+'Dashboard (2)'!$T$1)*(1+'Dashboard (2)'!$T$1)*(1+'Dashboard (2)'!$T$1)*(1+'Dashboard (2)'!$T$1)*Inputs!H29+Inputs!$C$15*(1+Inputs!$B$9)*(1+'Dashboard (2)'!$T$1)*(1+'Dashboard (2)'!$T$1)*(1+'Dashboard (2)'!$T$1)*(1+'Dashboard (2)'!$T$1)*Inputs!H30 -> 17251252 | BQ10: =IF(ISNUMBER(BG10),BG10*BN10/BD10,"no KPI data") -> no KPI data | BR10: n/a
A11: IUK | B11: LCV | C11: =Dashboard!C7 -> 6062956.5 | D11: =Dashboard!D7 -> 12936000 | E11: =Dashboard!E7 -> 0.46868866 | F11: =Dashboard!F7 -> 0.018 | G11: =Dashboard!G7 -> 232848 | H11: =Dashboard!H7 -> 0.48668866 | I11: =Dashboard!I7 -> 6295804.5 | K11: LCV | L11: =IUK!D14 -> 250 | M11: =IUK!D9 -> 47783 | N11: =L11*M11 -> 11945750 | O11: =IUK!D20 -> 5895486.2 | P11: =O11/N11 -> 0.49352165 | Q11: =Inputs!$C$13 -> 448 | R11: =Q11*M11 -> 21406784 | S11: =IF(ISNUMBER(Dashboard!Q7),Dashboard!Q7,"no KPI data") -> 21418279 | T11: n/a | U11: LCV | V11: =IUK!E14 -> 262.5 | W11: =IUK!E9 -> 49280 | X11: =V11*W11 -> 12936000 | Y11: =Z11/X11 -> 0.48668866 | Z11: =IUK!E24 -> 6295804.5 | AA11: =Inputs!$C$13*(1+Inputs!$B$9) -> 470.4 | AB11: =AA11*W11 -> 23181312 | AC11: =IF(ISNUMBER(S11),S11+Dashboard!G7/(1-Inputs!$B$18),"no KPI data") -> 21776507 | AD11: n/a | AE11: LCV | AF11: =IUK!F14 -> 270.375 | AG11: =IUK!F9 -> 50202 | AH11: =AF11*AG11 -> 13573366 | AI11: =IF(Y11>=Inputs!$B$38,Y11,MIN(Y11+'Dashboard (2)'!$N$2,Inputs!$B$38)) -> 0.49668866 | AJ11: =AH11*AI11 -> 6741736.8 | AK11: =Inputs!$C$13*(1+Inputs!$B$9)*(1+'Dashboard (2)'!$T$1) -> 484.512 | AL11: =AK11*AG11 -> 24323471 | AM11: =IF(ISNUMBER(AC11),AC11*AJ11/Z11,"no KPI data") -> 23318938 | AN11: n/a | AO11: LCV | AP11: =IUK!G14 -> 278.48625 | AQ11: =IUK!G9 -> 51096 | AR11: =AP11*AQ11 -> 14229533 | AS11: =IF(AI11>=Inputs!$B$38,AI11,MIN(AI11+'Dashboard (2)'!$N$2,Inputs!$B$38)) -> 0.50668866 | AT11: =AR11*AS11 -> 7209943.2 | AU11: =Inputs!$C$13*(1+Inputs!$B$9)*(1+'Dashboard (2)'!$T$1)*(1+'Dashboard (2)'!$T$1) -> 499.04736 | AV11: =AU11*AQ11 -> 25499324 | AW11: =IF(ISNUMBER(AM11),AM11*AT11/AJ11,"no KPI data") -> 24938414 | AX11: n/a | AY11: LCV | AZ11: =IUK!H14 -> 286.84084 | BA11: =IUK!H9 -> 51963 | BB11: =AZ11*BA11 -> 14905110 | BC11: =IF(AS11>=Inputs!$B$38,AS11,MIN(AS11+'Dashboard (2)'!$N$2,Inputs!$B$38)) -> 0.51668866 | BD11: =BB11*BC11 -> 7701301.5 | BE11: =Inputs!$C$13*(1+Inputs!$B$9)*(1+'Dashboard (2)'!$T$1)*(1+'Dashboard (2)'!$T$1)*(1+'Dashboard (2)'!$T$1) -> 514.01878 | BF11: =BE11*BA11 -> 26709958 | BG11: =IF(ISNUMBER(AW11),AW11*BD11/AT11,"no KPI data") -> 26637969 | BH11: n/a | BI11: LCV | BJ11: =IUK!I14 -> 295.44606 | BK11: =IUK!I9 -> 52804 | BL11: =BJ11*BK11 -> 15600734 | BM11: =IF(BC11>=Inputs!$B$38,BC11,MIN(BC11+'Dashboard (2)'!$N$2,Inputs!$B$38)) -> 0.52668866 | BN11: =BL11*BM11 -> 8216729.6 | BO11: =Inputs!$C$13*(1+Inputs!$B$9)*(1+'Dashboard (2)'!$T$1)*(1+'Dashboard (2)'!$T$1)*(1+'Dashboard (2)'!$T$1)*(1+'Dashboard (2)'!$T$1) -> 529.43934 | BP11: =BO11*BK11 -> 27956515 | BQ11: =IF(ISNUMBER(BG11),BG11*BN11/BD11,"no KPI data") -> 28420779 | BR11: n/a
A12: UMI | B12: LCV | C12: =Dashboard!C8 -> 2973279.3 | D12: =Dashboard!D8 -> 4957575 | E12: =Dashboard!E8 -> 0.5997447 | F12: =Dashboard!F8 -> 0.018 | G12: =Dashboard!G8 -> 89236.35 | H12: =Dashboard!H8 -> 0.6177447 | I12: =Dashboard!I8 -> 3062515.7 | K12: LCV | L12: =UMI!D14 -> 250 | M12: =UMI!D9 -> 18542 | N12: =L12*M12 -> 4635500 | O12: =UMI!D20 -> 2445335.2 | P12: =O12/N12 -> 0.52752351 | Q12: =Inputs!$C$13 -> 448 | R12: =Q12*M12 -> 8306816 | S12: =IF(ISNUMBER(Dashboard!Q8),Dashboard!Q8,"no KPI data") -> no KPI data | T12: n/a | U12: LCV | V12: =UMI!E14 -> 262.5 | W12: =UMI!E9 -> 18886 | X12: =V12*W12 -> 4957575 | Y12: =Z12/X12 -> 0.6177447 | Z12: =UMI!E24 -> 3062515.7 | AA12: =Inputs!$C$13*(1+Inputs!$B$9) -> 470.4 | AB12: =AA12*W12 -> 8883974.4 | AC12: =IF(ISNUMBER(S12),S12+Dashboard!G8/(1-Inputs!$B$18),"no KPI data") -> no KPI data | AD12: n/a | AE12: LCV | AF12: =UMI!F14 -> 270.375 | AG12: =UMI!F9 -> 19319 | AH12: =AF12*AG12 -> 5223374.6 | AI12: =IF(Y12>=Inputs!$B$38,Y12,MIN(Y12+'Dashboard (2)'!$N$2,Inputs!$B$38)) -> 0.6277447 | AJ12: =AH12*AI12 -> 3278945.7 | AK12: =Inputs!$C$13*(1+Inputs!$B$9)*(1+'Dashboard (2)'!$T$1) -> 484.512 | AL12: =AK12*AG12 -> 9360287.3 | AM12: =IF(ISNUMBER(AC12),AC12*AJ12/Z12,"no KPI data") -> no KPI data | AN12: n/a | AO12: LCV | AP12: =UMI!G14 -> 278.48625 | AQ12: =UMI!G9 -> 19669 | AR12: =AP12*AQ12 -> 5477546.1 | AS12: =IF(AI12>=Inputs!$B$38,AI12,MIN(AI12+'Dashboard (2)'!$N$2,Inputs!$B$38)) -> 0.6377447 | AT12: =AR12*AS12 -> 3493276 | AU12: =Inputs!$C$13*(1+Inputs!$B$9)*(1+'Dashboard (2)'!$T$1)*(1+'Dashboard (2)'!$T$1) -> 499.04736 | AV12: =AU12*AQ12 -> 9815762.5 | AW12: =IF(ISNUMBER(AM12),AM12*AT12/AJ12,"no KPI data") -> no KPI data | AX12: n/a | AY12: LCV | AZ12: =UMI!H14 -> 286.84084 | BA12: =UMI!H9 -> 20009 | BB12: =AZ12*BA12 -> 5739398.3 | BC12: =IF(AS12>=Inputs!$B$38,AS12,MIN(AS12+'Dashboard (2)'!$N$2,Inputs!$B$38)) -> 0.6477447 | BD12: =BB12*BC12 -> 3717664.8 | BE12: =Inputs!$C$13*(1+Inputs!$B$9)*(1+'Dashboard (2)'!$T$1)*(1+'Dashboard (2)'!$T$1)*(1+'Dashboard (2)'!$T$1) -> 514.01878 | BF12: =BE12*BA12 -> 10285002 | BG12: =IF(ISNUMBER(AW12),AW12*BD12/AT12,"no KPI data") -> no KPI data | BH12: n/a | BI12: LCV | BJ12: =UMI!I14 -> 295.44606 | BK12: =UMI!I9 -> 20339 | BL12: =BJ12*BK12 -> 6009077.5 | BM12: =IF(BC12>=Inputs!$B$38,BC12,MIN(BC12+'Dashboard (2)'!$N$2,Inputs!$B$38)) -> 0.6577447 | BN12: =BL12*BM12 -> 3952438.9 | BO12: =Inputs!$C$13*(1+Inputs!$B$9)*(1+'Dashboard (2)'!$T$1)*(1+'Dashboard (2)'!$T$1)*(1+'Dashboard (2)'!$T$1)*(1+'Dashboard (2)'!$T$1) -> 529.43934 | BP12: =BO12*BK12 -> 10768267 | BQ12: =IF(ISNUMBER(BG12),BG12*BN12/BD12,"no KPI data") -> no KPI data | BR12: n/a
A13: NORWAY | B13: LCV | C13: =Dashboard!C9 -> 1764799.8 | D13: =Dashboard!D9 -> 2129137.5 | E13: =Dashboard!E9 -> 0.82888012 | F13: =Dashboard!F9 -> 0.018 | G13: =Dashboard!G9 -> 38324.475 | H13: =Dashboard!H9 -> 0.84688012 | I13: =Dashboard!I9 -> 1803124.2 | K13: LCV | L13: =NORWAY!D14 -> 250 | M13: =NORWAY!D9 -> 7929 | N13: =L13*M13 -> 1982250 | O13: =NORWAY!D20 -> 1471434.2 | P13: =O13/N13 -> 0.74230506 | Q13: =Inputs!$C$13 -> 448 | R13: =Q13*M13 -> 3552192 | S13: =IF(ISNUMBER(Dashboard!Q9),Dashboard!Q9,"no KPI data") -> 5248795 | T13: n/a | U13: LCV | V13: =NORWAY!E14 -> 262.5 | W13: =NORWAY!E9 -> 8111 | X13: =V13*W13 -> 2129137.5 | Y13: =Z13/X13 -> 0.84688012 | Z13: =NORWAY!E24 -> 1803124.2 | AA13: =Inputs!$C$13*(1+Inputs!$B$9) -> 470.4 | AB13: =AA13*W13 -> 3815414.4 | AC13: =IF(ISNUMBER(S13),S13+Dashboard!G9/(1-Inputs!$B$18),"no KPI data") -> 5307755.7 | AD13: n/a | AE13: LCV | AF13: =NORWAY!F14 -> 270.375 | AG13: =NORWAY!F9 -> 8218 | AH13: =AF13*AG13 -> 2221941.8 | AI13: =IF(Y13>=Inputs!$B$38,Y13,MIN(Y13+'Dashboard (2)'!$N$2,Inputs!$B$38)) -> 0.85688012 | AJ13: =AH13*AI13 -> 1903937.7 | AK13: =Inputs!$C$13*(1+Inputs!$B$9)*(1+'Dashboard (2)'!$T$1) -> 484.512 | AL13: =AK13*AG13 -> 3981719.6 | AM13: =IF(ISNUMBER(AC13),AC13*AJ13/Z13,"no KPI data") -> 5604514.8 | AN13: n/a | AO13: LCV | AP13: =NORWAY!G14 -> 278.48625 | AQ13: =NORWAY!G9 -> 8426 | AR13: =AP13*AQ13 -> 2346525.1 | AS13: =IF(AI13>=Inputs!$B$38,AI13,MIN(AI13+'Dashboard (2)'!$N$2,Inputs!$B$38)) -> 0.86688012 | AT13: =AR13*AS13 -> 2034156 | AU13: =Inputs!$C$13*(1+Inputs!$B$9)*(1+'Dashboard (2)'!$T$1)*(1+'Dashboard (2)'!$T$1) -> 499.04736 | AV13: =AU13*AQ13 -> 4204973.1 | AW13: =IF(ISNUMBER(AM13),AM13*AT13/AJ13,"no KPI data") -> 5987831 | AX13: n/a | AY13: LCV | AZ13: =NORWAY!H14 -> 286.84084 | BA13: =NORWAY!H9 -> 8628 | BB13: =AZ13*BA13 -> 2474862.7 | BC13: =IF(AS13>=Inputs!$B$38,AS13,MIN(AS13+'Dashboard (2)'!$N$2,Inputs!$B$38)) -> 0.87688012 | BD13: =BB13*BC13 -> 2170157.9 | BE13: =Inputs!$C$13*(1+Inputs!$B$9)*(1+'Dashboard (2)'!$T$1)*(1+'Dashboard (2)'!$T$1)*(1+'Dashboard (2)'!$T$1) -> 514.01878 | BF13: =BE13*BA13 -> 4434954 | BG13: =IF(ISNUMBER(AW13),AW13*BD13/AT13,"no KPI data") -> 6388172.3 | BH13: n/a | BI13: LCV | BJ13: =NORWAY!I14 -> 295.44606 | BK13: =NORWAY!I9 -> 8824 | BL13: =BJ13*BK13 -> 2607016.1 | BM13: =IF(BC13>=Inputs!$B$38,BC13,MIN(BC13+'Dashboard (2)'!$N$2,Inputs!$B$38)) -> 0.88688012 | BN13: =BL13*BM13 -> 2312110.7 | BO13: =Inputs!$C$13*(1+Inputs!$B$9)*(1+'Dashboard (2)'!$T$1)*(1+'Dashboard (2)'!$T$1)*(1+'Dashboard (2)'!$T$1)*(1+'Dashboard (2)'!$T$1) -> 529.43934 | BP13: =BO13*BK13 -> 4671772.8 | BQ13: =IF(ISNUMBER(BG13),BG13*BN13/BD13,"no KPI data") -> 6806030.7 | BR13: n/a
A14: SWEDEN | B14: LCV | C14: =Dashboard!C10 -> 1464302.3 | D14: =Dashboard!D10 -> 2386125 | E14: =Dashboard!E10 -> 0.61367377 | F14: =Dashboard!F10 -> 0.018 | G14: =Dashboard!G10 -> 42950.25 | H14: =Dashboard!H10 -> 0.63167377 | I14: =Dashboard!I10 -> 1507252.6 | K14: LCV | L14: =SWEDEN!D14 -> 250 | M14: =SWEDEN!D9 -> 8443 | N14: =L14*M14 -> 2110750 | O14: =SWEDEN!D20 -> 1298276 | P14: =O14/N14 -> 0.61507805 | Q14: =Inputs!$C$13 -> 448 | R14: =Q14*M14 -> 3782464 | S14: =IF(ISNUMBER(Dashboard!Q10),Dashboard!Q10,"no KPI data") -> 3154222 | T14: n/a | U14: LCV | V14: =SWEDEN!E14 -> 262.5 | W14: =SWEDEN!E9 -> 9090 | X14: =V14*W14 -> 2386125 | Y14: =Z14/X14 -> 0.63167377 | Z14: =SWEDEN!E24 -> 1507252.6 | AA14: =Inputs!$C$13*(1+Inputs!$B$9) -> 470.4 | AB14: =AA14*W14 -> 4275936 | AC14: =IF(ISNUMBER(S14),S14+Dashboard!G10/(1-Inputs!$B$18),"no KPI data") -> 3220299.3 | AD14: n/a | AE14: LCV | AF14: =SWEDEN!F14 -> 270.375 | AG14: =SWEDEN!F9 -> 9737 | AH14: =AF14*AG14 -> 2632641.4 | AI14: =IF(Y14>=Inputs!$B$38,Y14,MIN(Y14+'Dashboard (2)'!$N$2,Inputs!$B$38)) -> 0.64167377 | AJ14: =AH14*AI14 -> 1689296.9 | AK14: =Inputs!$C$13*(1+Inputs!$B$9)*(1+'Dashboard (2)'!$T$1) -> 484.512 | AL14: =AK14*AG14 -> 4717693.3 | AM14: =IF(ISNUMBER(AC14),AC14*AJ14/Z14,"no KPI data") -> 3609243.6 | AN14: n/a | AO14: LCV | AP14: =SWEDEN!G14 -> 278.48625 | AQ14: =SWEDEN!G9 -> 10320 | AR14: =AP14*AQ14 -> 2873978.1 | AS14: =IF(AI14>=Inputs!$B$38,AI14,MIN(AI14+'Dashboard (2)'!$N$2,Inputs!$B$38)) -> 0.65167377 | AT14: =AR14*AS14 -> 1872896.2 | AU14: =Inputs!$C$13*(1+Inputs!$B$9)*(1+'Dashboard (2)'!$T$1)*(1+'Dashboard (2)'!$T$1) -> 499.04736 | AV14: =AU14*AQ14 -> 5150168.8 | AW14: =IF(ISNUMBER(AM14),AM14*AT14/AJ14,"no KPI data") -> 4001509.9 | AX14: n/a | AY14: LCV | AZ14: =SWEDEN!H14 -> 286.84084 | BA14: =SWEDEN!H9 -> 10885 | BB14: =AZ14*BA14 -> 3122262.5 | BC14: =IF(AS14>=Inputs!$B$38,AS14,MIN(AS14+'Dashboard (2)'!$N$2,Inputs!$B$38)) -> 0.66167377 | BD14: =BB14*BC14 -> 2065919.2 | BE14: =Inputs!$C$13*(1+Inputs!$B$9)*(1+'Dashboard (2)'!$T$1)*(1+'Dashboard (2)'!$T$1)*(1+'Dashboard (2)'!$T$1) -> 514.01878 | BF14: =BE14*BA14 -> 5595094.4 | BG14: =IF(ISNUMBER(AW14),AW14*BD14/AT14,"no KPI data") -> 4413910.7 | BH14: n/a | BI14: LCV | BJ14: =SWEDEN!I14 -> 295.44606 | BK14: =SWEDEN!I9 -> 11433 | BL14: =BJ14*BK14 -> 3377834.8 | BM14: =IF(BC14>=Inputs!$B$38,BC14,MIN(BC14+'Dashboard (2)'!$N$2,Inputs!$B$38)) -> 0.67167377 | BN14: =BL14*BM14 -> 2268803.1 | BO14: =Inputs!$C$13*(1+Inputs!$B$9)*(1+'Dashboard (2)'!$T$1)*(1+'Dashboard (2)'!$T$1)*(1+'Dashboard (2)'!$T$1)*(1+'Dashboard (2)'!$T$1) -> 529.43934 | BP14: =BO14*BK14 -> 6053080 | BQ14: =IF(ISNUMBER(BG14),BG14*BN14/BD14,"no KPI data") -> 4847379.3 | BR14: n/a
A15: HUNGARY | B15: LCV | C15: =Dashboard!C11 -> 349600 | D15: =Dashboard!D11 -> 1047900 | E15: =Dashboard!E11 -> 0.33361962 | F15: =Dashboard!F11 -> 0.018 | G15: =Dashboard!G11 -> 18862.2 | H15: =Dashboard!H11 -> 0.35161962 | I15: =Dashboard!I11 -> 368462.2 | K15: LCV | L15: =HUNGARY!D14 -> 250 | M15: =HUNGARY!D9 -> 3734 | N15: =L15*M15 -> 933500 | O15: =HUNGARY!D20 -> 346246.24 | P15: =O15/N15 -> 0.37091188 | Q15: =Inputs!$C$13 -> 448 | R15: =Q15*M15 -> 1672832 | S15: =IF(ISNUMBER(Dashboard!Q11),Dashboard!Q11,"no KPI data") -> no KPI data | T15: n/a | U15: LCV | V15: =HUNGARY!E14 -> 262.5 | W15: =HUNGARY!E9 -> 3992 | X15: =V15*W15 -> 1047900 | Y15: =Z15/X15 -> 0.35161962 | Z15: =HUNGARY!E24 -> 368462.2 | AA15: =Inputs!$C$13*(1+Inputs!$B$9) -> 470.4 | AB15: =AA15*W15 -> 1877836.8 | AC15: =IF(ISNUMBER(S15),S15+Dashboard!G11/(1-Inputs!$B$18),"no KPI data") -> no KPI data | AD15: n/a | AE15: LCV | AF15: =HUNGARY!F14 -> 270.375 | AG15: =HUNGARY!F9 -> 4242 | AH15: =AF15*AG15 -> 1146930.8 | AI15: =IF(Y15>=Inputs!$B$38,Y15,MIN(Y15+'Dashboard (2)'!$N$2,Inputs!$B$38)) -> 0.36161962 | AJ15: =AH15*AI15 -> 414752.66 | AK15: =Inputs!$C$13*(1+Inputs!$B$9)*(1+'Dashboard (2)'!$T$1) -> 484.512 | AL15: =AK15*AG15 -> 2055299.9 | AM15: =IF(ISNUMBER(AC15),AC15*AJ15/Z15,"no KPI data") -> no KPI data | AN15: n/a | AO15: LCV | AP15: =HUNGARY!G14 -> 278.48625 | AQ15: =HUNGARY!G9 -> 4390 | AR15: =AP15*AQ15 -> 1222554.6 | AS15: =IF(AI15>=Inputs!$B$38,AI15,MIN(AI15+'Dashboard (2)'!$N$2,Inputs!$B$38)) -> 0.37161962 | AT15: =AR15*AS15 -> 454325.29 | AU15: =Inputs!$C$13*(1+Inputs!$B$9)*(1+'Dashboard (2)'!$T$1)*(1+'Dashboard (2)'!$T$1) -> 499.04736 | AV15: =AU15*AQ15 -> 2190817.9 | AW15: =IF(ISNUMBER(AM15),AM15*AT15/AJ15,"no KPI data") -> no KPI data | AX15: n/a | AY15: LCV | AZ15: =HUNGARY!H14 -> 286.84084 | BA15: =HUNGARY!H9 -> 4533 | BB15: =AZ15*BA15 -> 1300249.5 | BC15: =IF(AS15>=Inputs!$B$38,AS15,MIN(AS15+'Dashboard (2)'!$N$2,Inputs!$B$38)) -> 0.38161962 | BD15: =BB15*BC15 -> 496200.73 | BE15: =Inputs!$C$13*(1+Inputs!$B$9)*(1+'Dashboard (2)'!$T$1)*(1+'Dashboard (2)'!$T$1)*(1+'Dashboard (2)'!$T$1) -> 514.01878 | BF15: =BE15*BA15 -> 2330047.1 | BG15: =IF(ISNUMBER(AW15),AW15*BD15/AT15,"no KPI data") -> no KPI data | BH15: n/a | BI15: LCV | BJ15: =HUNGARY!I14 -> 295.44606 | BK15: =HUNGARY!I9 -> 4672 | BL15: =BJ15*BK15 -> 1380324 | BM15: =IF(BC15>=Inputs!$B$38,BC15,MIN(BC15+'Dashboard (2)'!$N$2,Inputs!$B$38)) -> 0.39161962 | BN15: =BL15*BM15 -> 540561.96 | BO15: =Inputs!$C$13*(1+Inputs!$B$9)*(1+'Dashboard (2)'!$T$1)*(1+'Dashboard (2)'!$T$1)*(1+'Dashboard (2)'!$T$1)*(1+'Dashboard (2)'!$T$1) -> 529.43934 | BP15: =BO15*BK15 -> 2473540.6 | BQ15: =IF(ISNUMBER(BG15),BG15*BN15/BD15,"no KPI data") -> no KPI data | BR15: n/a
A16: FINLAND | B16: LCV | C16: =Dashboard!C12 -> 360300 | D16: =Dashboard!D12 -> 343350 | E16: =Dashboard!E12 -> 1.0493665 | F16: =Dashboard!F12 -> 0.018 | G16: =Dashboard!G12 -> 6180.3 | H16: =Dashboard!H12 -> 1.0673665 | I16: =Dashboard!I12 -> 366480.3 | K16: LCV | L16: =FINLAND!D14 -> 250 | M16: =FINLAND!D9 -> 1204 | N16: =L16*M16 -> 301000 | O16: =FINLAND!D20 -> 279383.25 | P16: =O16/N16 -> 0.92818355 | Q16: =Inputs!$C$13 -> 448 | R16: =Q16*M16 -> 539392 | S16: =IF(ISNUMBER(Dashboard!Q12),Dashboard!Q12,"no KPI data") -> no KPI data | T16: n/a | U16: LCV | V16: =FINLAND!E14 -> 262.5 | W16: =FINLAND!E9 -> 1308 | X16: =V16*W16 -> 343350 | Y16: =Z16/X16 -> 1.0673665 | Z16: =FINLAND!E24 -> 366480.3 | AA16: =Inputs!$C$13*(1+Inputs!$B$9) -> 470.4 | AB16: =AA16*W16 -> 615283.2 | AC16: =IF(ISNUMBER(S16),S16+Dashboard!G12/(1-Inputs!$B$18),"no KPI data") -> no KPI data | AD16: n/a | AE16: LCV | AF16: =FINLAND!F14 -> 270.375 | AG16: =FINLAND!F9 -> 1409 | AH16: =AF16*AG16 -> 380958.38 | AI16: =IF(Y16>=Inputs!$B$38,Y16,MIN(Y16+'Dashboard (2)'!$N$2,Inputs!$B$38)) -> 1.0773665 | AJ16: =AH16*AI16 -> 410431.8 | AK16: =Inputs!$C$13*(1+Inputs!$B$9)*(1+'Dashboard (2)'!$T$1) -> 484.512 | AL16: =AK16*AG16 -> 682677.41 | AM16: =IF(ISNUMBER(AC16),AC16*AJ16/Z16,"no KPI data") -> no KPI data | AN16: n/a | AO16: LCV | AP16: =FINLAND!G14 -> 278.48625 | AQ16: =FINLAND!G9 -> 1522 | AR16: =AP16*AQ16 -> 423856.07 | AS16: =IF(AI16>=Inputs!$B$38,AI16,MIN(AI16+'Dashboard (2)'!$N$2,Inputs!$B$38)) -> 1.0873665 | AT16: =AR16*AS16 -> 460886.91 | AU16: =Inputs!$C$13*(1+Inputs!$B$9)*(1+'Dashboard (2)'!$T$1)*(1+'Dashboard (2)'!$T$1) -> 499.04736 | AV16: =AU16*AQ16 -> 759550.08 | AW16: =IF(ISNUMBER(AM16),AM16*AT16/AJ16,"no KPI data") -> no KPI data | AX16: n/a | AY16: LCV | AZ16: =FINLAND!H14 -> 286.84084 | BA16: =FINLAND!H9 -> 1631 | BB16: =AZ16*BA16 -> 467837.41 | BC16: =IF(AS16>=Inputs!$B$38,AS16,MIN(AS16+'Dashboard (2)'!$N$2,Inputs!$B$38)) -> 1.0973665 | BD16: =BB16*BC16 -> 513389.11 | BE16: =Inputs!$C$13*(1+Inputs!$B$9)*(1+'Dashboard (2)'!$T$1)*(1+'Dashboard (2)'!$T$1)*(1+'Dashboard (2)'!$T$1) -> 514.01878 | BF16: =BE16*BA16 -> 838364.63 | BG16: =IF(ISNUMBER(AW16),AW16*BD16/AT16,"no KPI data") -> no KPI data | BH16: n/a | BI16: LCV | BJ16: =FINLAND!I14 -> 295.44606 | BK16: =FINLAND!I9 -> 1737 | BL16: =BJ16*BK16 -> 513189.81 | BM16: =IF(BC16>=Inputs!$B$38,BC16,MIN(BC16+'Dashboard (2)'!$N$2,Inputs!$B$38)) -> 1.1073665 | BN16: =BL16*BM16 -> 568289.22 | BO16: =Inputs!$C$13*(1+Inputs!$B$9)*(1+'Dashboard (2)'!$T$1)*(1+'Dashboard (2)'!$T$1)*(1+'Dashboard (2)'!$T$1)*(1+'Dashboard (2)'!$T$1) -> 529.43934 | BP16: =BO16*BK16 -> 919636.14 | BQ16: =IF(ISNUMBER(BG16),BG16*BN16/BD16,"no KPI data") -> no KPI data | BR16: n/a
A17: ROMANIA | B17: LCV | C17: =Dashboard!C13 -> 199587.57 | D17: =Dashboard!D13 -> 317362.5 | E17: =Dashboard!E13 -> 0.62889462 | F17: =Dashboard!F13 -> 0.018 | G17: =Dashboard!G13 -> 5712.525 | H17: =Dashboard!H13 -> 0.64689462 | I17: =Dashboard!I13 -> 205300.1 | K17: LCV | L17: =ROMANIA!D14 -> 250 | M17: =ROMANIA!D9 -> 1071 | N17: =L17*M17 -> 267750 | O17: =ROMANIA!D20 -> 177897.87 | P17: =O17/N17 -> 0.66441782 | Q17: =Inputs!$C$13 -> 448 | R17: =Q17*M17 -> 479808 | S17: =IF(ISNUMBER(Dashboard!Q13),Dashboard!Q13,"no KPI data") -> 394597 | T17: n/a | U17: LCV | V17: =ROMANIA!E14 -> 262.5 | W17: =ROMANIA!E9 -> 1209 | X17: =V17*W17 -> 317362.5 | Y17: =Z17/X17 -> 0.64689462 | Z17: =ROMANIA!E24 -> 205300.1 | AA17: =Inputs!$C$13*(1+Inputs!$B$9) -> 470.4 | AB17: =AA17*W17 -> 568713.6 | AC17: =IF(ISNUMBER(S17),S17+Dashboard!G13/(1-Inputs!$B$18),"no KPI data") -> 403385.5 | AD17: n/a | AE17: LCV | AF17: =ROMANIA!F14 -> 270.375 | AG17: =ROMANIA!F9 -> 1343 | AH17: =AF17*AG17 -> 363113.62 | AI17: =IF(Y17>=Inputs!$B$38,Y17,MIN(Y17+'Dashboard (2)'!$N$2,Inputs!$B$38)) -> 0.65689462 | AJ17: =AH17*AI17 -> 238527.39 | AK17: =Inputs!$C$13*(1+Inputs!$B$9)*(1+'Dashboard (2)'!$T$1) -> 484.512 | AL17: =AK17*AG17 -> 650699.62 | AM17: =IF(ISNUMBER(AC17),AC17*AJ17/Z17,"no KPI data") -> 468672.41 | AN17: n/a | AO17: LCV | AP17: =ROMANIA!G14 -> 278.48625 | AQ17: =ROMANIA!G9 -> 1475 | AR17: =AP17*AQ17 -> 410767.22 | AS17: =IF(AI17>=Inputs!$B$38,AI17,MIN(AI17+'Dashboard (2)'!$N$2,Inputs!$B$38)) -> 0.66689462 | AT17: =AR17*AS17 -> 273938.45 | AU17: =Inputs!$C$13*(1+Inputs!$B$9)*(1+'Dashboard (2)'!$T$1)*(1+'Dashboard (2)'!$T$1) -> 499.04736 | AV17: =AU17*AQ17 -> 736094.86 | AW17: =IF(ISNUMBER(AM17),AM17*AT17/AJ17,"no KPI data") -> 538250.11 | AX17: n/a | AY17: LCV | AZ17: =ROMANIA!H14 -> 286.84084 | BA17: =ROMANIA!H9 -> 1603 | BB17: =AZ17*BA17 -> 459805.86 | BC17: =IF(AS17>=Inputs!$B$38,AS17,MIN(AS17+'Dashboard (2)'!$N$2,Inputs!$B$38)) -> 0.67689462 | BD17: =BB17*BC17 -> 311240.12 | BE17: =Inputs!$C$13*(1+Inputs!$B$9)*(1+'Dashboard (2)'!$T$1)*(1+'Dashboard (2)'!$T$1)*(1+'Dashboard (2)'!$T$1) -> 514.01878 | BF17: =BE17*BA17 -> 823972.11 | BG17: =IF(ISNUMBER(AW17),AW17*BD17/AT17,"no KPI data") -> 611542.58 | BH17: n/a | BI17: LCV | BJ17: =ROMANIA!I14 -> 295.44606 | BK17: =ROMANIA!I9 -> 1727 | BL17: =BJ17*BK17 -> 510235.35 | BM17: =IF(BC17>=Inputs!$B$38,BC17,MIN(BC17+'Dashboard (2)'!$N$2,Inputs!$B$38)) -> 0.68689462 | BN17: =BL17*BM17 -> 350477.92 | BO17: =Inputs!$C$13*(1+Inputs!$B$9)*(1+'Dashboard (2)'!$T$1)*(1+'Dashboard (2)'!$T$1)*(1+'Dashboard (2)'!$T$1)*(1+'Dashboard (2)'!$T$1) -> 529.43934 | BP17: =BO17*BK17 -> 914341.75 | BQ17: =IF(ISNUMBER(BG17),BG17*BN17/BD17,"no KPI data") -> 688639.28 | BR17: n/a
A18: DENMARK | B18: LCV | C18: =Dashboard!C14 -> 187600 | D18: =Dashboard!D14 -> 247800 | E18: =Dashboard!E14 -> 0.75706215 | F18: =Dashboard!F14 -> 0.018 | G18: =Dashboard!G14 -> 4460.4 | H18: =Dashboard!H14 -> 0.77506215 | I18: =Dashboard!I14 -> 192060.4 | K18: LCV | L18: =DENMARK!D14 -> 250 | M18: =DENMARK!D9 -> 850 | N18: =L18*M18 -> 212500 | O18: =DENMARK!D20 -> 154459.8 | P18: =O18/N18 -> 0.72686965 | Q18: =Inputs!$C$13 -> 448 | R18: =Q18*M18 -> 380800 | S18: =IF(ISNUMBER(Dashboard!Q14),Dashboard!Q14,"no KPI data") -> 572864 | T18: n/a | U18: LCV | V18: =DENMARK!E14 -> 262.5 | W18: =DENMARK!E9 -> 944 | X18: =V18*W18 -> 247800 | Y18: =Z18/X18 -> 0.77506215 | Z18: =DENMARK!E24 -> 192060.4 | AA18: =Inputs!$C$13*(1+Inputs!$B$9) -> 470.4 | AB18: =AA18*W18 -> 444057.6 | AC18: =IF(ISNUMBER(S18),S18+Dashboard!G14/(1-Inputs!$B$18),"no KPI data") -> 579726.15 | AD18: n/a | AE18: LCV | AF18: =DENMARK!F14 -> 270.375 | AG18: =DENMARK!F9 -> 1036 | AH18: =AF18*AG18 -> 280108.5 | AI18: =IF(Y18>=Inputs!$B$38,Y18,MIN(Y18+'Dashboard (2)'!$N$2,Inputs!$B$38)) -> 0.78506215 | AJ18: =AH18*AI18 -> 219902.58 | AK18: =Inputs!$C$13*(1+Inputs!$B$9)*(1+'Dashboard (2)'!$T$1) -> 484.512 | AL18: =AK18*AG18 -> 501954.43 | AM18: =IF(ISNUMBER(AC18),AC18*AJ18/Z18,"no KPI data") -> 663766.59 | AN18: n/a | AO18: LCV | AP18: =DENMARK!G14 -> 278.48625 | AQ18: =DENMARK!G9 -> 1140 | AR18: =AP18*AQ18 -> 317474.33 | AS18: =IF(AI18>=Inputs!$B$38,AI18,MIN(AI18+'Dashboard (2)'!$N$2,Inputs!$B$38)) -> 0.79506215 | AT18: =AR18*AS18 -> 252411.82 | AU18: =Inputs!$C$13*(1+Inputs!$B$9)*(1+'Dashboard (2)'!$T$1)*(1+'Dashboard (2)'!$T$1) -> 499.04736 | AV18: =AU18*AQ18 -> 568913.99 | AW18: =IF(ISNUMBER(AM18),AM18*AT18/AJ18,"no KPI data") -> 761894.35 | AX18: n/a | AY18: LCV | AZ18: =DENMARK!H14 -> 286.84084 | BA18: =DENMARK!H9 -> 1241 | BB18: =AZ18*BA18 -> 355969.48 | BC18: =IF(AS18>=Inputs!$B$38,AS18,MIN(AS18+'Dashboard (2)'!$N$2,Inputs!$B$38)) -> 0.80506215 | BD18: =BB18*BC18 -> 286577.55 | BE18: =Inputs!$C$13*(1+Inputs!$B$9)*(1+'Dashboard (2)'!$T$1)*(1+'Dashboard (2)'!$T$1)*(1+'Dashboard (2)'!$T$1) -> 514.01878 | BF18: =BE18*BA18 -> 637897.31 | BG18: =IF(ISNUMBER(AW18),AW18*BD18/AT18,"no KPI data") -> 865022.16 | BH18: n/a | BI18: LCV | BJ18: =DENMARK!I14 -> 295.44606 | BK18: =DENMARK!I9 -> 1339 | BL18: =BJ18*BK18 -> 395602.28 | BM18: =IF(BC18>=Inputs!$B$38,BC18,MIN(BC18+'Dashboard (2)'!$N$2,Inputs!$B$38)) -> 0.81506215 | BN18: =BL18*BM18 -> 322440.44 | BO18: =Inputs!$C$13*(1+Inputs!$B$9)*(1+'Dashboard (2)'!$T$1)*(1+'Dashboard (2)'!$T$1)*(1+'Dashboard (2)'!$T$1)*(1+'Dashboard (2)'!$T$1) -> 529.43934 | BP18: =BO18*BK18 -> 708919.28 | BQ18: =IF(ISNUMBER(BG18),BG18*BN18/BD18,"no KPI data") -> 973272.77 | BR18: n/a
A19: ICELAND | B19: LCV | C19: =Dashboard!C15 -> 104600 | D19: =Dashboard!D15 -> 115237.5 | E19: =Dashboard!E15 -> 0.90769064 | F19: =Dashboard!F15 -> 0.018 | G19: =Dashboard!G15 -> 2074.275 | H19: =Dashboard!H15 -> 0.92569064 | I19: =Dashboard!I15 -> 106674.27 | K19: LCV | L19: =ICELAND!D14 -> 250 | M19: =ICELAND!D9 -> 406 | N19: =L19*M19 -> 101500 | O19: =ICELAND!D20 -> 86604.51 | P19: =O19/N19 -> 0.8532464 | Q19: =Inputs!$C$13 -> 448 | R19: =Q19*M19 -> 181888 | S19: =IF(ISNUMBER(Dashboard!Q15),Dashboard!Q15,"no KPI data") -> 195849 | T19: n/a | U19: LCV | V19: =ICELAND!E14 -> 262.5 | W19: =ICELAND!E9 -> 439 | X19: =V19*W19 -> 115237.5 | Y19: =Z19/X19 -> 0.92569064 | Z19: =ICELAND!E24 -> 106674.27 | AA19: =Inputs!$C$13*(1+Inputs!$B$9) -> 470.4 | AB19: =AA19*W19 -> 206505.6 | AC19: =IF(ISNUMBER(S19),S19+Dashboard!G15/(1-Inputs!$B$18),"no KPI data") -> 199040.19 | AD19: n/a | AE19: LCV | AF19: =ICELAND!F14 -> 270.375 | AG19: =ICELAND!F9 -> 471 | AH19: =AF19*AG19 -> 127346.62 | AI19: =IF(Y19>=Inputs!$B$38,Y19,MIN(Y19+'Dashboard (2)'!$N$2,Inputs!$B$38)) -> 0.93569064 | AJ19: =AH19*AI19 -> 119157.04 | AK19: =Inputs!$C$13*(1+Inputs!$B$9)*(1+'Dashboard (2)'!$T$1) -> 484.512 | AL19: =AK19*AG19 -> 228205.15 | AM19: =IF(ISNUMBER(AC19),AC19*AJ19/Z19,"no KPI data") -> 222331.4 | AN19: n/a | AO19: LCV | AP19: =ICELAND!G14 -> 278.48625 | AQ19: =ICELAND!G9 -> 549 | AR19: =AP19*AQ19 -> 152888.95 | AS19: =IF(AI19>=Inputs!$B$38,AI19,MIN(AI19+'Dashboard (2)'!$N$2,Inputs!$B$38)) -> 0.94569064 | AT19: =AR19*AS19 -> 144585.65 | AU19: =Inputs!$C$13*(1+Inputs!$B$9)*(1+'Dashboard (2)'!$T$1)*(1+'Dashboard (2)'!$T$1) -> 499.04736 | AV19: =AU19*AQ19 -> 273977 | AW19: =IF(ISNUMBER(AM19),AM19*AT19/AJ19,"no KPI data") -> 269777.84 | AX19: n/a | AY19: LCV | AZ19: =ICELAND!H14 -> 286.84084 | BA19: =ICELAND!H9 -> 625 | BB19: =AZ19*BA19 -> 179275.52 | BC19: =IF(AS19>=Inputs!$B$38,AS19,MIN(AS19+'Dashboard (2)'!$N$2,Inputs!$B$38)) -> 0.95569064 | BD19: =BB19*BC19 -> 171331.94 | BE19: =Inputs!$C$13*(1+Inputs!$B$9)*(1+'Dashboard (2)'!$T$1)*(1+'Dashboard (2)'!$T$1)*(1+'Dashboard (2)'!$T$1) -> 514.01878 | BF19: =BE19*BA19 -> 321261.74 | BG19: =IF(ISNUMBER(AW19),AW19*BD19/AT19,"no KPI data") -> 319682.91 | BH19: n/a | BI19: LCV | BJ19: =ICELAND!I14 -> 295.44606 | BK19: =ICELAND!I9 -> 698 | BL19: =BJ19*BK19 -> 206221.35 | BM19: =IF(BC19>=Inputs!$B$38,BC19,MIN(BC19+'Dashboard (2)'!$N$2,Inputs!$B$38)) -> 0.96569064 | BN19: =BL19*BM19 -> 199146.03 | BO19: =Inputs!$C$13*(1+Inputs!$B$9)*(1+'Dashboard (2)'!$T$1)*(1+'Dashboard (2)'!$T$1)*(1+'Dashboard (2)'!$T$1)*(1+'Dashboard (2)'!$T$1) -> 529.43934 | BP19: =BO19*BK19 -> 369548.66 | BQ19: =IF(ISNUMBER(BG19),BG19*BN19/BD19,"no KPI data") -> 371580.34 | BR19: n/a
A20: GERMANY | B20: mixed | C20: =Dashboard!C16 -> 2913662.8 | D20: =Dashboard!D16 -> 4443791.1 | E20: =Dashboard!E16 -> 0.65567052 | F20: =Dashboard!F16 -> 0.018 | G20: =Dashboard!G16 -> 79988.24 | H20: =Dashboard!H16 -> 0.67367052 | I20: =Dashboard!I16 -> 2993651.1 | K20: CV LD | L20: =GERMANY!C17 -> 739 | M20: =GERMANY!D9 -> 697 | N20: =L20*M20 -> 515083 | Q20: =IFERROR(R20/M20,0) -> 1120 | R20: =Inputs!$C$14*GERMANY!D9 -> 780640 | U20: CV LD | V20: =GERMANY!D17 -> 775.95 | W20: =GERMANY!E9 -> 1066 | X20: =V20*W20 -> 827162.7 | AA20: =IFERROR(AB20/W20,0) -> 1176 | AB20: =Inputs!$C$14*(1+Inputs!$B$9)*GERMANY!E9 -> 1253616 | AE20: CV LD | AF20: =GERMANY!E17 -> 799.2285 | AG20: =GERMANY!F9 -> 1422 | AH20: =AF20*AG20 -> 1136502.9 | AK20: =IFERROR(AL20/AG20,0) -> 1211.28 | AL20: =Inputs!$C$14*(1+Inputs!$B$9)*(1+'Dashboard (2)'!$T$1)*GERMANY!F9 -> 1722440.2 | AO20: CV LD | AP20: =GERMANY!F17 -> 823.20536 | AQ20: =GERMANY!G9 -> 2003 | AR20: =AP20*AQ20 -> 1648880.3 | AU20: =IFERROR(AV20/AQ20,0) -> 1247.6184 | AV20: =Inputs!$C$14*(1+Inputs!$B$9)*(1+'Dashboard (2)'!$T$1)*(1+'Dashboard (2)'!$T$1)*GERMANY!G9 -> 2498979.7 | AY20: CV LD | AZ20: =GERMANY!G17 -> 847.90152 | BA20: =GERMANY!H9 -> 2841 | BB20: =AZ20*BA20 -> 2408888.2 | BE20: =IFERROR(BF20/BA20,0) -> 1285.047 | BF20: =Inputs!$C$14*(1+Inputs!$B$9)*(1+'Dashboard (2)'!$T$1)*(1+'Dashboard (2)'!$T$1)*(1+'Dashboard (2)'!$T$1)*GERMANY!H9 -> 3650818.4 | BI20: CV LD | BJ20: =GERMANY!H17 -> 873.33856 | BK20: =GERMANY!I9 -> 3756 | BL20: =BJ20*BK20 -> 3280259.6 | BO20: =IFERROR(BP20/BK20,0) -> 1323.5984 | BP20: =Inputs!$C$14*(1+Inputs!$B$9)*(1+'Dashboard (2)'!$T$1)*(1+'Dashboard (2)'!$T$1)*(1+'Dashboard (2)'!$T$1)*(1+'Dashboard (2)'!$T$1)*GERMANY!I9 -> 4971435.4
K21: CV MD | L21: =GERMANY!C18 -> 887 | M21: =GERMANY!D10 -> 35 | N21: =L21*M21 -> 31045 | Q21: =IFERROR(R21/M21,0) -> 1344 | R21: =Inputs!$C$15*GERMANY!D10 -> 47040 | U21: CV MD | V21: =GERMANY!D18 -> 931.35 | W21: =GERMANY!E10 -> 34 | X21: =V21*W21 -> 31665.9 | AA21: =IFERROR(AB21/W21,0) -> 1411.2 | AB21: =Inputs!$C$15*(1+Inputs!$B$9)*GERMANY!E10 -> 47980.8 | AE21: CV MD | AF21: =GERMANY!E18 -> 959.2905 | AG21: =GERMANY!F10 -> 33 | AH21: =AF21*AG21 -> 31656.587 | AK21: =IFERROR(AL21/AG21,0) -> 1453.536 | AL21: =Inputs!$C$15*(1+Inputs!$B$9)*(1+'Dashboard (2)'!$T$1)*GERMANY!F10 -> 47966.688 | AO21: CV MD | AP21: =GERMANY!F18 -> 988.06921 | AQ21: =GERMANY!G10 -> 32 | AR21: =AP21*AQ21 -> 31618.215 | AU21: =IFERROR(AV21/AQ21,0) -> 1497.1421 | AV21: =Inputs!$C$15*(1+Inputs!$B$9)*(1+'Dashboard (2)'!$T$1)*(1+'Dashboard (2)'!$T$1)*GERMANY!G10 -> 47908.547 | AY21: CV MD | AZ21: =GERMANY!G18 -> 1017.7113 | BA21: =GERMANY!H10 -> 31 | BB21: =AZ21*BA21 -> 31549.05 | BE21: =IFERROR(BF21/BA21,0) -> 1542.0563 | BF21: =Inputs!$C$15*(1+Inputs!$B$9)*(1+'Dashboard (2)'!$T$1)*(1+'Dashboard (2)'!$T$1)*(1+'Dashboard (2)'!$T$1)*GERMANY!H10 -> 47803.747 | BI21: CV MD | BJ21: =GERMANY!H18 -> 1048.2426 | BK21: =GERMANY!I10 -> 30 | BL21: =BJ21*BK21 -> 31447.279 | BO21: =IFERROR(BP21/BK21,0) -> 1588.318 | BP21: =Inputs!$C$15*(1+Inputs!$B$9)*(1+'Dashboard (2)'!$T$1)*(1+'Dashboard (2)'!$T$1)*(1+'Dashboard (2)'!$T$1)*(1+'Dashboard (2)'!$T$1)*GERMANY!I10 -> 47649.541
K22: LCV | L22: =GERMANY!C20 -> 250 | M22: =GERMANY!D12 -> 13048 | N22: =L22*M22 -> 3262000 | Q22: =IFERROR(R22/M22,0) -> 448 | R22: =Inputs!$C$13*GERMANY!D12 -> 5845504 | U22: LCV | V22: =GERMANY!D20 -> 262.5 | W22: =GERMANY!E12 -> 13657 | X22: =V22*W22 -> 3584962.5 | AA22: =IFERROR(AB22/W22,0) -> 470.4 | AB22: =Inputs!$C$13*(1+Inputs!$B$9)*GERMANY!E12 -> 6424252.8 | AE22: LCV | AF22: =GERMANY!E20 -> 270.375 | AG22: =GERMANY!F12 -> 14247 | AH22: =AF22*AG22 -> 3852032.6 | AK22: =IFERROR(AL22/AG22,0) -> 484.512 | AL22: =Inputs!$C$13*(1+Inputs!$B$9)*(1+'Dashboard (2)'!$T$1)*GERMANY!F12 -> 6902842.5 | AO22: LCV | AP22: =GERMANY!F20 -> 278.48625 | AQ22: =GERMANY!G12 -> 14820 | AR22: =AP22*AQ22 -> 4127166.2 | AU22: =IFERROR(AV22/AQ22,0) -> 499.04736 | AV22: =Inputs!$C$13*(1+Inputs!$B$9)*(1+'Dashboard (2)'!$T$1)*(1+'Dashboard (2)'!$T$1)*GERMANY!G12 -> 7395881.9 | AY22: LCV | AZ22: =GERMANY!G20 -> 286.84084 | BA22: =GERMANY!H12 -> 15375 | BB22: =AZ22*BA22 -> 4410177.9 | BE22: =IFERROR(BF22/BA22,0) -> 514.01878 | BF22: =Inputs!$C$13*(1+Inputs!$B$9)*(1+'Dashboard (2)'!$T$1)*(1+'Dashboard (2)'!$T$1)*(1+'Dashboard (2)'!$T$1)*GERMANY!H12 -> 7903038.8 | BI22: LCV | BJ22: =GERMANY!H20 -> 295.44606 | BK22: =GERMANY!I12 -> 15914 | BL22: =BJ22*BK22 -> 4701728.6 | BO22: =IFERROR(BP22/BK22,0) -> 529.43934 | BP22: =Inputs!$C$13*(1+Inputs!$B$9)*(1+'Dashboard (2)'!$T$1)*(1+'Dashboard (2)'!$T$1)*(1+'Dashboard (2)'!$T$1)*(1+'Dashboard (2)'!$T$1)*GERMANY!I12 -> 8425497.7
M23: =SUM(M20:M22) -> 13780 | N23: =SUM(N20:N22) -> 3808128 | O23: =GERMANY!D26 -> 2641885.1 | P23: =O23/N23 -> 0.69374904 | R23: =SUM(R20:R22) -> 6673184 | S23: =IF(ISNUMBER(Dashboard!Q16),Dashboard!Q16,"no KPI data") -> no KPI data | T23: n/a | W23: =SUM(W20:W22) -> 14757 | X23: =SUM(X20:X22) -> 4443791.1 | Y23: =Z23/X23 -> 0.67367052 | Z23: =GERMANY!E30 -> 2993651.1 | AB23: =SUM(AB20:AB22) -> 7725849.6 | AC23: =IF(ISNUMBER(S23),S23+Dashboard!G16/(1-Inputs!$B$18),"no KPI data") -> no KPI data | AD23: n/a | AG23: =SUM(AG20:AG22) -> 15702 | AH23: =SUM(AH20:AH22) -> 5020192.1 | AI23: =IF(Y23>=Inputs!$B$38,Y23,MIN(Y23+'Dashboard (2)'!$N$2,Inputs!$B$38)) -> 0.68367052 | AJ23: =AH23*AI23 -> 3432157.4 | AL23: =SUM(AL20:AL22) -> 8673249.3 | AM23: =IF(ISNUMBER(AC23),AC23*AJ23/Z23,"no KPI data") -> no KPI data | AN23: n/a | AQ23: =SUM(AQ20:AQ22) -> 16855 | AR23: =SUM(AR20:AR22) -> 5807664.8 | AS23: =IF(AI23>=Inputs!$B$38,AI23,MIN(AI23+'Dashboard (2)'!$N$2,Inputs!$B$38)) -> 0.69367052 | AT23: =AR23*AS23 -> 4028605.9 | AV23: =SUM(AV20:AV22) -> 9942770.1 | AW23: =IF(ISNUMBER(AM23),AM23*AT23/AJ23,"no KPI data") -> no KPI data | AX23: n/a | BA23: =SUM(BA20:BA22) -> 18247 | BB23: =SUM(BB20:BB22) -> 6850615.1 | BC23: =IF(AS23>=Inputs!$B$38,AS23,MIN(AS23+'Dashboard (2)'!$N$2,Inputs!$B$38)) -> 0.70367052 | BD23: =BB23*BC23 -> 4820575.9 | BF23: =SUM(BF20:BF22) -> 11601661 | BG23: =IF(ISNUMBER(AW23),AW23*BD23/AT23,"no KPI data") -> no KPI data | BH23: n/a | BK23: =SUM(BK20:BK22) -> 19700 | BL23: =SUM(BL20:BL22) -> 8013435.6 | BM23: =IF(BC23>=Inputs!$B$38,BC23,MIN(BC23+'Dashboard (2)'!$N$2,Inputs!$B$38)) -> 0.71367052 | BN23: =BL23*BM23 -> 5718952.8 | BP23: =SUM(BP20:BP22) -> 13444583 | BQ23: =IF(ISNUMBER(BG23),BG23*BN23/BD23,"no KPI data") -> no KPI data | BR23: n/a
A24: BELGIUM | B24: mixed | C24: =Dashboard!C17 -> 2296577.3 | D24: =Dashboard!D17 -> 2739612.8 | E24: =Dashboard!E17 -> 0.83828539 | F24: =Dashboard!F17 -> 0.018 | G24: =Dashboard!G17 -> 49313.029 | H24: =Dashboard!H17 -> 0.85628539 | I24: =Dashboard!I17 -> 2345890.4 | K24: CV LD | L24: =BELGIUM!C17 -> 739 | M24: =BELGIUM!D9 -> 113 | N24: =L24*M24 -> 83507 | Q24: =IFERROR(R24/M24,0) -> 1120 | R24: =Inputs!$C$14*BELGIUM!D9 -> 126560 | U24: CV LD | V24: =BELGIUM!D17 -> 775.95 | W24: =BELGIUM!E9 -> 145 | X24: =V24*W24 -> 112512.75 | AA24: =IFERROR(AB24/W24,0) -> 1176 | AB24: =Inputs!$C$14*(1+Inputs!$B$9)*BELGIUM!E9 -> 170520 | AE24: CV LD | AF24: =BELGIUM!E17 -> 799.2285 | AG24: =BELGIUM!F9 -> 176 | AH24: =AF24*AG24 -> 140664.22 | AK24: =IFERROR(AL24/AG24,0) -> 1211.28 | AL24: =Inputs!$C$14*(1+Inputs!$B$9)*(1+'Dashboard (2)'!$T$1)*BELGIUM!F9 -> 213185.28 | AO24: CV LD | AP24: =BELGIUM!F17 -> 823.20536 | AQ24: =BELGIUM!G9 -> 206 | AR24: =AP24*AQ24 -> 169580.3 | AU24: =IFERROR(AV24/AQ24,0) -> 1247.6184 | AV24: =Inputs!$C$14*(1+Inputs!$B$9)*(1+'Dashboard (2)'!$T$1)*(1+'Dashboard (2)'!$T$1)*BELGIUM!G9 -> 257009.39 | AY24: CV LD | AZ24: =BELGIUM!G17 -> 847.90152 | BA24: =BELGIUM!H9 -> 235 | BB24: =AZ24*BA24 -> 199256.86 | BE24: =IFERROR(BF24/BA24,0) -> 1285.047 | BF24: =Inputs!$C$14*(1+Inputs!$B$9)*(1+'Dashboard (2)'!$T$1)*(1+'Dashboard (2)'!$T$1)*(1+'Dashboard (2)'!$T$1)*BELGIUM!H9 -> 301986.03 | BI24: CV LD | BJ24: =BELGIUM!H17 -> 873.33856 | BK24: =BELGIUM!I9 -> 263 | BL24: =BJ24*BK24 -> 229688.04 | BO24: =IFERROR(BP24/BK24,0) -> 1323.5984 | BP24: =Inputs!$C$14*(1+Inputs!$B$9)*(1+'Dashboard (2)'!$T$1)*(1+'Dashboard (2)'!$T$1)*(1+'Dashboard (2)'!$T$1)*(1+'Dashboard (2)'!$T$1)*BELGIUM!I9 -> 348106.37
K25: LCV | L25: =BELGIUM!C20 -> 250 | M25: =BELGIUM!D12 -> 9452 | N25: =L25*M25 -> 2363000 | Q25: =IFERROR(R25/M25,0) -> 448 | R25: =Inputs!$C$13*BELGIUM!D12 -> 4234496 | U25: LCV | V25: =BELGIUM!D20 -> 262.5 | W25: =BELGIUM!E12 -> 10008 | X25: =V25*W25 -> 2627100 | AA25: =IFERROR(AB25/W25,0) -> 470.4 | AB25: =Inputs!$C$13*(1+Inputs!$B$9)*BELGIUM!E12 -> 4707763.2 | AE25: LCV | AF25: =BELGIUM!E20 -> 270.375 | AG25: =BELGIUM!F12 -> 10548 | AH25: =AF25*AG25 -> 2851915.5 | AK25: =IFERROR(AL25/AG25,0) -> 484.512 | AL25: =Inputs!$C$13*(1+Inputs!$B$9)*(1+'Dashboard (2)'!$T$1)*BELGIUM!F12 -> 5110632.6 | AO25: LCV | AP25: =BELGIUM!F20 -> 278.48625 | AQ25: =BELGIUM!G12 -> 11072 | AR25: =AP25*AQ25 -> 3083399.8 | AU25: =IFERROR(AV25/AQ25,0) -> 499.04736 | AV25: =Inputs!$C$13*(1+Inputs!$B$9)*(1+'Dashboard (2)'!$T$1)*(1+'Dashboard (2)'!$T$1)*BELGIUM!G12 -> 5525452.4 | AY25: LCV | AZ25: =BELGIUM!G20 -> 286.84084 | BA25: =BELGIUM!H12 -> 11580 | BB25: =AZ25*BA25 -> 3321616.9 | BE25: =IFERROR(BF25/BA25,0) -> 514.01878 | BF25: =Inputs!$C$13*(1+Inputs!$B$9)*(1+'Dashboard (2)'!$T$1)*(1+'Dashboard (2)'!$T$1)*(1+'Dashboard (2)'!$T$1)*BELGIUM!H12 -> 5952337.5 | BI25: LCV | BJ25: =BELGIUM!H20 -> 295.44606 | BK25: =BELGIUM!I12 -> 12073 | BL25: =BJ25*BK25 -> 3566920.3 | BO25: =IFERROR(BP25/BK25,0) -> 529.43934 | BP25: =Inputs!$C$13*(1+Inputs!$B$9)*(1+'Dashboard (2)'!$T$1)*(1+'Dashboard (2)'!$T$1)*(1+'Dashboard (2)'!$T$1)*(1+'Dashboard (2)'!$T$1)*BELGIUM!I12 -> 6391921.2
M26: =SUM(M24:M25) -> 9565 | N26: =SUM(N24:N25) -> 2446507 | O26: =BELGIUM!D26 -> 2110127.7 | P26: =O26/N26 -> 0.86250628 | R26: =SUM(R24:R25) -> 4361056 | S26: =IF(ISNUMBER(Dashboard!Q17),Dashboard!Q17,"no KPI data") -> 6834272 | T26: n/a | W26: =SUM(W24:W25) -> 10153 | X26: =SUM(X24:X25) -> 2739612.8 | Y26: =Z26/X26 -> 0.85628539 | Z26: =BELGIUM!E30 -> 2345890.4 | AB26: =SUM(AB24:AB25) -> 4878283.2 | AC26: =IF(ISNUMBER(S26),S26+Dashboard!G17/(1-Inputs!$B$18),"no KPI data") -> 6910138.2 | AD26: n/a | AG26: =SUM(AG24:AG25) -> 10724 | AH26: =SUM(AH24:AH25) -> 2992579.7 | AI26: =IF(Y26>=Inputs!$B$38,Y26,MIN(Y26+'Dashboard (2)'!$N$2,Inputs!$B$38)) -> 0.86628539 | AJ26: =AH26*AI26 -> 2592428.1 | AL26: =SUM(AL24:AL25) -> 5323817.9 | AM26: =IF(ISNUMBER(AC26),AC26*AJ26/Z26,"no KPI data") -> 7636348.5 | AN26: n/a | AQ26: =SUM(AQ24:AQ25) -> 11278 | AR26: =SUM(AR24:AR25) -> 3252980.1 | AS26: =IF(AI26>=Inputs!$B$38,AI26,MIN(AI26+'Dashboard (2)'!$N$2,Inputs!$B$38)) -> 0.87628539 | AT26: =AR26*AS26 -> 2850538.9 | AV26: =SUM(AV24:AV25) -> 5782461.8 | AW26: =IF(ISNUMBER(AM26),AM26*AT26/AJ26,"no KPI data") -> 8396648.9 | AX26: n/a | BA26: =SUM(BA24:BA25) -> 11815 | BB26: =SUM(BB24:BB25) -> 3520873.8 | BC26: =IF(AS26>=Inputs!$B$38,AS26,MIN(AS26+'Dashboard (2)'!$N$2,Inputs!$B$38)) -> 0.88628539 | BD26: =BB26*BC26 -> 3120499 | BF26: =SUM(BF24:BF25) -> 6254323.5 | BG26: =IF(ISNUMBER(AW26),AW26*BD26/AT26,"no KPI data") -> 9191852.9 | BH26: n/a | BK26: =SUM(BK24:BK25) -> 12336 | BL26: =SUM(BL24:BL25) -> 3796608.4 | BM26: =IF(BC26>=Inputs!$B$38,BC26,MIN(BC26+'Dashboard (2)'!$N$2,Inputs!$B$38)) -> 0.89628539 | BN26: =BL26*BM26 -> 3402844.6 | BP26: =SUM(BP24:BP25) -> 6740027.6 | BQ26: =IF(ISNUMBER(BG26),BG26*BN26/BD26,"no KPI data") -> 10023540 | BR26: n/a
A27: PORTUGAL | B27: mixed | C27: =Dashboard!C18 -> 1858269.4 | D27: =Dashboard!D18 -> 3788245.6 | E27: =Dashboard!E18 -> 0.49053561 | F27: =Dashboard!F18 -> 0.018 | G27: =Dashboard!G18 -> 68188.422 | H27: =Dashboard!H18 -> 0.50853561 | I27: =Dashboard!I18 -> 1926457.8 | K27: CV N | L27: =PORTUGAL!C17 -> 739 | M27: =PORTUGAL!D9 -> 2206 | N27: =L27*M27 -> 1630234 | Q27: =IFERROR(R27/M27,0) -> 1120 | R27: =Inputs!$C$14*PORTUGAL!D9 -> 2470720 | U27: CV N | V27: =PORTUGAL!D17 -> 775.95 | W27: =PORTUGAL!E9 -> 2596 | X27: =V27*W27 -> 2014366.2 | AA27: =IFERROR(AB27/W27,0) -> 1176 | AB27: =Inputs!$C$14*(1+Inputs!$B$9)*PORTUGAL!E9 -> 3052896 | AE27: CV N | AF27: =PORTUGAL!E17 -> 799.2285 | AG27: =PORTUGAL!F9 -> 2974 | AH27: =AF27*AG27 -> 2376905.6 | AK27: =IFERROR(AL27/AG27,0) -> 1211.28 | AL27: =Inputs!$C$14*(1+Inputs!$B$9)*(1+'Dashboard (2)'!$T$1)*PORTUGAL!F9 -> 3602346.7 | AO27: CV N | AP27: =PORTUGAL!F17 -> 823.20536 | AQ27: =PORTUGAL!G9 -> 3341 | AR27: =AP27*AQ27 -> 2750329.1 | AU27: =IFERROR(AV27/AQ27,0) -> 1247.6184 | AV27: =Inputs!$C$14*(1+Inputs!$B$9)*(1+'Dashboard (2)'!$T$1)*(1+'Dashboard (2)'!$T$1)*PORTUGAL!G9 -> 4168293.1 | AY27: CV N | AZ27: =PORTUGAL!G17 -> 847.90152 | BA27: =PORTUGAL!H9 -> 3697 | BB27: =AZ27*BA27 -> 3134691.9 | BE27: =IFERROR(BF27/BA27,0) -> 1285.047 | BF27: =Inputs!$C$14*(1+Inputs!$B$9)*(1+'Dashboard (2)'!$T$1)*(1+'Dashboard (2)'!$T$1)*(1+'Dashboard (2)'!$T$1)*PORTUGAL!H9 -> 4750818.6 | BI27: CV N | BJ27: =PORTUGAL!H17 -> 873.33856 | BK27: =PORTUGAL!I9 -> 4042 | BL27: =BJ27*BK27 -> 3530034.5 | BO27: =IFERROR(BP27/BK27,0) -> 1323.5984 | BP27: =Inputs!$C$14*(1+Inputs!$B$9)*(1+'Dashboard (2)'!$T$1)*(1+'Dashboard (2)'!$T$1)*(1+'Dashboard (2)'!$T$1)*(1+'Dashboard (2)'!$T$1)*PORTUGAL!I9 -> 5349984.6
K28: CV F | L28: =IFERROR(N28/M28,0) -> 887 | M28: =PORTUGAL!D10+PORTUGAL!D11 -> 269 | N28: =PORTUGAL!C18*PORTUGAL!D10+PORTUGAL!C19*PORTUGAL!D11 -> 238603 | Q28: =IFERROR(R28/M28,0) -> 1344 | R28: =Inputs!$C$15*PORTUGAL!D10+Inputs!$C$15*PORTUGAL!D11 -> 361536 | U28: CV F | V28: =IFERROR(X28/W28,0) -> 931.35 | W28: =PORTUGAL!E10+PORTUGAL!E11 -> 357 | X28: =PORTUGAL!D18*PORTUGAL!E10+PORTUGAL!D19*PORTUGAL!E11 -> 332491.95 | AA28: =IFERROR(AB28/W28,0) -> 1411.2 | AB28: =Inputs!$C$15*(1+Inputs!$B$9)*PORTUGAL!E10+Inputs!$C$15*(1+Inputs!$B$9)*PORTUGAL!E11 -> 503798.4 | AE28: CV F | AF28: =IFERROR(AH28/AG28,0) -> 959.2905 | AG28: =PORTUGAL!F10+PORTUGAL!F11 -> 454 | AH28: =PORTUGAL!E18*PORTUGAL!F10+PORTUGAL!E19*PORTUGAL!F11 -> 435517.89 | AK28: =IFERROR(AL28/AG28,0) -> 1453.536 | AL28: =Inputs!$C$15*(1+Inputs!$B$9)*(1+'Dashboard (2)'!$T$1)*PORTUGAL!F10+Inputs!$C$15*(1+Inputs!$B$9)*(1+'Dashboard (2)'!$T$1)*PORTUGAL!F11 -> 659905.34 | AO28: CV F | AP28: =IFERROR(AR28/AQ28,0) -> 988.06921 | AQ28: =PORTUGAL!G10+PORTUGAL!G11 -> 548 | AR28: =PORTUGAL!F18*PORTUGAL!G10+PORTUGAL!F19*PORTUGAL!G11 -> 541461.93 | AU28: =IFERROR(AV28/AQ28,0) -> 1497.1421 | AV28: =Inputs!$C$15*(1+Inputs!$B$9)*(1+'Dashboard (2)'!$T$1)*(1+'Dashboard (2)'!$T$1)*PORTUGAL!G10+Inputs!$C$15*(1+Inputs!$B$9)*(1+'Dashboard (2)'!$T$1)*(1+'Dashboard (2)'!$T$1)*PORTUGAL!G11 -> 820433.86 | AY28: CV F | AZ28: =IFERROR(BB28/BA28,0) -> 1017.7113 | BA28: =PORTUGAL!H10+PORTUGAL!H11 -> 640 | BB28: =PORTUGAL!G18*PORTUGAL!H10+PORTUGAL!G19*PORTUGAL!H11 -> 651335.23 | BE28: =IFERROR(BF28/BA28,0) -> 1542.0563 | BF28: =Inputs!$C$15*(1+Inputs!$B$9)*(1+'Dashboard (2)'!$T$1)*(1+'Dashboard (2)'!$T$1)*(1+'Dashboard (2)'!$T$1)*PORTUGAL!H10+Inputs!$C$15*(1+Inputs!$B$9)*(1+'Dashboard (2)'!$T$1)*(1+'Dashboard (2)'!$T$1)*(1+'Dashboard (2)'!$T$1)*PORTUGAL!H11 -> 986916.06 | BI28: CV F | BJ28: =IFERROR(BL28/BK28,0) -> 1048.2426 | BK28: =PORTUGAL!I10+PORTUGAL!I11 -> 729 | BL28: =PORTUGAL!H18*PORTUGAL!I10+PORTUGAL!H19*PORTUGAL!I11 -> 764168.88 | BO28: =IFERROR(BP28/BK28,0) -> 1588.318 | BP28: =Inputs!$C$15*(1+Inputs!$B$9)*(1+'Dashboard (2)'!$T$1)*(1+'Dashboard (2)'!$T$1)*(1+'Dashboard (2)'!$T$1)*(1+'Dashboard (2)'!$T$1)*PORTUGAL!I10+Inputs!$C$15*(1+Inputs!$B$9)*(1+'Dashboard (2)'!$T$1)*(1+'Dashboard (2)'!$T$1)*(1+'Dashboard (2)'!$T$1)*(1+'Dashboard (2)'!$T$1)*PORTUGAL!I11 -> 1157883.8
K29: LCV | L29: =PORTUGAL!C20 -> 250 | M29: =PORTUGAL!D12 -> 4733 | N29: =L29*M29 -> 1183250 | Q29: =IFERROR(R29/M29,0) -> 448 | R29: =Inputs!$C$13*PORTUGAL!D12 -> 2120384 | U29: LCV | V29: =PORTUGAL!D20 -> 262.5 | W29: =PORTUGAL!E12 -> 5491 | X29: =V29*W29 -> 1441387.5 | AA29: =IFERROR(AB29/W29,0) -> 470.4 | AB29: =Inputs!$C$13*(1+Inputs!$B$9)*PORTUGAL!E12 -> 2582966.4 | AE29: LCV | AF29: =PORTUGAL!E20 -> 270.375 | AG29: =PORTUGAL!F12 -> 6226 | AH29: =AF29*AG29 -> 1683354.8 | AK29: =IFERROR(AL29/AG29,0) -> 484.512 | AL29: =Inputs!$C$13*(1+Inputs!$B$9)*(1+'Dashboard (2)'!$T$1)*PORTUGAL!F12 -> 3016571.7 | AO29: LCV | AP29: =PORTUGAL!F20 -> 278.48625 | AQ29: =PORTUGAL!G12 -> 6879 | AR29: =AP29*AQ29 -> 1915706.9 | AU29: =IFERROR(AV29/AQ29,0) -> 499.04736 | AV29: =Inputs!$C$13*(1+Inputs!$B$9)*(1+'Dashboard (2)'!$T$1)*(1+'Dashboard (2)'!$T$1)*PORTUGAL!G12 -> 3432946.8 | AY29: LCV | AZ29: =PORTUGAL!G20 -> 286.84084 | BA29: =PORTUGAL!H12 -> 7513 | BB29: =AZ29*BA29 -> 2155035.2 | BE29: =IFERROR(BF29/BA29,0) -> 514.01878 | BF29: =Inputs!$C$13*(1+Inputs!$B$9)*(1+'Dashboard (2)'!$T$1)*(1+'Dashboard (2)'!$T$1)*(1+'Dashboard (2)'!$T$1)*PORTUGAL!H12 -> 3861823.1 | BI29: LCV | BJ29: =PORTUGAL!H20 -> 295.44606 | BK29: =PORTUGAL!I12 -> 8128 | BL29: =BJ29*BK29 -> 2401385.6 | BO29: =IFERROR(BP29/BK29,0) -> 529.43934 | BP29: =Inputs!$C$13*(1+Inputs!$B$9)*(1+'Dashboard (2)'!$T$1)*(1+'Dashboard (2)'!$T$1)*(1+'Dashboard (2)'!$T$1)*(1+'Dashboard (2)'!$T$1)*PORTUGAL!I12 -> 4303283
M30: =SUM(M27:M29) -> 7208 | N30: =SUM(N27:N29) -> 3052087 | O30: =PORTUGAL!D26 -> 1813146.9 | P30: =O30/N30 -> 0.59406788 | R30: =SUM(R27:R29) -> 4952640 | S30: =IF(ISNUMBER(Dashboard!Q18),Dashboard!Q18,"no KPI data") -> 4047903 | T30: n/a | W30: =SUM(W27:W29) -> 8444 | X30: =SUM(X27:X29) -> 3788245.6 | Y30: =Z30/X30 -> 0.50853561 | Z30: =PORTUGAL!E30 -> 1926457.8 | AB30: =SUM(AB27:AB29) -> 6139660.8 | AC30: =IF(ISNUMBER(S30),S30+Dashboard!G18/(1-Inputs!$B$18),"no KPI data") -> 4152808.3 | AD30: n/a | AG30: =SUM(AG27:AG29) -> 9654 | AH30: =SUM(AH27:AH29) -> 4495778.2 | AI30: =IF(Y30>=Inputs!$B$38,Y30,MIN(Y30+'Dashboard (2)'!$N$2,Inputs!$B$38)) -> 0.51853561 | AJ30: =AH30*AI30 -> 2331221.1 | AL30: =SUM(AL27:AL29) -> 7278823.8 | AM30: =IF(ISNUMBER(AC30),AC30*AJ30/Z30,"no KPI data") -> 5025344.5 | AN30: n/a | AQ30: =SUM(AQ27:AQ29) -> 10768 | AR30: =SUM(AR27:AR29) -> 5207497.9 | AS30: =IF(AI30>=Inputs!$B$38,AI30,MIN(AI30+'Dashboard (2)'!$N$2,Inputs!$B$38)) -> 0.52853561 | AT30: =AR30*AS30 -> 2752348.1 | AV30: =SUM(AV27:AV29) -> 8421673.7 | AW30: =IF(ISNUMBER(AM30),AM30*AT30/AJ30,"no KPI data") -> 5933155.6 | AX30: n/a | BA30: =SUM(BA27:BA29) -> 11850 | BB30: =SUM(BB27:BB29) -> 5941062.3 | BC30: =IF(AS30>=Inputs!$B$38,AS30,MIN(AS30+'Dashboard (2)'!$N$2,Inputs!$B$38)) -> 0.53853561 | BD30: =BB30*BC30 -> 3199473.6 | BF30: =SUM(BF27:BF29) -> 9599557.7 | BG30: =IF(ISNUMBER(AW30),AW30*BD30/AT30,"no KPI data") -> 6897010.9 | BH30: n/a | BK30: =SUM(BK27:BK29) -> 12899 | BL30: =SUM(BL27:BL29) -> 6695588.9 | BM30: =IF(BC30>=Inputs!$B$38,BC30,MIN(BC30+'Dashboard (2)'!$N$2,Inputs!$B$38)) -> 0.54853561 | BN30: =BL30*BM30 -> 3672769 | BP30: =SUM(BP27:BP29) -> 10811151 | BQ30: =IF(ISNUMBER(BG30),BG30*BN30/BD30,"no KPI data") -> 7917279.7 | BR30: n/a
A31: IRELAND | B31: mixed | C31: =Dashboard!C19 -> 1267443.4 | D31: =Dashboard!D19 -> 1287772.5 | E31: =Dashboard!E19 -> 0.98421371 | F31: =Dashboard!F19 -> 0.018 | G31: =Dashboard!G19 -> 23179.905 | H31: =Dashboard!H19 -> 1.0022137 | I31: =Dashboard!I19 -> 1290623.3 | K31: CV N | L31: =IRELAND!C17 -> 739 | M31: =IRELAND!D9 -> 731 | N31: =L31*M31 -> 540209 | Q31: =IFERROR(R31/M31,0) -> 1120 | R31: =Inputs!$C$14*IRELAND!D9 -> 818720 | U31: CV N | V31: =IRELAND!D17 -> 775.95 | W31: =IRELAND!E9 -> 925 | X31: =V31*W31 -> 717753.75 | AA31: =IFERROR(AB31/W31,0) -> 1176 | AB31: =Inputs!$C$14*(1+Inputs!$B$9)*IRELAND!E9 -> 1087800 | AE31: CV N | AF31: =IRELAND!E17 -> 799.2285 | AG31: =IRELAND!F9 -> 1113 | AH31: =AF31*AG31 -> 889541.32 | AK31: =IFERROR(AL31/AG31,0) -> 1211.28 | AL31: =Inputs!$C$14*(1+Inputs!$B$9)*(1+'Dashboard (2)'!$T$1)*IRELAND!F9 -> 1348154.6 | AO31: CV N | AP31: =IRELAND!F17 -> 823.20536 | AQ31: =IRELAND!G9 -> 1296 | AR31: =AP31*AQ31 -> 1066874.1 | AU31: =IFERROR(AV31/AQ31,0) -> 1247.6184 | AV31: =Inputs!$C$14*(1+Inputs!$B$9)*(1+'Dashboard (2)'!$T$1)*(1+'Dashboard (2)'!$T$1)*IRELAND!G9 -> 1616913.4 | AY31: CV N | AZ31: =IRELAND!G17 -> 847.90152 | BA31: =IRELAND!H9 -> 1473 | BB31: =AZ31*BA31 -> 1248958.9 | BE31: =IFERROR(BF31/BA31,0) -> 1285.047 | BF31: =Inputs!$C$14*(1+Inputs!$B$9)*(1+'Dashboard (2)'!$T$1)*(1+'Dashboard (2)'!$T$1)*(1+'Dashboard (2)'!$T$1)*IRELAND!H9 -> 1892874.2 | BI31: CV N | BJ31: =IRELAND!H17 -> 873.33856 | BK31: =IRELAND!I9 -> 1645 | BL31: =BJ31*BK31 -> 1436641.9 | BO31: =IFERROR(BP31/BK31,0) -> 1323.5984 | BP31: =Inputs!$C$14*(1+Inputs!$B$9)*(1+'Dashboard (2)'!$T$1)*(1+'Dashboard (2)'!$T$1)*(1+'Dashboard (2)'!$T$1)*(1+'Dashboard (2)'!$T$1)*IRELAND!I9 -> 2177319.3
K32: CV F | L32: =IFERROR(N32/M32,0) -> 887 | M32: =IRELAND!D10+IRELAND!D11 -> 92 | N32: =IRELAND!C18*IRELAND!D10+IRELAND!C19*IRELAND!D11 -> 81604 | Q32: =IFERROR(R32/M32,0) -> 1344 | R32: =Inputs!$C$15*IRELAND!D10+Inputs!$C$15*IRELAND!D11 -> 123648 | U32: CV F | V32: =IFERROR(X32/W32,0) -> 931.35 | W32: =IRELAND!E10+IRELAND!E11 -> 125 | X32: =IRELAND!D18*IRELAND!E10+IRELAND!D19*IRELAND!E11 -> 116418.75 | AA32: =IFERROR(AB32/W32,0) -> 1411.2 | AB32: =Inputs!$C$15*(1+Inputs!$B$9)*IRELAND!E10+Inputs!$C$15*(1+Inputs!$B$9)*IRELAND!E11 -> 176400 | AE32: CV F | AF32: =IFERROR(AH32/AG32,0) -> 959.2905 | AG32: =IRELAND!F10+IRELAND!F11 -> 157 | AH32: =IRELAND!E18*IRELAND!F10+IRELAND!E19*IRELAND!F11 -> 150608.61 | AK32: =IFERROR(AL32/AG32,0) -> 1453.536 | AL32: =Inputs!$C$15*(1+Inputs!$B$9)*(1+'Dashboard (2)'!$T$1)*IRELAND!F10+Inputs!$C$15*(1+Inputs!$B$9)*(1+'Dashboard (2)'!$T$1)*IRELAND!F11 -> 228205.15 | AO32: CV F | AP32: =IFERROR(AR32/AQ32,0) -> 988.06921 | AQ32: =IRELAND!G10+IRELAND!G11 -> 188 | AR32: =IRELAND!F18*IRELAND!G10+IRELAND!F19*IRELAND!G11 -> 185757.01 | AU32: =IFERROR(AV32/AQ32,0) -> 1497.1421 | AV32: =Inputs!$C$15*(1+Inputs!$B$9)*(1+'Dashboard (2)'!$T$1)*(1+'Dashboard (2)'!$T$1)*IRELAND!G10+Inputs!$C$15*(1+Inputs!$B$9)*(1+'Dashboard (2)'!$T$1)*(1+'Dashboard (2)'!$T$1)*IRELAND!G11 -> 281462.71 | AY32: CV F | AZ32: =IFERROR(BB32/BA32,0) -> 1017.7113 | BA32: =IRELAND!H10+IRELAND!H11 -> 219 | BB32: =IRELAND!G18*IRELAND!H10+IRELAND!G19*IRELAND!H11 -> 222878.77 | BE32: =IFERROR(BF32/BA32,0) -> 1542.0563 | BF32: =Inputs!$C$15*(1+Inputs!$B$9)*(1+'Dashboard (2)'!$T$1)*(1+'Dashboard (2)'!$T$1)*(1+'Dashboard (2)'!$T$1)*IRELAND!H10+Inputs!$C$15*(1+Inputs!$B$9)*(1+'Dashboard (2)'!$T$1)*(1+'Dashboard (2)'!$T$1)*(1+'Dashboard (2)'!$T$1)*IRELAND!H11 -> 337710.34 | BI32: CV F | BJ32: =IFERROR(BL32/BK32,0) -> 1048.2426 | BK32: =IRELAND!I10+IRELAND!I11 -> 249 | BL32: =IRELAND!H18*IRELAND!I10+IRELAND!H19*IRELAND!I11 -> 261012.41 | BO32: =IFERROR(BP32/BK32,0) -> 1588.318 | BP32: =Inputs!$C$15*(1+Inputs!$B$9)*(1+'Dashboard (2)'!$T$1)*(1+'Dashboard (2)'!$T$1)*(1+'Dashboard (2)'!$T$1)*(1+'Dashboard (2)'!$T$1)*IRELAND!I10+Inputs!$C$15*(1+Inputs!$B$9)*(1+'Dashboard (2)'!$T$1)*(1+'Dashboard (2)'!$T$1)*(1+'Dashboard (2)'!$T$1)*(1+'Dashboard (2)'!$T$1)*IRELAND!I11 -> 395491.19
