Workbook

Sheet Dashboard (2)
A1: ISZE — FY2027 GPS Extended Target
A2: ISZE->DB level only. Stretch % lives on each DB tab. Everything here and on Waterfall VP is live. Dealer-level (DB->DLR) dropped — see WATCH.
K3: 2025年度 | L3: FY2026 | U3: 2026年度 | V3: FY2027 | AE3: 2027年度 | AF3: FY2028 | AO3: 2028年度 | AP3: FY2029 | AY3: 2029年度 | AZ3: FY2030 | BI3: 2030年度 | BJ3: FY2031
A4: DB | B4: Segment | C4: BP FY27 | D4: Max spend | E4: GPS % | F4: Stretch% | G4: Stretch EUR | H4: New GPS | I4: EXT TARGET | J4: Note | K4: ISZE台当たり単価 | M4: UIO | N4: ISZE部品販売 ポテンシャル | O4: ISZE部品売上実績 | P4: ISZE部品カバー率 (実績) | Q4: 販社台当たり単価 | R4: 販社部品販売ポテンシャル | S4: 販社部品販売 (実績) | T4: 販社部品カバー率 (実績) | U4: ISZE台当たり単価 | W4: UIO | X4: ISZE 部品販売 ポテンシャル | Y4: ISZE 部品カバー率 (目標) | Z4: ISZE部品売上目標 | AA4: 販社台当たり単価 | AB4: 販社部品販売ポテンシャル | AC4: 販社部品販売目標 | AD4: 販社部品カバー率(目標) | AE4: ISZE台当たり単価 | AG4: UIO | AH4: ISZE 部品販売 ポテンシャル | AI4: ISZE 部品カバー率 (目標) | AJ4: ISZE部品売上目標 | AK4: 販社台当たり単価 | AL4: 販社部品販売ポテンシャル | AM4: 販社部品販売目標 | AN4: 販社部品カバー率(目標) | AO4: ISZE台当たり単価 | AQ4: UIO | AR4: ISZE 部品販売 ポテンシャル | AS4: ISZE 部品カバー率 (目標) | AT4: ISZE部品売上目標 | AU4: 販社台当たり単価 | AV4: 販社部品販売ポテンシャル | AW4: 販社部品販売目標 | AX4: 販社部品カバー率(目標) | AY4: ISZE台当たり単価 | BA4: UIO | BB4: ISZE 部品販売 ポテンシャル | BC4: ISZE 部品カバー率 (目標) | BD4: ISZE部品売上目標 | BE4: 販社台当たり単価 | BF4: 販社部品販売ポテンシャル | BG4: 販社部品販売目標 | BH4: 販社部品カバー率(目標) | BI4: ISZE台当たり単価 | BK4: UIO | BL4: ISZE 部品販売 ポテンシャル | BM4: ISZE 部品カバー率 (目標) | BN4: ISZE部品売上目標 | BO4: 販社台当たり単価 | BP4: 販社部品販売ポテンシャル | BQ4: 販社部品販売目標 | BR4: 販社部品カバー率(目標)
K5: ISZE Parts Sales per Unit | N5: ISZE Parts Sles Potential | O5: ISZE Parts Sales Actual | P5: ISZE Share Actual | Q5: Distributor's Parts Sales per Unit | R5: Distributor's Parts Sales Potential | S5: Distributor Parts Sales Actual | T5: Dist Parts Share Actual | U5: ISZE Parts Sales per Unit | X5: ISZE Parts Sles Potential | Y5: ISZE Target Share | Z5: ISZE Parts Sales Target | AA5: Distributor's Parts Sales per Unit | AB5: Distributor's Parts Sales Potential | AC5: Distributor Parts Sales Target | AD5: Distributor Parts Share target | AE5: ISZE Parts Sales per Unit | AH5: ISZE Parts Sles Potential | AI5: ISZE Target Share | AJ5: ISZE Parts Sales Target | AK5: Distributor's Parts Sales per Unit | AL5: Distributor's Parts Sales Potential | AM5: Distributor Parts Sales Target | AN5: Distributor Parts Share target | AO5: ISZE Parts Sales per Unit | AR5: ISZE Parts Sles Potential | AS5: ISZE Target Share | AT5: ISZE Parts Sales Target | AU5: Distributor's Parts Sales per Unit | AV5: Distributor's Parts Sales Potential | AW5: Distributor Parts Sales Target | AX5: Distributor Parts Share target | AY5: ISZE Parts Sales per Unit | BB5: ISZE Parts Sles Potential | BC5: ISZE Target Share | BD5: ISZE Parts Sales Target | BE5: Distributor's Parts Sales per Unit | BF5: Distributor's Parts Sales Potential | BG5: Distributor Parts Sales Target | BH5: Distributor Parts Share target | BI5: ISZE Parts Sales per Unit | BL5: ISZE Parts Sles Potential | BM5: ISZE Target Share | BN5: ISZE Parts Sales Target | BO5: Distributor's Parts Sales per Unit | BP5: Distributor's Parts Sales Potential | BQ5: Distributor Parts Sales Target | BR5: Distributor Parts Share target
A6: ITUK | B6: presented | C6: 6974170.1 | D6: 13051953 | E6: 0.53433921 | G6: 376073.91 | I6: 7350244 | J6: V4 basis (CY2027F, no +5%) — NOT rebased | K6: N35 | L6: 281.6 | M6: 11444 | N6: =L6*M6 -> 3222630.4 | Q6: =400*1.12 -> 448 | R6: =Q6*M6 -> 5126912 | U6: N35 | V6: 295.68 | W6: 12345 | X6: =V6*W6 -> 3650169.6 | AA6: =400*1.12*1.03 -> 461.44 | AB6: =AA6*W6 -> 5696476.8
K7: N75 | L7: 704 | M7: 10747 | N7: =L7*M7 -> 7565888 | Q7: =1000*1.12 -> 1120 | R7: =Q7*M7 -> 12036640 | U7: N75 | V7: 739.2 | W7: 10865 | X7: =V7*W7 -> 8031408 | AA7: =1000*1.12*1.03 -> 1153.6 | AB7: =AA7*W7 -> 12533864
K8: F | L8: 844.8 | M8: 877 | N8: =L8*M8 -> 740889.6 | Q8: =1200*1.12 -> 1344 | R8: =Q8*M8 -> 1178688 | U8: F | V8: 887.04 | W8: 963 | X8: =V8*W8 -> 854219.52 | AA8: =1200*1.12*1.03 -> 1384.32 | AB8: =AA8*W8 -> 1333100.2
M9: =SUM(M6:M8) -> 23068 | N9: =SUM(N6:N8) -> 11529408 | O9: 6658172.1 | P9: =O9/N9 -> 0.5774947 | R9: =SUM(R6:R8) -> 18342240 | S9: =12873997.67*1.12 -> 14418877 | T9: =S9/R9 -> 0.78610232 | W9: =SUM(W6:W8) -> 24173 | X9: =SUM(X6:X8) -> 12535797 | Y9: =Z9/X9 -> 0.58634037 | Z9: 7350244 | AB9: =SUM(AB6:AB8) -> 19563441 | AC9: =AB9*(0.786+0.018) -> 15729007 | AD9: =AC9/AB9 -> 0.804
A10: UTI | B10: presented | C10: 3098113.5 | D10: 8834692 | E10: 0.35067589 | G10: 159024.46 | I10: 3257138 | J10: V4 basis (CY2027F, no +5%) — NOT rebased | K10: CV | L10: =V10/1.05 -> 751.02929 | M10: 10336 | N10: =L10*M10 -> 7762638.8 | O10: 2895270 | P10: =O10/N10 -> 0.37297497 | U10: CV | V10: =X10/W10 -> 788.58076 | W10: 10760 | X10: 8485129 | Y10: =Z10/X10 -> 0.38386428 | Z10: 3257138
A11: IUK | B11: LCV | C11: 6062956.5 | D11: 11361161 | E11: 0.53365642 | F11: 0.018 | G11: 204500.9 | H11: 0.55165642 | I11: 6267457.4 | K11: LCV | L11: 219.5648 | M11: =[1]IUK!D9 -> 47783 | N11: =L11*M11 -> 10491465 | O11: 5682505 | P11: =O11/N11 -> 0.54163123 | U11: LCV | V11: =[1]IUK!E14 -> 230.54304 | W11: =[1]IUK!E9 -> 49280 | X11: =V11*W11 -> 11361161 | Y11: =Z11/X11 -> 0.55165642 | Z11: 6267457.4
A12: UMI | B12: LCV | C12: 2973279.3 | D12: 4354035.9 | E12: 0.68287893 | F12: 0.018 | G12: 78372.645 | H12: 0.70087893 | I12: 3051652 | K12: LCV | L12: =[1]IUK!D14 -> 219.5648 | M12: =[1]UMI!D9 -> 18542 | N12: =L12*M12 -> 4071170.5 | O12: 2651674.2 | P12: =O12/N12 -> 0.65132969 | U12: LCV | V12: =[1]UMI!E14 -> 230.54304 | W12: =[1]UMI!E9 -> 18886 | X12: =V12*W12 -> 4354035.9 | Y12: =Z12/X12 -> 0.70087893 | Z12: 3051652
A13: NORWAY | B13: LCV | C13: 1764799.8 | D13: 1869934.6 | E13: 0.94377619 | F13: 0.018 | G13: 33658.823 | H13: 0.96177619 | I13: 1798458.6 | K13: LCV | L13: =[1]NORWAY!D14 -> 219.5648 | M13: =[1]NORWAY!D9 -> 7929 | N13: =L13*M13 -> 1740929.3 | O13: 1578970.7 | P13: =O13/N13 -> 0.90697002 | U13: LCV | V13: =[1]NORWAY!E14 -> 230.54304 | W13: =[1]NORWAY!E9 -> 8111 | X13: =V13*W13 -> 1869934.6 | Y13: =Z13/X13 -> 0.96177619 | Z13: 1798458.6
A14: SWEDEN | B14: LCV | C14: 1464302.3 | D14: 2095636.2 | E14: 0.69873879 | F14: 0.018 | G14: 37721.452 | H14: 0.71673879 | I14: 1502023.8 | K14: LCV | L14: =[1]SWEDEN!D14 -> 219.5648 | M14: =[1]SWEDEN!D9 -> 8443 | N14: =L14*M14 -> 1853785.6 | O14: 1387714.3 | P14: =O14/N14 -> 0.74858402 | U14: LCV | V14: =[1]SWEDEN!E14 -> 230.54304 | W14: =[1]SWEDEN!E9 -> 9090 | X14: =V14*W14 -> 2095636.2 | Y14: =Z14/X14 -> 0.71673879 | Z14: 1502023.8
A15: HUNGARY | B15: LCV | C15: 349600 | D15: 920327.82 | E15: 0.37986465 | F15: 0.018 | G15: 16565.901 | H15: 0.39786465 | I15: 366165.9 | K15: LCV | L15: =[1]HUNGARY!D14 -> 219.5648 | M15: =[1]HUNGARY!D9 -> 3734 | N15: =L15*M15 -> 819854.96 | O15: 349055 | P15: =O15/N15 -> 0.42575213 | U15: LCV | V15: =[1]HUNGARY!E14 -> 230.54304 | W15: =[1]HUNGARY!E9 -> 3992 | X15: =V15*W15 -> 920327.82 | Y15: =Z15/X15 -> 0.39786465 | Z15: 366165.9
A16: FINLAND | B16: LCV | C16: 360300 | D16: 301550.3 | E16: 1.1948256 | F16: 0.018 | G16: 5427.9053 | H16: 1.2128256 | I16: 365727.91 | K16: LCV | L16: =[1]FINLAND!D14 -> 219.5648 | M16: =[1]FINLAND!D9 -> 1204 | N16: =L16*M16 -> 264356.02 | O16: 328900.8 | P16: =O16/N16 -> 1.2441585 | U16: LCV | V16: =[1]FINLAND!E14 -> 230.54304 | W16: =[1]FINLAND!E9 -> 1308 | X16: =V16*W16 -> 301550.3 | Y16: =Z16/X16 -> 1.2128256 | Z16: 365727.91
A17: ROMANIA | B17: LCV | C17: 199587.57 | D17: 278726.54 | E17: 0.7160695 | F17: 0.018 | G17: 5017.0776 | H17: 0.7340695 | I17: 204604.65 | K17: LCV | L17: =[1]ROMANIA!D14 -> 219.5648 | M17: =[1]ROMANIA!D9 -> 1071 | N17: =L17*M17 -> 235153.9 | O17: 182754.93 | P17: =O17/N17 -> 0.77717159 | U17: LCV | V17: =[1]ROMANIA!E14 -> 230.54304 | W17: =[1]ROMANIA!E9 -> 1209 | X17: =V17*W17 -> 278726.54 | Y17: =Z17/X17 -> 0.7340695 | Z17: 204604.65
A18: DENMARK | B18: LCV | C18: 187600 | D18: 217632.63 | E18: 0.86200309 | F18: 0.018 | G18: 3917.3873 | H18: 0.88000309 | I18: 191517.39 | K18: LCV | L18: =[1]DENMARK!D14 -> 219.5648 | M18: =[1]DENMARK!D9 -> 850 | N18: =L18*M18 -> 186630.08 | O18: 174827.66 | P18: =O18/N18 -> 0.93676036 | U18: LCV | V18: =[1]DENMARK!E14 -> 230.54304 | W18: =[1]DENMARK!E9 -> 944 | X18: =V18*W18 -> 217632.63 | Y18: =Z18/X18 -> 0.88000309 | Z18: 191517.39
A19: ICELAND | B19: LCV | C19: 104600 | D19: 101208.39 | E19: 1.0335111 | F19: 0.018 | G19: 1821.7511 | H19: 1.0515111 | I19: 106421.75 | K19: LCV | L19: =[1]ICELAND!D14 -> 219.5648 | M19: =[1]ICELAND!D9 -> 406 | N19: =L19*M19 -> 89143.309 | O19: 89209.04 | P19: =O19/N19 -> 1.0007374 | U19: LCV | V19: =[1]ICELAND!E14 -> 230.54304 | W19: =[1]ICELAND!E9 -> 439 | X19: =V19*W19 -> 101208.39 | Y19: =Z19/X19 -> 1.0515111 | Z19: 106421.75
A20: GERMANY | B20: mixed | C20: 2913662.8 | D20: 4007354.9 | E20: 0.72707881 | F20: 0.018 | G20: 72132.388 | H20: 0.74507881 | I20: 2985795.2 | K20: CV LD | L20: =[1]GERMANY!C17 -> 739 | M20: =[1]GERMANY!D9 -> 697 | N20: =L20*M20 -> 515083 | U20: CV LD | V20: =[1]GERMANY!D17 -> 775.95 | W20: =[1]GERMANY!E9 -> 1066 | X20: =V20*W20 -> 827162.7
K21: CV MD | L21: =[1]GERMANY!C18 -> 887 | M21: =[1]GERMANY!D10 -> 35 | N21: =L21*M21 -> 31045 | U21: CV MD | V21: =[1]GERMANY!D18 -> 931.35 | W21: =[1]GERMANY!E10 -> 34 | X21: =V21*W21 -> 31665.9
K22: LCV | L22: =[1]GERMANY!C20 -> 219.5648 | M22: =[1]GERMANY!D12 -> 13048 | N22: =L22*M22 -> 2864881.5 | U22: LCV | V22: =[1]GERMANY!D20 -> 230.54304 | W22: =[1]GERMANY!E12 -> 13657 | X22: =V22*W22 -> 3148526.3
M23: =SUM(M20:M22) -> 13780 | N23: =SUM(N20:N22) -> 3411009.5 | O23: 2661850.4 | P23: =O23/N23 -> 0.78037028 | W23: =SUM(W20:W22) -> 14757 | X23: =SUM(X20:X22) -> 4007354.9 | Y23: =Z23/X23 -> 0.74507881 | Z23: 2985795.2
A24: BELGIUM | B24: mixed | C24: 2296577.3 | D24: 2419787.5 | E24: 0.94908224 | F24: 0.018 | G24: 43556.175 | H24: 0.96708224 | I24: 2340133.5 | K24: CV LD | L24: =[1]BELGIUM!C17 -> 739 | M24: =[1]BELGIUM!D9 -> 113 | N24: =L24*M24 -> 83507 | U24: CV LD | V24: =[1]BELGIUM!D17 -> 775.95 | W24: =[1]BELGIUM!E9 -> 145 | X24: =V24*W24 -> 112512.75
K25: LCV | L25: =[1]BELGIUM!C20 -> 219.5648 | M25: =[1]BELGIUM!D12 -> 9452 | N25: =L25*M25 -> 2075326.5 | U25: LCV | V25: =[1]BELGIUM!D20 -> 230.54304 | W25: =[1]BELGIUM!E12 -> 10008 | X25: =V25*W25 -> 2307274.7
M26: =SUM(M24:M25) -> 9565 | N26: =SUM(N24:N25) -> 2158833.5 | O26: 2152712.5 | P26: =O26/N26 -> 0.99716467 | W26: =SUM(W24:W25) -> 10153 | X26: =SUM(X24:X25) -> 2419787.5 | Y26: =Z26/X26 -> 0.96708224 | Z26: 2340133.5
A27: PORTUGAL | B27: mixed | C27: 1858269.4 | D27: 3612770 | E27: 0.51436139 | F27: 0.018 | G27: 65029.86 | H27: 0.53236139 | I27: 1923299.3 | K27: CV N | L27: =[1]PORTUGAL!C17 -> 739 | M27: =[1]PORTUGAL!D9 -> 2206 | N27: =L27*M27 -> 1630234 | U27: CV N | V27: =[1]PORTUGAL!D17 -> 775.95 | W27: =[1]PORTUGAL!E9 -> 2596 | X27: =V27*W27 -> 2014366.2
K28: CV F | L28: =[1]PORTUGAL!C19 -> 887 | M28: =[1]PORTUGAL!D11 -> 269 | N28: =L28*M28 -> 238603 | U28: CV F | V28: =[1]PORTUGAL!D19 -> 931.35 | W28: =[1]PORTUGAL!E10+[1]PORTUGAL!E11 -> 357 | X28: =V28*W28 -> 332491.95
K29: LCV | L29: =[1]PORTUGAL!C20 -> 219.5648 | M29: =[1]PORTUGAL!D12 -> 4733 | N29: =L29*M29 -> 1039200.2 | U29: LCV | V29: =[1]PORTUGAL!D20 -> 230.54304 | W29: =[1]PORTUGAL!E12 -> 5491 | X29: =V29*W29 -> 1265911.8
M30: =SUM(M27:M29) -> 7208 | N30: =SUM(N27:N29) -> 2908037.2 | O30: 1795020.2 | P30: =O30/N30 -> 0.61726177 | W30: =SUM(W27:W29) -> 8444 | X30: =SUM(X27:X29) -> 3612770 | Y30: =Z30/X30 -> 0.53236139 | Z30: 1923299.3
A31: IRELAND | B31: mixed | C31: 1267443.4 | D31: 1232550.9 | E31: 1.0283092 | F31: 0.018 | G31: 22185.916 | H31: 1.0463092 | I31: 1289629.3 | K31: CV N | L31: =[1]IRELAND!C17 -> 739 | M31: =[1]IRELAND!D9 -> 731 | N31: =L31*M31 -> 540209 | U31: CV N | V31: =[1]IRELAND!D17 -> 775.95 | W31: =[1]IRELAND!E9 -> 925 | X31: =V31*W31 -> 717753.75
K32: CV F | L32: =[1]IRELAND!C19 -> 887 | M32: =[1]IRELAND!D11 -> 92 | N32: =L32*M32 -> 81604 | U32: CV F | V32: =[1]IRELAND!D19 -> 931.35 | W32: =[1]IRELAND!E10+[1]IRELAND!E11 -> 125 | X32: =V32*W32 -> 116418.75
K33: LCV | L33: =[1]IRELAND!C20 -> 219.5648 | M33: =[1]IRELAND!D12 -> 1338 | N33: =L33*M33 -> 293777.7 | U33: LCV | V33: =[1]IRELAND!D20 -> 230.54304 | W33: =[1]IRELAND!E12 -> 1728 | X33: =V33*W33 -> 398378.37
M34: =SUM(M31:M33) -> 2161 | N34: =SUM(N31:N33) -> 915590.7 | O34: 1137820 | P34: =O34/N34 -> 1.2427168 | W34: =SUM(W31:W33) -> 2778 | X34: =SUM(X31:X33) -> 1232550.9 | Y34: =Z34/X34 -> 1.0463092 | Z34: 1289629.3
A35: GREECE | B35: mixed | C35: 574400 | D35: 1021923.8 | E35: 0.56207716 | F35: 0.018 | G35: 18394.628 | H35: 0.58007716 | I35: 592794.63 | K35: CV N | L35: =[1]GREECE!C17 -> 739 | M35: =[1]GREECE!D9 -> 37 | N35: =L35*M35 -> 27343 | U35: CV N | V35: =[1]GREECE!D17 -> 775.95 | W35: =[1]GREECE!E9 -> 56 | X35: =V35*W35 -> 43453.2
K36: LCV | L36: =[1]GREECE!C20 -> 219.5648 | M36: =[1]GREECE!D12 -> 3705 | N36: =L36*M36 -> 813487.58 | U36: LCV | V36: =[1]GREECE!D20 -> 230.54304 | W36: =[1]GREECE!E12 -> 4224 | X36: =V36*W36 -> 973813.8
M37: =SUM(M35:M36) -> 3742 | N37: =SUM(N35:N36) -> 840830.58 | O37: 471585.68 | P37: =O37/N37 -> 0.56085695 | W37: =SUM(W35:W36) -> 4280 | X37: =SUM(X35:X36) -> 1017267 | Y37: =Z37/X37 -> 0.58273258 | Z37: 592794.63
A38: CYPRUS | B38: mixed | C38: 539600 | D38: 734561.78 | E38: 0.73458763 | F38: 0.018 | G38: 13222.112 | H38: 0.75258763 | I38: 552822.11 | K38: CV N | L38: =[1]CYPRUS!C17 -> 739 | M38: =[1]CYPRUS!D9 -> 203 | N38: =L38*M38 -> 150017 | U38: CV N | V38: =[1]CYPRUS!D17 -> 775.95 | W38: =[1]CYPRUS!E9+[1]CYPRUS!E10 -> 232 | X38: =V38*W38 -> 180020.4
K39: LCV | L39: =[1]CYPRUS!C20 -> 219.5648 | M39: =[1]CYPRUS!D12 -> 2105 | N39: =L39*M39 -> 462183.9 | U39: LCV | V39: =[1]CYPRUS!D20 -> 230.54304 | W39: =[1]CYPRUS!E12 -> 2402 | X39: =V39*W39 -> 553764.38
M40: =SUM(M38:M39) -> 2308 | N40: =SUM(N38:N39) -> 612200.9 | O40: 410727.51 | P40: =O40/N40 -> 0.67090314 | W40: =SUM(W38:W39) -> 2634 | X40: =SUM(X38:X39) -> 733784.78 | Y40: =Z40/X40 -> 0.75338454 | Z40: 552822.11
...

Sheet Dashboard
A1: ISZE — FY2027 GPS Extended Target
A2: ISZE->DB level only (columns A:J). Stretch % lives on each DB tab. Everything here and on Waterfall VP is live. Dealer-level (DB->DLR) GPS% blend dropped — see WATCH. Two blocks added 22-07-2026, clearly separated by level: L:M = ISZE→DB billing actuals (reference only); O:U = DB→DLR Sales-to-Dealer, a SEPARATE track, NOT blended into A:J. See Method tab.
A3: ISZE → DB (billing / GPS% — unchanged, live) | M3: ISZE → DB (billing actuals, ref only) | P3: DB → DLR (Sales to Dealer — separate track, NOT GPS)
A4: DB | B4: Segment | C4: BP FY27 | D4: Max spend | E4: GPS % | F4: Stretch% | G4: Stretch EUR | H4: New GPS | I4: EXT TARGET | J4: Note | M4: ISZE billing FY25 (EUR) | N4: ISZE billing FY26 (EUR) | P4: Sales to Dealer FY25 (EUR) | Q4: Sales to Dealer FY26 (EUR) | R4: UIO growth FY26→FY27 | S4: Price increase FY27 | T4: Add'l growth (small, bounded 0.5–4%) | U4: Sales to Dealer FY27 TARGET (EUR) | V4: S2D Note (S2D = Sales-to-Dealer, i.e. this whole DB→DLR block) | W4: Rationale
A5: ITUK | B5: presented | C5: 6974170.1 | D5: 13051953 | E5: =C5/D5 -> 0.53433921 | G5: 376073.91 | I5: =C5+G5 -> 7350244 | J5: V4 basis (CY2027F, no +5%) — NOT rebased | L5: =G5*0.33/2 -> 62052.196 | M5: 5668549 | N5: 6658172 | P5: Skipped | W5: N/A — skipped for this round (see S2D Note).
A6: UTI | B6: presented | C6: 3098113.5 | D6: 8834692 | E6: =C6/D6 -> 0.35067589 | G6: 159024.46 | I6: =C6+G6 -> 3257138 | J6: V4 basis (CY2027F, no +5%) — NOT rebased | L6: =G6*0.33/2 -> 26239.035 | P6: Skipped | W6: N/A — skipped for this round (see S2D Note).
A7: IUK | B7: LCV | C7: =IUK!E20 -> 6062956.5 | D7: =IUK!E19 -> 11361161 | E7: =IUK!E21 -> 0.53365642 | F7: =IUK!E22 -> 0.018 | G7: =IUK!E23 -> 204500.9 | H7: =IUK!E25 -> 0.55165642 | I7: =IUK!E24 -> 6267457.4 | L7: =G7*0.33/2 -> 33742.648 | M7: 7154801 | N7: 5682505 | P7: 18843293 | Q7: 21418279 | R7: 0.031329134 | S7: 0.05 | T7: 0.018 | U7: 22981703 | V7: full 12/12 monthly coverage both FY25 and FY26 | W7: Historical non-UIO growth signal was +16% (above peers), ranking 7/10 strongest among the 10 comparable DBs. Banded across the peer range (0.5%-4%) by rank, floored to nearest 0.5% -> 2.5% suggested. Jerome set 2.0% instead (22-07-2026) — used as final.
A8: UMI | B8: LCV | C8: =UMI!E20 -> 2973279.3 | D8: =UMI!E19 -> 4354035.9 | E8: =UMI!E21 -> 0.68287893 | F8: =UMI!E22 -> 0.018 | G8: =UMI!E23 -> 78372.645 | H8: =UMI!E25 -> 0.70087893 | I8: =UMI!E24 -> 3051652 | L8: =G8*0.33/2 -> 12931.486 | M8: 5755871 | N8: 5546944 | P8: Insufficient data | S8: 0.05 | T8: 0.018 | V8: Insufficient data — KPI marks UMI DB→DLR "Internal only", no figures. | W8: N/A — insufficient data, no target set (see S2D Note).
A9: NORWAY | B9: LCV | C9: =NORWAY!E20 -> 1764799.8 | D9: =NORWAY!E19 -> 1869934.6 | E9: =NORWAY!E21 -> 0.94377619 | F9: =NORWAY!E22 -> 0.018 | G9: =NORWAY!E23 -> 33658.823 | H9: =NORWAY!E25 -> 0.96177619 | I9: =NORWAY!E24 -> 1798458.6 | L9: =G9*0.33/2 -> 5553.7058 | M9: 1156859 | N9: 1454525 | P9: 3367988 | Q9: 5248795 | R9: 0.022953714 | S9: 0.05 | T9: 0.018 | U9: 5640960 | V9: FY26 annualized from 11/12 months | W9: Historical non-UIO growth signal was +62% (above peers), ranking 10/10 strongest among the 10 comparable DBs. Banded across the peer range (0.5%-4%) by rank, floored to nearest 0.5% -> 4.0% suggested. Jerome set 3.0% instead (22-07-2026) — used as final.
A10: SWEDEN | B10: LCV | C10: =SWEDEN!E20 -> 1464302.3 | D10: =SWEDEN!E19 -> 2095636.2 | E10: =SWEDEN!E21 -> 0.69873879 | F10: =SWEDEN!E22 -> 0.018 | G10: =SWEDEN!E23 -> 37721.452 | H10: =SWEDEN!E25 -> 0.71673879 | I10: =SWEDEN!E24 -> 1502023.8 | L10: =G10*0.33/2 -> 6224.0396 | M10: 1233980 | N10: 1282687 | P10: 2482560 | Q10: 3154222 | R10: 0.076631529 | S10: 0.05 | T10: 0.018 | U10: 3533131 | V10: full 12/12 monthly coverage both FY25 and FY26 | W10: Historical non-UIO growth signal was +9% (above peers), ranking 6/10 strongest among the 10 comparable DBs. Banded across the peer range (0.5%-4%) by rank, floored to nearest 0.5% -> 2.0% suggested.
A11: HUNGARY | B11: LCV | C11: =HUNGARY!E20 -> 349600 | D11: =HUNGARY!E19 -> 920327.82 | E11: =HUNGARY!E21 -> 0.37986465 | F11: =HUNGARY!E22 -> 0.018 | G11: =HUNGARY!E23 -> 16565.901 | H11: =HUNGARY!E25 -> 0.39786465 | I11: =HUNGARY!E24 -> 366165.9 | L11: =G11*0.33/2 -> 2733.3736 | M11: 365622 | N11: 347456 | P11: Insufficient data | S11: 0.05 | T11: 0.018 | V11: Insufficient data — no Hungary/AutoWallis row in the KPI DB→DLR block. | W11: N/A — insufficient data, no target set (see S2D Note).
A12: FINLAND | B12: LCV | C12: =FINLAND!E20 -> 360300 | D12: =FINLAND!E19 -> 301550.3 | E12: =FINLAND!E21 -> 1.1948256 | F12: =FINLAND!E22 -> 0.018 | G12: =FINLAND!E23 -> 5427.9053 | H12: =FINLAND!E25 -> 1.2128256 | I12: =FINLAND!E24 -> 365727.91 | L12: =G12*0.33/2 -> 895.60438 | M12: 267986 | N12: 280753 | P12: Insufficient data | S12: 0.05 | T12: 0.018 | V12: Insufficient data — KPI DB→DLR (IMF/Nordic Auto.) stopped reporting Oct'25, 9 months stale. | W12: N/A — insufficient data, no target set (see S2D Note).
A13: ROMANIA | B13: LCV | C13: =ROMANIA!E20 -> 199587.57 | D13: =ROMANIA!E19 -> 278726.54 | E13: =ROMANIA!E21 -> 0.7160695 | F13: =ROMANIA!E22 -> 0.018 | G13: =ROMANIA!E23 -> 5017.0776 | H13: =ROMANIA!E25 -> 0.7340695 | I13: =ROMANIA!E24 -> 204604.65 | L13: =G13*0.33/2 -> 827.81781 | M13: 155162 | N13: 180500 | P13: 382258 | Q13: 394597 | R13: 0.12885154 | S13: 0.05 | T13: 0.018 | U13: 458894 | V13: full 12/12 monthly coverage both FY25 and FY26 | W13: Historical non-UIO growth signal was -5% (below peers), ranking 2/10 strongest among the 10 comparable DBs. Banded across the peer range (0.5%-4%) by rank, floored to nearest 0.5% -> 0.5% suggested. Jerome set 1.0% instead (22-07-2026) — used as final.
A14: DENMARK | B14: LCV | C14: =DENMARK!E20 -> 187600 | D14: =DENMARK!E19 -> 217632.63 | E14: =DENMARK!E21 -> 0.86200309 | F14: =DENMARK!E22 -> 0.018 | G14: =DENMARK!E23 -> 3917.3873 | H14: =DENMARK!E25 -> 0.88000309 | I14: =DENMARK!E24 -> 191517.39 | L14: =G14*0.33/2 -> 646.36891 | M14: 125038 | N14: 155945 | P14: 356680 | Q14: 572864 | R14: 0.11058824 | S14: 0.05 | T14: 0.018 | U14: 671653 | V14: full 12/12 monthly coverage both FY25 and FY26 | W14: Historical non-UIO growth signal was +57% (above peers), ranking 9/10 strongest among the 10 comparable DBs. Banded across the peer range (0.5%-4%) by rank, floored to nearest 0.5% -> 3.5% suggested.
A15: ICELAND | B15: LCV | C15: =ICELAND!E20 -> 104600 | D15: =ICELAND!E19 -> 101208.39 | E15: =ICELAND!E21 -> 1.0335111 | F15: =ICELAND!E22 -> 0.018 | G15: =ICELAND!E23 -> 1821.7511 | H15: =ICELAND!E25 -> 1.0515111 | I15: =ICELAND!E24 -> 106421.75 | L15: =G15*0.33/2 -> 300.58893 | M15: 76214 | N15: 89209 | P15: 209944 | Q15: 195849 | R15: 0.081280788 | S15: 0.05 | T15: 0.018 | U15: 217083 | V15: full 12/12 monthly coverage both FY25 and FY26 | W15: Historical non-UIO growth signal was -21% (below peers), ranking 1/10 strongest among the 10 comparable DBs. Banded across the peer range (0.5%-4%) by rank, floored to nearest 0.5% -> 0.5% suggested.
A16: GERMANY | B16: mixed | C16: =GERMANY!E26 -> 2913662.8 | D16: =GERMANY!E25 -> 4007354.9 | E16: =GERMANY!E27 -> 0.72707881 | F16: =GERMANY!E28 -> 0.018 | G16: =GERMANY!E29 -> 72132.388 | H16: =GERMANY!E31 -> 0.74507881 | I16: =GERMANY!E30 -> 2985795.2 | L16: =G16*0.33/2 -> 11901.844 | M16: 2614731 | N16: 2661850 | P16: Insufficient data | S16: 0.05 | T16: 0.018 | V16: Insufficient data — KPI DB→DLR (ISD) stopped reporting Mar'25, 15+ months stale. | W16: N/A — insufficient data, no target set (see S2D Note).
A17: BELGIUM | B17: mixed | C17: =BELGIUM!E26 -> 2296577.3 | D17: =BELGIUM!E25 -> 2419787.5 | E17: =BELGIUM!E27 -> 0.94908224 | F17: =BELGIUM!E28 -> 0.018 | G17: =BELGIUM!E29 -> 43556.175 | H17: =BELGIUM!E31 -> 0.96708224 | I17: =BELGIUM!E30 -> 2340133.5 | L17: =G17*0.33/2 -> 7186.7689 | M17: 2286742 | N17: 2152712 | P17: 4867562 | Q17: 6834272 | R17: 0.061474124 | S17: 0.05 | T17: 0.018 | U17: 7621476 | V17: FY25 annualized from 10/12 months | W17: Historical non-UIO growth signal was +36% (above peers), ranking 8/10 strongest among the 10 comparable DBs. Banded across the peer range (0.5%-4%) by rank, floored to nearest 0.5% -> 3.0% suggested.
A18: PORTUGAL | B18: mixed | C18: =PORTUGAL!E26 -> 1858269.4 | D18: =PORTUGAL!E25 -> 3612770 | E18: =PORTUGAL!E27 -> 0.51436139 | F18: =PORTUGAL!E28 -> 0.018 | G18: =PORTUGAL!E29 -> 65029.86 | H18: =PORTUGAL!E31 -> 0.53236139 | I18: =PORTUGAL!E30 -> 1923299.3 | L18: =G18*0.33/2 -> 10729.927 | M18: 1551256 | N18: 1795020 | P18: 3821463 | Q18: 4047903 | R18: 0.17147614 | S18: 0.05 | T18: 0.018 | U18: 4933599 | V18: FY25 annualized from 7/12 months | W18: Historical non-UIO growth signal was +1% (above peers), ranking 5/10 strongest among the 10 comparable DBs. Banded across the peer range (0.5%-4%) by rank, floored to nearest 0.5% -> 2.0% suggested.
A19: IRELAND | B19: mixed | C19: =IRELAND!E26 -> 1267443.4 | D19: =IRELAND!E25 -> 1232550.9 | E19: =IRELAND!E27 -> 1.0283092 | F19: =IRELAND!E28 -> 0.018 | G19: =IRELAND!E29 -> 22185.916 | H19: =IRELAND!E31 -> 1.0463092 | I19: =IRELAND!E30 -> 1289629.3 | L19: =G19*0.33/2 -> 3660.6761 | M19: 1201537 | N19: 1118453 | P19: 2687539 | Q19: 2833637 | R19: 0.28551596 | S19: 0.05 | T19: 0.018 | U19: 3752695 | V19: full 12/12 monthly coverage both FY25 and FY26 | W19: Historical non-UIO growth signal was -5% (below peers), ranking 3/10 strongest among the 10 comparable DBs. Banded across the peer range (0.5%-4%) by rank, floored to nearest 0.5% -> 1.0% suggested.
A20: GREECE | B20: mixed | C20: =GREECE!E26 -> 574400 | D20: =GREECE!E25 -> 1021923.8 | E20: =GREECE!E27 -> 0.56207716 | F20: =GREECE!E28 -> 0.018 | G20: =GREECE!E29 -> 18394.628 | H20: =GREECE!E31 -> 0.58007716 | I20: =GREECE!E30 -> 592794.63 | L20: =G20*0.33/2 -> 3035.1135 | M20: 467826 | N20: 471586 | P20: Insufficient data | S20: 0.05 | T20: 0.018 | V20: Insufficient data — Petros Petropoulos stale since Jun'25 (12+ months). | W20: N/A — insufficient data, no target set (see S2D Note).
A21: CYPRUS | B21: mixed | C21: =CYPRUS!E26 -> 539600 | D21: =CYPRUS!E25 -> 734561.78 | E21: =CYPRUS!E27 -> 0.73458763 | F21: =CYPRUS!E28 -> 0.018 | G21: =CYPRUS!E29 -> 13222.112 | H21: =CYPRUS!E31 -> 0.75258763 | I21: =CYPRUS!E30 -> 552822.11 | L21: =G21*0.33/2 -> 2181.6485 | P21: Insufficient data | S21: 0.05 | T21: 0.018 | V21: Insufficient data — Cyprus's real distributor (Loutsios & Sons) has zero KPI data. KPI's 'MIDI' row is Italy's, not Cyprus's — excluded. | W21: N/A — insufficient data, no target set (see S2D Note).
A22: MALTA | B22: mixed | C22: =MALTA!E26 -> 233100 | D22: =MALTA!E25 -> 397247.5 | E22: =MALTA!E27 -> 0.58678784 | F22: =MALTA!E28 -> 0.018 | G22: =MALTA!E29 -> 7150.455 | H22: =MALTA!E31 -> 0.60478784 | I22: =MALTA!E30 -> 240250.45 | L22: =G22*0.33/2 -> 1179.8251 | M22: 209033 | N22: 196245 | P22: 555482 | Q22: 553873 | R22: 0.065384615 | S22: 0.05 | T22: 0.018 | U22: 610918 | V22: full 12/12 monthly coverage both FY25 and FY26 | W22: Historical non-UIO growth signal was +1% (above peers), ranking 4/10 strongest among the 10 comparable DBs. Banded across the peer range (0.5%-4%) by rank, floored to nearest 0.5% -> 1.5% suggested.
A23: TOTAL | C23: =SUM(C5:C22) -> 33222362 | D23: =SUM(D5:D22) -> 56813054 | E23: =C23/D23 -> 0.58476634 | G23: =SUM(G5:G22) -> 1163773.7 | I23: =SUM(I5:I22) -> 34386136 | M23: =SUM(M5:M22) -> 30291207 | N23: =SUM(N5:N22) -> 30074562 | P23: =SUM(P5:P22) -> 37574769 | Q23: =SUM(Q5:Q22) -> 45254291 | S23: 0.05 | T23: 0.018 | U23: =SUM(U5:U22) -> 50422112
A25: Remaining stretch BEFORE GPS | C25: 952037.42
A26: GPS contribution (18 DBs) | C26: =G23 -> 1163773.7
A27: Remaining stretch AFTER GPS | C27: =C25-C26 -> -211736.32 | E27: negative = over-covered = buffer
A29: WATCH
A30: • DEALER-LEVEL BLOCK DROPPED (Jerome, 17-07-2026). The KPI 'Parts Sales DB to DLR' figure is 2.2x-3.7x ISZE billing (IUK 3.58x, Denmark 3.67x, Romania 2.19x). A 35% DB margin implies 1.54x. To reconcile you would need DB margins of 54-73%. It is not the same goods marked up, so the /0.65 gross-up was invalid — and it is the same reason the DB-to-DLR GPS exceeded 100%.
A31: • BASIS SPLIT: ITUK and UTI carry their AS-PRESENTED V4 figures. V4 (2026-07-06) maps FY27 to UIO CY2027F — the off-by-one MH corrected on 17-07 — and has no +5%. Every other row is on MH's corrected basis. OPEN: rebase, or ratify V4?
A32: • V4 IUK max spend = 50,202 (CY2027F) x EUR250 = 12,550,500. This file: 49,280 (CY2026F) x 230.543 = 11,361,161.
A33: • FINLAND (121.3%), ICELAND (105.2%) and IRELAND (104.6%) exceed 100% GPS after stretch — the target is above the theoretical max spend of their whole parc. Not quotable as a %. Discuss the amount, or agree the per-unit rate first. BELGIUM (96.7%) and NORWAY (96.2%) are close behind.
A34: • GREECE billing = payer 66, labelled 'RSA' in gps_billing_fy_ALLCUSTOMERS.csv. It is Greece, not Norway. The warranty file uses 'RSA' for Norway — joining the two on that name merges Greece's sales into Norway. Live bug at source.
A35: • BELGIUM = ISUZU BENELUX NV covering BE/NL/PL/LUX, but only the BELGIUM UIO rows are in its max spend.

Sheet Waterfall VP
P4: =SUM(V13:V30) -> 1163773.7 | Q4: =T7-C16-SUM(D5:S16)-P4 -> -211736.32 | T4: check:
O5: 210000 | P5: GPS extended target | Q5: remaining stretch / SURPLUS if negative | R5: -260000 | T5: =SUM(C3:S16) -> 35284444
O6: MOS ISA+RSA | S6: -350000
N7: =71575+307333 -> 378908 | R7: Shell oil decrease | T7: 35284444
K8: 93000 | N8: SPA | S8: negative impact on volume from price increase
M9: 55000 | U9: SURPLUS vs FY2027 Plan (GPS exceeds the gap) | V9: =-Q4 -> 211736.32
J10: 280000 | K10: local DPD | M10: Overstock campaign | N10: # Original: 1,015k | U10: Q4 stays negative — the bridge needs it to close to the Plan. This is the same number, stated positively.
H11: 46000 | I11: 11940 | J11: local brake | M11: All DB's 55K€ | N11: -> IUK 71,575
G12: 75000 | H12: Genuine Share | I12: PMS | N12: -> UTI 307333 | U12: GPS extended target — per customer
F13: 60000 | G13: L/B | H13: # Original: 46,000 | I13: # Original: 11,940 | N13: -> | U13: -> ITUK (as presented, V4 basis) | V13: 376073.91
E14: 96664.198 | F14: Cab | H14: -> ITUK 376,074 | I14: -> ITUK 8,000 | N14: -> | U14: -> UTI (as presented, V4 basis) | V14: 159024.46
D15: 691851.85 | E15: UIO up | H15: -> Ireland | I15: -> Portugal | U15: -> IUK | V15: =IUK!E23 -> 204500.9
C16: 32944043 | D16: Price up 2% | H16: -> Portugal | I16: -> Ireland | U16: -> UMI | V16: =UMI!E23 -> 78372.645
H17: -> | I17: -> IUK | U17: -> NORWAY | V17: =NORWAY!E23 -> 33658.823
H18: -> | I18: -> | U18: -> SWEDEN | V18: =SWEDEN!E23 -> 37721.452
H19: -> | I19: -> | U19: -> HUNGARY | V19: =HUNGARY!E23 -> 16565.901
U20: -> FINLAND | V20: =FINLAND!E23 -> 5427.9053
U21: -> ROMANIA | V21: =ROMANIA!E23 -> 5017.0776
U22: -> DENMARK | V22: =DENMARK!E23 -> 3917.3873
U23: -> ICELAND | V23: =ICELAND!E23 -> 1821.7511
U24: -> GERMANY | V24: =GERMANY!E29 -> 72132.388
C25: FY2026 Actual | T25: FY2027 Plan | U25: -> BELGIUM | V25: =BELGIUM!E29 -> 43556.175
U26: -> PORTUGAL | V26: =PORTUGAL!E29 -> 65029.86
U27: -> IRELAND | V27: =IRELAND!E29 -> 22185.916
U28: -> GREECE | V28: =GREECE!E29 -> 18394.628
U29: -> CYPRUS | V29: =CYPRUS!E29 -> 13222.112
U30: -> MALTA | V30: =MALTA!E29 -> 7150.455
U31: GPS total | V31: =SUM(V13:V30) -> 1163773.7

Sheet IUK
A1: IUK — GPS Extended Target FY2027 · I.M. PARTS & SERVICE Limited [LCV only]
A2: ISZE->DB level only. Blue = adjustable. Dealer-level (DB->DLR) block removed: the KPI dealer figure is 2.2-3.7x ISZE billing, which cannot be a 35% margin on the same goods.
F3: Colours
F4: Firm / actual
F5: Stretch
I6: In-house FX: EUR@181, GBP@210, EUR/GBP1.16 | J6: 1.16
A7: IUK UIO (LCV)
C8: FY25 (Apr'24-Mar'25) | D8: FY26 (Apr'25-Mar'26) | E8: FY27 (Apr'26-Mar'27)
A9: LCV | C9: 48876 | D9: 47783 | E9: 49280
A10: TTL | C10: =C9 -> 48876 | D10: =D9 -> 47783 | E10: =E9 -> 49280
A11: Source: UIO v19 '1.UIO Overview' row 25, LCV — CY2024 / CY2025E / CY2026F mapped to FY25 / FY26 / FY27 (UIO shifted one column right).
A13: Parts Sales / Unit (EUR) | C13: GBP->EUR | D13: Conv. To ISZE | E13: FY27 (+5%) | F13: FY28 (+3%)
A14: ISZE-net EUR/unit (= DB cost) · per MH | B14: 291.2 | C14: =B14*$J$6 -> 337.792 | D14: =C14*0.65 -> 219.5648 | E14: =D14*1.05 -> 230.54304 | F14: =E14*1.03 -> 237.45933
A15: MH chain: 291.2 x 1.16 = 337.79 -> x0.65 = 219.5648 ISZE-net (FY26 base). FY27 = +5% price increase. FY28-31 = +3%/yr (IML policy).
A17: ISZE -> IUK wholesale (ISZE-net EUR) << EXTENDED TARGET IS SET HERE
C18: FY25 (Apr'24-Mar'25) | D18: FY26 (Apr'25-Mar'26) | E18: FY27 (Apr'26-Mar'27)
A19: Max spend / potential (= UIO x ISZE-net rate) | C19: =C9*$D$14 -> 10731449 | D19: =D9*$D$14 -> 10491465 | E19: =E9*$E$14 -> 11361161
A20: Actual (ISZE billing) · FY27 = BP target | C20: 7314795.2 | D20: 5981960.5 | E20: 6062956.5 | F20: FY27 = BP reviewed 24-04-2026
A21: Share (GPS, ISZE level) | C21: =C20/C19 -> 0.68162232 | D21: =D20/D19 -> 0.570174 | E21: =E20/E19 -> 0.53365642
A22: Stretch idea (%) - set me | C22: 0 | D22: 0 | E22: 0.018
A23: Stretch amount (= max spend x stretch%) | C23: =C19*C22 -> 0 | D23: =D19*D22 -> 0 | E23: =E19*E22 -> 204500.9
A24: TTL amount (= actual + stretch) << EXTENDED TARGET | C24: =C20+C23 -> 7314795.2 | D24: =D20+D23 -> 5981960.5 | E24: =E20+E23 -> 6267457.4
A25: Share (new) | C25: =C24/C19 -> 0.68162232 | D25: =D24/D19 -> 0.570174 | E25: =E24/E19 -> 0.55165642
A26: Source: 00_derived/gps_billing_fy_ALLCUSTOMERS.csv canonical 'IUK' (net_gps, GPS-audited, FY-aligned, lubricants included).
A28: IUK -> DEALER level (DB->DLR) — MH method (35% DB margin gross-up)
C29: FY25 (Apr'24-Mar'25) | D29: FY26 (Apr'25-Mar'26) | E29: FY27 (Apr'26-Mar'27)
A30: Parts Sales DB-to-DLR (actual) · KPI Master File june 2026.xlsx | C30: 18843293 | D30: 21418279 | F30: FY25 12/12 mo · FY26 12/12 mo
A31: DB margin % (MH assumption — same as testcase B15) | B31: 0.35
A32: Stretch amount at dealer (= ISZE stretch / (1 − margin)) · MH E29 | E32: =-E23/(B31-1) -> 314616.77
A33: FY27 AMOUNT TO REACH at dealer (= FY26 actual + dealer stretch) | E33: =IF(OR(D30="",D30="no KPI data"),"no KPI data",D30+E32) -> 21732896
A34: MH method (same factors as ISZE_IUK_Sales_Share_Stretch_TESTCASE): DB margin 35% → dealer stretch = ISZE stretch / (1−0.35) = ISZE stretch / 0.65 (identical to MH E29 = −E41/(0.35−1)). FY27 amount to reach = FY26 dealer actual + dealer stretch. Observed dealer/ISZE often ≠ 1.54x — not used for the conversion.
A37: GAPS / open items
A38: 1. LCV rate: MH's 291.2 chain ends at 219.5648. The identical GBP400 under the v9 CV convention ends at 296. Same source, two conventions — carried as instructed.

Sheet UMI
A1: UMI — GPS Extended Target FY2027 · UNIVERSAL MOTORS ISRAEL LTD [LCV only]
A2: ISZE->DB level only. Blue = adjustable. Dealer-level (DB->DLR) block removed: the KPI dealer figure is 2.2-3.7x ISZE billing, which cannot be a 35% margin on the same goods.
F3: Colours
F4: Firm / actual
F5: Stretch
I6: In-house FX: EUR@181, GBP@210, EUR/GBP1.16 | J6: 1.16
A7: UMI UIO (LCV)
C8: FY25 (Apr'24-Mar'25) | D8: FY26 (Apr'25-Mar'26) | E8: FY27 (Apr'26-Mar'27)
A9: LCV | C9: 18349 | D9: 18542 | E9: 18886
A10: TTL | C10: =C9 -> 18349 | D10: =D9 -> 18542 | E10: =E9 -> 18886
A11: Source: UIO v19 '1.UIO Overview' row 9, LCV — CY2024 / CY2025E / CY2026F mapped to FY25 / FY26 / FY27 (UIO shifted one column right).
A13: Parts Sales / Unit (EUR) | C13: GBP->EUR | D13: Conv. To ISZE | E13: FY27 (+5%) | F13: FY28 (+3%)
A14: ISZE-net EUR/unit (= DB cost) · per MH | B14: 291.2 | C14: =B14*$J$6 -> 337.792 | D14: =C14*0.65 -> 219.5648 | E14: =D14*1.05 -> 230.54304 | F14: =E14*1.03 -> 237.45933
A15: MH chain: 291.2 x 1.16 = 337.79 -> x0.65 = 219.5648 ISZE-net (FY26 base). FY27 = +5% price increase. FY28-31 = +3%/yr (IML policy).
A17: ISZE -> UMI wholesale (ISZE-net EUR) << EXTENDED TARGET IS SET HERE
C18: FY25 (Apr'24-Mar'25) | D18: FY26 (Apr'25-Mar'26) | E18: FY27 (Apr'26-Mar'27)
A19: Max spend / potential (= UIO x ISZE-net rate) | C19: =C9*$D$14 -> 4028794.5 | D19: =D9*$D$14 -> 4071170.5 | E19: =E9*$E$14 -> 4354035.9
A20: Actual (ISZE billing) · FY27 = BP target | C20: 2739215.7 | D20: 2445335.2 | E20: 2973279.3 | F20: FY27 = BP reviewed 24-04-2026
A21: Share (GPS, ISZE level) | C21: =C20/C19 -> 0.67990951 | D21: =D20/D19 -> 0.60064673 | E21: =E20/E19 -> 0.68287893
A22: Stretch idea (%) - set me | C22: 0 | D22: 0 | E22: 0.018
A23: Stretch amount (= max spend x stretch%) | C23: =C19*C22 -> 0 | D23: =D19*D22 -> 0 | E23: =E19*E22 -> 78372.645
A24: TTL amount (= actual + stretch) << EXTENDED TARGET | C24: =C20+C23 -> 2739215.7 | D24: =D20+D23 -> 2445335.2 | E24: =E20+E23 -> 3051652
A25: Share (new) | C25: =C24/C19 -> 0.67990951 | D25: =D24/D19 -> 0.60064673 | E25: =E24/E19 -> 0.70087893
A26: Source: 00_derived/gps_billing_fy_ALLCUSTOMERS.csv canonical 'UMI' (net_gps, GPS-audited, FY-aligned, lubricants included).
A28: UMI -> DEALER level (DB->DLR) — MH method (35% DB margin gross-up)
C29: FY25 (Apr'24-Mar'25) | D29: FY26 (Apr'25-Mar'26) | E29: FY27 (Apr'26-Mar'27)
A30: Parts Sales DB-to-DLR (actual) · KPI Master File june 2026.xlsx | F30: FY25 0/12 mo · FY26 0/12 mo
A31: DB margin % (MH assumption — same as testcase B15) | B31: 0.35
A32: Stretch amount at dealer (= ISZE stretch / (1 − margin)) · MH E29 | E32: =-E23/(B31-1) -> 120573.3
A33: FY27 AMOUNT TO REACH at dealer (= FY26 actual + dealer stretch) | E33: =IF(OR(D30="",D30="no KPI data"),"no KPI data",D30+E32) -> no KPI data
A34: MH method (same factors as ISZE_IUK_Sales_Share_Stretch_TESTCASE): DB margin 35% → dealer stretch = ISZE stretch / (1−0.35) = ISZE stretch / 0.65 (identical to MH E29 = −E41/(0.35−1)). FY27 amount to reach = FY26 dealer actual + dealer stretch. Observed dealer/ISZE often ≠ 1.54x — not used for the conversion.
A37: GAPS / open items
A38: 1. LCV rate: MH's 291.2 chain ends at 219.5648. The identical GBP400 under the v9 CV convention ends at 296. Same source, two conventions — carried as instructed.
A39: 2. Dealer-level data is 'Internal only' in the KPI Master — irrelevant now that the DB-to-DLR block is dropped.

Sheet NORWAY
A1: NORWAY — GPS Extended Target FY2027 · RUTEBILEIERNES STANDARDISERING AS [LCV only]
A2: ISZE->DB level only. Blue = adjustable. Dealer-level (DB->DLR) block removed: the KPI dealer figure is 2.2-3.7x ISZE billing, which cannot be a 35% margin on the same goods.
F3: Colours
F4: Firm / actual
F5: Stretch
I6: In-house FX: EUR@181, GBP@210, EUR/GBP1.16 | J6: 1.16
A7: NORWAY UIO (LCV)
C8: FY25 (Apr'24-Mar'25) | D8: FY26 (Apr'25-Mar'26) | E8: FY27 (Apr'26-Mar'27)
A9: LCV | C9: 8237 | D9: 7929 | E9: 8111
A10: TTL | C10: =C9 -> 8237 | D10: =D9 -> 7929 | E10: =E9 -> 8111
A11: Source: UIO v19 '1.UIO Overview' row 15, LCV — CY2024 / CY2025E / CY2026F mapped to FY25 / FY26 / FY27 (UIO shifted one column right).
A13: Parts Sales / Unit (EUR) | C13: GBP->EUR | D13: Conv. To ISZE | E13: FY27 (+5%) | F13: FY28 (+3%)
A14: ISZE-net EUR/unit (= DB cost) · per MH | B14: 291.2 | C14: =B14*$J$6 -> 337.792 | D14: =C14*0.65 -> 219.5648 | E14: =D14*1.05 -> 230.54304 | F14: =E14*1.03 -> 237.45933
A15: MH chain: 291.2 x 1.16 = 337.79 -> x0.65 = 219.5648 ISZE-net (FY26 base). FY27 = +5% price increase. FY28-31 = +3%/yr (IML policy).
A17: ISZE -> NORWAY wholesale (ISZE-net EUR) << EXTENDED TARGET IS SET HERE
C18: FY25 (Apr'24-Mar'25) | D18: FY26 (Apr'25-Mar'26) | E18: FY27 (Apr'26-Mar'27)
A19: Max spend / potential (= UIO x ISZE-net rate) | C19: =C9*$D$14 -> 1808555.3 | D19: =D9*$D$14 -> 1740929.3 | E19: =E9*$E$14 -> 1869934.6
A20: Actual (ISZE billing) · FY27 = BP target | C20: 1162750.7 | D20: 1471434.2 | E20: 1764799.8 | F20: FY27 = BP reviewed 24-04-2026
A21: Share (GPS, ISZE level) | C21: =C20/C19 -> 0.64291686 | D21: =D20/D19 -> 0.84520044 | E21: =E20/E19 -> 0.94377619
A22: Stretch idea (%) - set me | C22: 0 | D22: 0 | E22: 0.018
A23: Stretch amount (= max spend x stretch%) | C23: =C19*C22 -> 0 | D23: =D19*D22 -> 0 | E23: =E19*E22 -> 33658.823
A24: TTL amount (= actual + stretch) << EXTENDED TARGET | C24: =C20+C23 -> 1162750.7 | D24: =D20+D23 -> 1471434.2 | E24: =E20+E23 -> 1798458.6
A25: Share (new) | C25: =C24/C19 -> 0.64291686 | D25: =D24/D19 -> 0.84520044 | E25: =E24/E19 -> 0.96177619
A26: Source: 00_derived/gps_billing_fy_ALLCUSTOMERS.csv canonical 'Norway' (net_gps, GPS-audited, FY-aligned, lubricants included).
A28: NORWAY -> DEALER level (DB->DLR) — MH method (35% DB margin gross-up)
C29: FY25 (Apr'24-Mar'25) | D29: FY26 (Apr'25-Mar'26) | E29: FY27 (Apr'26-Mar'27)
A30: Parts Sales DB-to-DLR (actual) · KPI Master File june 2026.xlsx | C30: 3367988 | D30: 4811395 | F30: FY25 12/12 mo · FY26 11/12 mo
A31: DB margin % (MH assumption — same as testcase B15) | B31: 0.35
A32: Stretch amount at dealer (= ISZE stretch / (1 − margin)) · MH E29 | E32: =-E23/(B31-1) -> 51782.804
A33: FY27 AMOUNT TO REACH at dealer (= FY26 actual + dealer stretch) | E33: =IF(OR(D30="",D30="no KPI data"),"no KPI data",D30+E32) -> 4863177.8
A34: MH method (same factors as ISZE_IUK_Sales_Share_Stretch_TESTCASE): DB margin 35% → dealer stretch = ISZE stretch / (1−0.35) = ISZE stretch / 0.65 (identical to MH E29 = −E41/(0.35−1)). FY27 amount to reach = FY26 dealer actual + dealer stretch. Observed dealer/ISZE often ≠ 1.54x — not used for the conversion.
A37: GAPS / open items
A38: 1. LCV rate: MH's 291.2 chain ends at 219.5648. The identical GBP400 under the v9 CV convention ends at 296. Same source, two conventions — carried as instructed.
A39: 2. Billing = payer 86 only. Payer 66 (labelled 'RSA' in the billing file) is GREECE, not Norway — confirmed by Jerome 17-07-2026. Do not join billing to warranty on the name 'RSA'.

Sheet SWEDEN
A1: SWEDEN — GPS Extended Target FY2027 · ISUZU SVERIGE AB [LCV only]
A2: ISZE->DB level only. Blue = adjustable. Dealer-level (DB->DLR) block removed: the KPI dealer figure is 2.2-3.7x ISZE billing, which cannot be a 35% margin on the same goods.
F3: Colours
F4: Firm / actual
F5: Stretch
I6: In-house FX: EUR@181, GBP@210, EUR/GBP1.16 | J6: 1.16
A7: SWEDEN UIO (LCV)
C8: FY25 (Apr'24-Mar'25) | D8: FY26 (Apr'25-Mar'26) | E8: FY27 (Apr'26-Mar'27)
A9: LCV | C9: 7221 | D9: 8443 | E9: 9090
A10: TTL | C10: =C9 -> 7221 | D10: =D9 -> 8443 | E10: =E9 -> 9090
A11: Source: UIO v19 '1.UIO Overview' row 18, LCV — CY2024 / CY2025E / CY2026F mapped to FY25 / FY26 / FY27 (UIO shifted one column right).
A13: Parts Sales / Unit (EUR) | C13: GBP->EUR | D13: Conv. To ISZE | E13: FY27 (+5%) | F13: FY28 (+3%)
A14: ISZE-net EUR/unit (= DB cost) · per MH | B14: 291.2 | C14: =B14*$J$6 -> 337.792 | D14: =C14*0.65 -> 219.5648 | E14: =D14*1.05 -> 230.54304 | F14: =E14*1.03 -> 237.45933
A15: MH chain: 291.2 x 1.16 = 337.79 -> x0.65 = 219.5648 ISZE-net (FY26 base). FY27 = +5% price increase. FY28-31 = +3%/yr (IML policy).
A17: ISZE -> SWEDEN wholesale (ISZE-net EUR) << EXTENDED TARGET IS SET HERE
C18: FY25 (Apr'24-Mar'25) | D18: FY26 (Apr'25-Mar'26) | E18: FY27 (Apr'26-Mar'27)
A19: Max spend / potential (= UIO x ISZE-net rate) | C19: =C9*$D$14 -> 1585477.4 | D19: =D9*$D$14 -> 1853785.6 | E19: =E9*$E$14 -> 2095636.2
A20: Actual (ISZE billing) · FY27 = BP target | C20: 1216815.8 | D20: 1299460.6 | E20: 1464302.3 | F20: FY27 = BP reviewed 24-04-2026
A21: Share (GPS, ISZE level) | C21: =C20/C19 -> 0.76747596 | D21: =D20/D19 -> 0.70097675 | E21: =E20/E19 -> 0.69873879
A22: Stretch idea (%) - set me | C22: 0 | D22: 0 | E22: 0.018
A23: Stretch amount (= max spend x stretch%) | C23: =C19*C22 -> 0 | D23: =D19*D22 -> 0 | E23: =E19*E22 -> 37721.452
A24: TTL amount (= actual + stretch) << EXTENDED TARGET | C24: =C20+C23 -> 1216815.8 | D24: =D20+D23 -> 1299460.6 | E24: =E20+E23 -> 1502023.8
A25: Share (new) | C25: =C24/C19 -> 0.76747596 | D25: =D24/D19 -> 0.70097675 | E25: =E24/E19 -> 0.71673879
A26: Source: 00_derived/gps_billing_fy_ALLCUSTOMERS.csv canonical 'Sverige' (net_gps, GPS-audited, FY-aligned, lubricants included).
A28: SWEDEN -> DEALER level (DB->DLR) — MH method (35% DB margin gross-up)
C29: FY25 (Apr'24-Mar'25) | D29: FY26 (Apr'25-Mar'26) | E29: FY27 (Apr'26-Mar'27)
A30: Parts Sales DB-to-DLR (actual) · KPI Master File june 2026.xlsx | C30: 2482560 | D30: 3154221.5 | F30: FY25 12/12 mo · FY26 12/12 mo
A31: DB margin % (MH assumption — same as testcase B15) | B31: 0.35
A32: Stretch amount at dealer (= ISZE stretch / (1 − margin)) · MH E29 | E32: =-E23/(B31-1) -> 58033.003
A33: FY27 AMOUNT TO REACH at dealer (= FY26 actual + dealer stretch) | E33: =IF(OR(D30="",D30="no KPI data"),"no KPI data",D30+E32) -> 3212254.5
A34: MH method (same factors as ISZE_IUK_Sales_Share_Stretch_TESTCASE): DB margin 35% → dealer stretch = ISZE stretch / (1−0.35) = ISZE stretch / 0.65 (identical to MH E29 = −E41/(0.35−1)). FY27 amount to reach = FY26 dealer actual + dealer stretch. Observed dealer/ISZE often ≠ 1.54x — not used for the conversion.
A37: GAPS / open items
A38: 1. LCV rate: MH's 291.2 chain ends at 219.5648. The identical GBP400 under the v9 CV convention ends at 296. Same source, two conventions — carried as instructed.

Sheet HUNGARY
A1: HUNGARY — GPS Extended Target FY2027 · AW Distribution Kft. [LCV only]
A2: ISZE->DB level only. Blue = adjustable. Dealer-level (DB->DLR) block removed: the KPI dealer figure is 2.2-3.7x ISZE billing, which cannot be a 35% margin on the same goods.
F3: Colours
F4: Firm / actual
F5: Stretch
I6: In-house FX: EUR@181, GBP@210, EUR/GBP1.16 | J6: 1.16
A7: HUNGARY UIO (LCV)
C8: FY25 (Apr'24-Mar'25) | D8: FY26 (Apr'25-Mar'26) | E8: FY27 (Apr'26-Mar'27)
A9: LCV | C9: 3714 | D9: 3734 | E9: 3992
A10: TTL | C10: =C9 -> 3714 | D10: =D9 -> 3734 | E10: =E9 -> 3992
A11: Source: UIO v19 '1.UIO Overview' row 75, LCV — CY2024 / CY2025E / CY2026F mapped to FY25 / FY26 / FY27 (UIO shifted one column right).
A13: Parts Sales / Unit (EUR) | C13: GBP->EUR | D13: Conv. To ISZE | E13: FY27 (+5%) | F13: FY28 (+3%)
A14: ISZE-net EUR/unit (= DB cost) · per MH | B14: 291.2 | C14: =B14*$J$6 -> 337.792 | D14: =C14*0.65 -> 219.5648 | E14: =D14*1.05 -> 230.54304 | F14: =E14*1.03 -> 237.45933
A15: MH chain: 291.2 x 1.16 = 337.79 -> x0.65 = 219.5648 ISZE-net (FY26 base). FY27 = +5% price increase. FY28-31 = +3%/yr (IML policy).
A17: ISZE -> HUNGARY wholesale (ISZE-net EUR) << EXTENDED TARGET IS SET HERE
C18: FY25 (Apr'24-Mar'25) | D18: FY26 (Apr'25-Mar'26) | E18: FY27 (Apr'26-Mar'27)
A19: Max spend / potential (= UIO x ISZE-net rate) | C19: =C9*$D$14 -> 815463.67 | D19: =D9*$D$14 -> 819854.96 | E19: =E9*$E$14 -> 920327.82
A20: Actual (ISZE billing) · FY27 = BP target | C20: 365817.37 | D20: 346246.24 | E20: 349600 | F20: FY27 = BP reviewed 24-04-2026
A21: Share (GPS, ISZE level) | C21: =C20/C19 -> 0.44860045 | D21: =D20/D19 -> 0.42232621 | E21: =E20/E19 -> 0.37986465
A22: Stretch idea (%) - set me | C22: 0 | D22: 0 | E22: 0.018
A23: Stretch amount (= max spend x stretch%) | C23: =C19*C22 -> 0 | D23: =D19*D22 -> 0 | E23: =E19*E22 -> 16565.901
A24: TTL amount (= actual + stretch) << EXTENDED TARGET | C24: =C20+C23 -> 365817.37 | D24: =D20+D23 -> 346246.24 | E24: =E20+E23 -> 366165.9
A25: Share (new) | C25: =C24/C19 -> 0.44860045 | D25: =D24/D19 -> 0.42232621 | E25: =E24/E19 -> 0.39786465
A26: Source: 00_derived/gps_billing_fy_ALLCUSTOMERS.csv canonical 'AutoWallis' (net_gps, GPS-audited, FY-aligned, lubricants included).
A28: HUNGARY -> DEALER level (DB->DLR) — MH method (35% DB margin gross-up)
C29: FY25 (Apr'24-Mar'25) | D29: FY26 (Apr'25-Mar'26) | E29: FY27 (Apr'26-Mar'27)
A30: Parts Sales DB-to-DLR (actual) · KPI Master File june 2026.xlsx | C30: 934209 | D30: 871455 | F30: FY25 12/12 mo · FY26 12/12 mo
A31: DB margin % (MH assumption — same as testcase B15) | B31: 0.35
A32: Stretch amount at dealer (= ISZE stretch / (1 − margin)) · MH E29 | E32: =-E23/(B31-1) -> 25486.001
A33: FY27 AMOUNT TO REACH at dealer (= FY26 actual + dealer stretch) | E33: =IF(OR(D30="",D30="no KPI data"),"no KPI data",D30+E32) -> 896941
A34: MH method (same factors as ISZE_IUK_Sales_Share_Stretch_TESTCASE): DB margin 35% → dealer stretch = ISZE stretch / (1−0.35) = ISZE stretch / 0.65 (identical to MH E29 = −E41/(0.35−1)). FY27 amount to reach = FY26 dealer actual + dealer stretch. Observed dealer/ISZE often ≠ 1.54x — not used for the conversion.
A37: GAPS / open items
A38: 1. LCV rate: MH's 291.2 chain ends at 219.5648. The identical GBP400 under the v9 CV convention ends at 296. Same source, two conventions — carried as instructed.

Sheet FINLAND
A1: FINLAND — GPS Extended Target FY2027 · Nordic Automotive trading oy. [LCV only]
A2: ISZE->DB level only. Blue = adjustable. Dealer-level (DB->DLR) block removed: the KPI dealer figure is 2.2-3.7x ISZE billing, which cannot be a 35% margin on the same goods.
F3: Colours
F4: Firm / actual
F5: Stretch
I6: In-house FX: EUR@181, GBP@210, EUR/GBP1.16 | J6: 1.16
A7: FINLAND UIO (LCV)
C8: FY25 (Apr'24-Mar'25) | D8: FY26 (Apr'25-Mar'26) | E8: FY27 (Apr'26-Mar'27)
A9: LCV | C9: 1259 | D9: 1204 | E9: 1308
A10: TTL | C10: =C9 -> 1259 | D10: =D9 -> 1204 | E10: =E9 -> 1308
A11: Source: UIO v19 '1.UIO Overview' row 66, LCV — CY2024 / CY2025E / CY2026F mapped to FY25 / FY26 / FY27 (UIO shifted one column right).
A13: Parts Sales / Unit (EUR) | C13: GBP->EUR | D13: Conv. To ISZE | E13: FY27 (+5%) | F13: FY28 (+3%)
A14: ISZE-net EUR/unit (= DB cost) · per MH | B14: 291.2 | C14: =B14*$J$6 -> 337.792 | D14: =C14*0.65 -> 219.5648 | E14: =D14*1.05 -> 230.54304 | F14: =E14*1.03 -> 237.45933
A15: MH chain: 291.2 x 1.16 = 337.79 -> x0.65 = 219.5648 ISZE-net (FY26 base). FY27 = +5% price increase. FY28-31 = +3%/yr (IML policy).
A17: ISZE -> FINLAND wholesale (ISZE-net EUR) << EXTENDED TARGET IS SET HERE
C18: FY25 (Apr'24-Mar'25) | D18: FY26 (Apr'25-Mar'26) | E18: FY27 (Apr'26-Mar'27)
A19: Max spend / potential (= UIO x ISZE-net rate) | C19: =C9*$D$14 -> 276432.08 | D19: =D9*$D$14 -> 264356.02 | E19: =E9*$E$14 -> 301550.3
A20: Actual (ISZE billing) · FY27 = BP target | C20: 266204.48 | D20: 279383.25 | E20: 360300 | F20: FY27 = BP reviewed 24-04-2026
A21: Share (GPS, ISZE level) | C21: =C20/C19 -> 0.96300141 | D21: =D20/D19 -> 1.0568447 | E21: =E20/E19 -> 1.1948256
A22: Stretch idea (%) - set me | C22: 0 | D22: 0 | E22: 0.018
A23: Stretch amount (= max spend x stretch%) | C23: =C19*C22 -> 0 | D23: =D19*D22 -> 0 | E23: =E19*E22 -> 5427.9053
A24: TTL amount (= actual + stretch) << EXTENDED TARGET | C24: =C20+C23 -> 266204.48 | D24: =D20+D23 -> 279383.25 | E24: =E20+E23 -> 365727.91
A25: Share (new) | C25: =C24/C19 -> 0.96300141 | D25: =D24/D19 -> 1.0568447 | E25: =E24/E19 -> 1.2128256
A26: Source: 00_derived/gps_billing_fy_ALLCUSTOMERS.csv canonical 'Nordic FI' (net_gps, GPS-audited, FY-aligned, lubricants included).
A28: FINLAND -> DEALER level (DB->DLR) — MH method (35% DB margin gross-up)
C29: FY25 (Apr'24-Mar'25) | D29: FY26 (Apr'25-Mar'26) | E29: FY27 (Apr'26-Mar'27)
A30: Parts Sales DB-to-DLR (actual) · KPI Master File june 2026.xlsx | C30: 576758 | D30: 350854 | F30: FY25 12/12 mo · FY26 6/12 mo
A31: DB margin % (MH assumption — same as testcase B15) | B31: 0.35
A32: Stretch amount at dealer (= ISZE stretch / (1 − margin)) · MH E29 | E32: =-E23/(B31-1) -> 8350.6236
A33: FY27 AMOUNT TO REACH at dealer (= FY26 actual + dealer stretch) | E33: =IF(OR(D30="",D30="no KPI data"),"no KPI data",D30+E32) -> 359204.62
A34: MH method (same factors as ISZE_IUK_Sales_Share_Stretch_TESTCASE): DB margin 35% → dealer stretch = ISZE stretch / (1−0.35) = ISZE stretch / 0.65 (identical to MH E29 = −E41/(0.35−1)). FY27 amount to reach = FY26 dealer actual + dealer stretch. Observed dealer/ISZE often ≠ 1.54x — not used for the conversion.
A37: GAPS / open items
A38: 1. LCV rate: MH's 291.2 chain ends at 219.5648. The identical GBP400 under the v9 CV convention ends at 296. Same source, two conventions — carried as instructed.
A39: 2. TARGET EXCEEDS 100% OF THE PARC'S MAX SPEND. Do not quote a GPS % to this DB — discuss the amount, or agree the per-unit rate first.

Sheet ROMANIA
A1: ROMANIA — GPS Extended Target FY2027 · Isuzu Rom Auto [LCV only]
A2: ISZE->DB level only. Blue = adjustable. Dealer-level (DB->DLR) block removed: the KPI dealer figure is 2.2-3.7x ISZE billing, which cannot be a 35% margin on the same goods.
F3: Colours
F4: Firm / actual
F5: Stretch
I6: In-house FX: EUR@181, GBP@210, EUR/GBP1.16 | J6: 1.16
A7: ROMANIA UIO (LCV)
C8: FY25 (Apr'24-Mar'25) | D8: FY26 (Apr'25-Mar'26) | E8: FY27 (Apr'26-Mar'27)
A9: LCV | C9: 986 | D9: 1071 | E9: 1209
A10: TTL | C10: =C9 -> 986 | D10: =D9 -> 1071 | E10: =E9 -> 1209
A11: Source: UIO v19 '1.UIO Overview' row 84, LCV — CY2024 / CY2025E / CY2026F mapped to FY25 / FY26 / FY27 (UIO shifted one column right).
A13: Parts Sales / Unit (EUR) | C13: GBP->EUR | D13: Conv. To ISZE | E13: FY27 (+5%) | F13: FY28 (+3%)
A14: ISZE-net EUR/unit (= DB cost) · per MH | B14: 291.2 | C14: =B14*$J$6 -> 337.792 | D14: =C14*0.65 -> 219.5648 | E14: =D14*1.05 -> 230.54304 | F14: =E14*1.03 -> 237.45933
A15: MH chain: 291.2 x 1.16 = 337.79 -> x0.65 = 219.5648 ISZE-net (FY26 base). FY27 = +5% price increase. FY28-31 = +3%/yr (IML policy).
A17: ISZE -> ROMANIA wholesale (ISZE-net EUR) << EXTENDED TARGET IS SET HERE
C18: FY25 (Apr'24-Mar'25) | D18: FY26 (Apr'25-Mar'26) | E18: FY27 (Apr'26-Mar'27)
A19: Max spend / potential (= UIO x ISZE-net rate) | C19: =C9*$D$14 -> 216490.89 | D19: =D9*$D$14 -> 235153.9 | E19: =E9*$E$14 -> 278726.54
A20: Actual (ISZE billing) · FY27 = BP target | C20: 151600.22 | D20: 180409.83 | E20: 199587.57 | F20: FY27 = BP reviewed 24-04-2026
A21: Share (GPS, ISZE level) | C21: =C20/C19 -> 0.70026143 | D21: =D20/D19 -> 0.76719895 | E21: =E20/E19 -> 0.7160695
A22: Stretch idea (%) - set me | C22: 0 | D22: 0 | E22: 0.018
A23: Stretch amount (= max spend x stretch%) | C23: =C19*C22 -> 0 | D23: =D19*D22 -> 0 | E23: =E19*E22 -> 5017.0776
A24: TTL amount (= actual + stretch) << EXTENDED TARGET | C24: =C20+C23 -> 151600.22 | D24: =D20+D23 -> 180409.83 | E24: =E20+E23 -> 204604.65
A25: Share (new) | C25: =C24/C19 -> 0.70026143 | D25: =D24/D19 -> 0.76719895 | E25: =E24/E19 -> 0.7340695
A26: Source: 00_derived/gps_billing_fy_ALLCUSTOMERS.csv canonical 'ROM Auto' (net_gps, GPS-audited, FY-aligned, lubricants included).
A28: ROMANIA -> DEALER level (DB->DLR) — MH method (35% DB margin gross-up)
C29: FY25 (Apr'24-Mar'25) | D29: FY26 (Apr'25-Mar'26) | E29: FY27 (Apr'26-Mar'27)
A30: Parts Sales DB-to-DLR (actual) · KPI Master File june 2026.xlsx | C30: 382258 | D30: 394596.63 | F30: FY25 12/12 mo · FY26 12/12 mo
A31: DB margin % (MH assumption — same as testcase B15) | B31: 0.35
A32: Stretch amount at dealer (= ISZE stretch / (1 − margin)) · MH E29 | E32: =-E23/(B31-1) -> 7718.581
A33: FY27 AMOUNT TO REACH at dealer (= FY26 actual + dealer stretch) | E33: =IF(OR(D30="",D30="no KPI data"),"no KPI data",D30+E32) -> 402315.21
A34: MH method (same factors as ISZE_IUK_Sales_Share_Stretch_TESTCASE): DB margin 35% → dealer stretch = ISZE stretch / (1−0.35) = ISZE stretch / 0.65 (identical to MH E29 = −E41/(0.35−1)). FY27 amount to reach = FY26 dealer actual + dealer stretch. Observed dealer/ISZE often ≠ 1.54x — not used for the conversion.
A37: GAPS / open items
A38: 1. LCV rate: MH's 291.2 chain ends at 219.5648. The identical GBP400 under the v9 CV convention ends at 296. Same source, two conventions — carried as instructed.
A39: 2. Absent from distributor_master_mapping.csv — mapping gap. LCV-only per v9 and the UIO row.

Sheet DENMARK
A1: DENMARK — GPS Extended Target FY2027 · ISUZU DANMARK A/S [LCV only]
A2: ISZE->DB level only. Blue = adjustable. Dealer-level (DB->DLR) block removed: the KPI dealer figure is 2.2-3.7x ISZE billing, which cannot be a 35% margin on the same goods.
F3: Colours
F4: Firm / actual
F5: Stretch
I6: In-house FX: EUR@181, GBP@210, EUR/GBP1.16 | J6: 1.16
A7: DENMARK UIO (LCV)
C8: FY25 (Apr'24-Mar'25) | D8: FY26 (Apr'25-Mar'26) | E8: FY27 (Apr'26-Mar'27)
A9: LCV | C9: 829 | D9: 850 | E9: 944
A10: TTL | C10: =C9 -> 829 | D10: =D9 -> 850 | E10: =E9 -> 944
A11: Source: UIO v19 '1.UIO Overview' row 21, LCV — CY2024 / CY2025E / CY2026F mapped to FY25 / FY26 / FY27 (UIO shifted one column right).
A13: Parts Sales / Unit (EUR) | C13: GBP->EUR | D13: Conv. To ISZE | E13: FY27 (+5%) | F13: FY28 (+3%)
A14: ISZE-net EUR/unit (= DB cost) · per MH | B14: 291.2 | C14: =B14*$J$6 -> 337.792 | D14: =C14*0.65 -> 219.5648 | E14: =D14*1.05 -> 230.54304 | F14: =E14*1.03 -> 237.45933
A15: MH chain: 291.2 x 1.16 = 337.79 -> x0.65 = 219.5648 ISZE-net (FY26 base). FY27 = +5% price increase. FY28-31 = +3%/yr (IML policy).
A17: ISZE -> DENMARK wholesale (ISZE-net EUR) << EXTENDED TARGET IS SET HERE
C18: FY25 (Apr'24-Mar'25) | D18: FY26 (Apr'25-Mar'26) | E18: FY27 (Apr'26-Mar'27)
A19: Max spend / potential (= UIO x ISZE-net rate) | C19: =C9*$D$14 -> 182019.22 | D19: =D9*$D$14 -> 186630.08 | E19: =E9*$E$14 -> 217632.63
A20: Actual (ISZE billing) · FY27 = BP target | C20: 122628.72 | D20: 155916.46 | E20: 187600 | F20: FY27 = BP reviewed 24-04-2026
A21: Share (GPS, ISZE level) | C21: =C20/C19 -> 0.67371302 | D21: =D20/D19 -> 0.83543049 | E21: =E20/E19 -> 0.86200309
A22: Stretch idea (%) - set me | C22: 0 | D22: 0 | E22: 0.018
A23: Stretch amount (= max spend x stretch%) | C23: =C19*C22 -> 0 | D23: =D19*D22 -> 0 | E23: =E19*E22 -> 3917.3873
A24: TTL amount (= actual + stretch) << EXTENDED TARGET | C24: =C20+C23 -> 122628.72 | D24: =D20+D23 -> 155916.46 | E24: =E20+E23 -> 191517.39
A25: Share (new) | C25: =C24/C19 -> 0.67371302 | D25: =D24/D19 -> 0.83543049 | E25: =E24/E19 -> 0.88000309
A26: Source: 00_derived/gps_billing_fy_ALLCUSTOMERS.csv canonical 'Danmark' (net_gps, GPS-audited, FY-aligned, lubricants included).
A28: DENMARK -> DEALER level (DB->DLR) — MH method (35% DB margin gross-up)
C29: FY25 (Apr'24-Mar'25) | D29: FY26 (Apr'25-Mar'26) | E29: FY27 (Apr'26-Mar'27)
A30: Parts Sales DB-to-DLR (actual) · KPI Master File june 2026.xlsx | C30: 356680.16 | D30: 572863.67 | F30: FY25 12/12 mo · FY26 12/12 mo
A31: DB margin % (MH assumption — same as testcase B15) | B31: 0.35
A32: Stretch amount at dealer (= ISZE stretch / (1 − margin)) · MH E29 | E32: =-E23/(B31-1) -> 6026.7497
A33: FY27 AMOUNT TO REACH at dealer (= FY26 actual + dealer stretch) | E33: =IF(OR(D30="",D30="no KPI data"),"no KPI data",D30+E32) -> 578890.42
A34: MH method (same factors as ISZE_IUK_Sales_Share_Stretch_TESTCASE): DB margin 35% → dealer stretch = ISZE stretch / (1−0.35) = ISZE stretch / 0.65 (identical to MH E29 = −E41/(0.35−1)). FY27 amount to reach = FY26 dealer actual + dealer stretch. Observed dealer/ISZE often ≠ 1.54x — not used for the conversion.
A37: GAPS / open items
A38: 1. LCV rate: MH's 291.2 chain ends at 219.5648. The identical GBP400 under the v9 CV convention ends at 296. Same source, two conventions — carried as instructed.

Sheet ICELAND
A1: ICELAND — GPS Extended Target FY2027 · BL. EHF. [LCV only]
A2: ISZE->DB level only. Blue = adjustable. Dealer-level (DB->DLR) block removed: the KPI dealer figure is 2.2-3.7x ISZE billing, which cannot be a 35% margin on the same goods.
F3: Colours
F4: Firm / actual
F5: Stretch
I6: In-house FX: EUR@181, GBP@210, EUR/GBP1.16 | J6: 1.16
A7: ICELAND UIO (LCV)
C8: FY25 (Apr'24-Mar'25) | D8: FY26 (Apr'25-Mar'26) | E8: FY27 (Apr'26-Mar'27)
A9: LCV | C9: 342 | D9: 406 | E9: 439
A10: TTL | C10: =C9 -> 342 | D10: =D9 -> 406 | E10: =E9 -> 439
A11: Source: UIO v19 '1.UIO Overview' row 12, LCV — CY2024 / CY2025E / CY2026F mapped to FY25 / FY26 / FY27 (UIO shifted one column right).
A13: Parts Sales / Unit (EUR) | C13: GBP->EUR | D13: Conv. To ISZE | E13: FY27 (+5%) | F13: FY28 (+3%)
A14: ISZE-net EUR/unit (= DB cost) · per MH | B14: 291.2 | C14: =B14*$J$6 -> 337.792 | D14: =C14*0.65 -> 219.5648 | E14: =D14*1.05 -> 230.54304 | F14: =E14*1.03 -> 237.45933
A15: MH chain: 291.2 x 1.16 = 337.79 -> x0.65 = 219.5648 ISZE-net (FY26 base). FY27 = +5% price increase. FY28-31 = +3%/yr (IML policy).
A17: ISZE -> ICELAND wholesale (ISZE-net EUR) << EXTENDED TARGET IS SET HERE
C18: FY25 (Apr'24-Mar'25) | D18: FY26 (Apr'25-Mar'26) | E18: FY27 (Apr'26-Mar'27)
A19: Max spend / potential (= UIO x ISZE-net rate) | C19: =C9*$D$14 -> 75091.162 | D19: =D9*$D$14 -> 89143.309 | E19: =E9*$E$14 -> 101208.39
A20: Actual (ISZE billing) · FY27 = BP target | C20: 73673.522 | D20: 86604.505 | E20: 104600 | F20: FY27 = BP reviewed 24-04-2026
A21: Share (GPS, ISZE level) | C21: =C20/C19 -> 0.98112108 | D21: =D20/D19 -> 0.97151997 | E21: =E20/E19 -> 1.0335111
A22: Stretch idea (%) - set me | C22: 0 | D22: 0 | E22: 0.018
A23: Stretch amount (= max spend x stretch%) | C23: =C19*C22 -> 0 | D23: =D19*D22 -> 0 | E23: =E19*E22 -> 1821.7511
A24: TTL amount (= actual + stretch) << EXTENDED TARGET | C24: =C20+C23 -> 73673.522 | D24: =D20+D23 -> 86604.505 | E24: =E20+E23 -> 106421.75
A25: Share (new) | C25: =C24/C19 -> 0.98112108 | D25: =D24/D19 -> 0.97151997 | E25: =E24/E19 -> 1.0515111
A26: Source: 00_derived/gps_billing_fy_ALLCUSTOMERS.csv canonical 'BL Iceland' (net_gps, GPS-audited, FY-aligned, lubricants included).
A28: ICELAND -> DEALER level (DB->DLR) — MH method (35% DB margin gross-up)
C29: FY25 (Apr'24-Mar'25) | D29: FY26 (Apr'25-Mar'26) | E29: FY27 (Apr'26-Mar'27)
A30: Parts Sales DB-to-DLR (actual) · KPI Master File june 2026.xlsx | C30: 209944 | D30: 195849 | F30: FY25 12/12 mo · FY26 12/12 mo
A31: DB margin % (MH assumption — same as testcase B15) | B31: 0.35
A32: Stretch amount at dealer (= ISZE stretch / (1 − margin)) · MH E29 | E32: =-E23/(B31-1) -> 2802.694
A33: FY27 AMOUNT TO REACH at dealer (= FY26 actual + dealer stretch) | E33: =IF(OR(D30="",D30="no KPI data"),"no KPI data",D30+E32) -> 198651.69
A34: MH method (same factors as ISZE_IUK_Sales_Share_Stretch_TESTCASE): DB margin 35% → dealer stretch = ISZE stretch / (1−0.35) = ISZE stretch / 0.65 (identical to MH E29 = −E41/(0.35−1)). FY27 amount to reach = FY26 dealer actual + dealer stretch. Observed dealer/ISZE often ≠ 1.54x — not used for the conversion.
A37: GAPS / open items
