Workbook

Sheet Dashboard (2)
A1: ISZE — FY2027 GPS Extended Target | K1: GPS stretch FY27 (pt) | N1: 0.018 | O1: Share ceiling | Q1: 1 | R1: Price FY28-31 / yr | T1: 0.03 | V1: Blue/yellow = input. Stretch is capped per distributor so GPS share never passes the ceiling; a distributor already above it keeps its share flat (no stretch).
A2: ISZE->DB level only. Stretch % lives on each DB tab. Everything here and on Waterfall VP is live. Dealer-level (DB->DLR) dropped — see WATCH. | K2: GPS stretch FY28-31 / yr (pt) | N2: 0.01 | V2: FY27 stretch must stay >= ~1.1% to cover the EUR 952K the waterfall needs (Dashboard C25).
K3: 2025年度 | L3: FY2026 | U3: 2026年度 | V3: FY2027 | AE3: 2027年度 | AF3: FY2028 | AO3: 2028年度 | AP3: FY2029 | AY3: 2029年度 | AZ3: FY2030 | BI3: 2030年度 | BJ3: FY2031
A4: DB | B4: Segment | C4: BP FY27 | D4: Max spend | E4: GPS % | F4: Stretch% | G4: Stretch EUR | H4: New GPS | I4: EXT TARGET | J4: Note | K4: ISZE台当たり単価 | M4: UIO | N4: ISZE部品販売 ポテンシャル | O4: ISZE部品売上実績 | P4: ISZE部品カバー率 (実績) | Q4: 販社台当たり単価 | R4: 販社部品販売ポテンシャル | S4: 販社部品販売 (実績) | T4: 販社部品カバー率 (実績) | U4: ISZE台当たり単価 | W4: UIO | X4: ISZE 部品販売 ポテンシャル | Y4: ISZE 部品カバー率 (目標) | Z4: ISZE部品売上目標 | AA4: 販社台当たり単価 | AB4: 販社部品販売ポテンシャル | AC4: 販社部品販売目標 | AD4: 販社部品カバー率(目標) | AE4: ISZE台当たり単価 | AG4: UIO | AH4: ISZE 部品販売 ポテンシャル | AI4: ISZE 部品カバー率 (目標) | AJ4: ISZE部品売上目標 | AK4: 販社台当たり単価 | AL4: 販社部品販売ポテンシャル | AM4: 販社部品販売目標 | AN4: 販社部品カバー率(目標) | AO4: ISZE台当たり単価 | AQ4: UIO | AR4: ISZE 部品販売 ポテンシャル | AS4: ISZE 部品カバー率 (目標) | AT4: ISZE部品売上目標 | AU4: 販社台当たり単価 | AV4: 販社部品販売ポテンシャル | AW4: 販社部品販売目標 | AX4: 販社部品カバー率(目標) | AY4: ISZE台当たり単価 | BA4: UIO | BB4: ISZE 部品販売 ポテンシャル | BC4: ISZE 部品カバー率 (目標) | BD4: ISZE部品売上目標 | BE4: 販社台当たり単価 | BF4: 販社部品販売ポテンシャル | BG4: 販社部品販売目標 | BH4: 販社部品カバー率(目標) | BI4: ISZE台当たり単価 | BK4: UIO | BL4: ISZE 部品販売 ポテンシャル | BM4: ISZE 部品カバー率 (目標) | BN4: ISZE部品売上目標 | BO4: 販社台当たり単価 | BP4: 販社部品販売ポテンシャル | BQ4: 販社部品販売目標 | BR4: 販社部品カバー率(目標)
K5: ISZE Parts Sales per Unit | N5: ISZE Parts Sles Potential | O5: ISZE Parts Sales Actual | P5: ISZE Share Actual | Q5: Distributor's Parts Sales per Unit | R5: Distributor's Parts Sales Potential | S5: Distributor Parts Sales Actual | T5: Dist Parts Share Actual | U5: ISZE Parts Sales per Unit | X5: ISZE Parts Sles Potential | Y5: ISZE Target Share | Z5: ISZE Parts Sales Target | AA5: Distributor's Parts Sales per Unit | AB5: Distributor's Parts Sales Potential | AC5: Distributor Parts Sales Target | AD5: Distributor Parts Share target | AE5: ISZE Parts Sales per Unit | AH5: ISZE Parts Sles Potential | AI5: ISZE Target Share | AJ5: ISZE Parts Sales Target | AK5: Distributor's Parts Sales per Unit | AL5: Distributor's Parts Sales Potential | AM5: Distributor Parts Sales Target | AN5: Distributor Parts Share target | AO5: ISZE Parts Sales per Unit | AR5: ISZE Parts Sles Potential | AS5: ISZE Target Share | AT5: ISZE Parts Sales Target | AU5: Distributor's Parts Sales per Unit | AV5: Distributor's Parts Sales Potential | AW5: Distributor Parts Sales Target | AX5: Distributor Parts Share target | AY5: ISZE Parts Sales per Unit | BB5: ISZE Parts Sles Potential | BC5: ISZE Target Share | BD5: ISZE Parts Sales Target | BE5: Distributor's Parts Sales per Unit | BF5: Distributor's Parts Sales Potential | BG5: Distributor Parts Sales Target | BH5: Distributor Parts Share target | BI5: ISZE Parts Sales per Unit | BL5: ISZE Parts Sles Potential | BM5: ISZE Target Share | BN5: ISZE Parts Sales Target | BO5: Distributor's Parts Sales per Unit | BP5: Distributor's Parts Sales Potential | BQ5: Distributor Parts Sales Target | BR5: Distributor Parts Share target
A6: ITUK | B6: presented | C6: =Dashboard!C5 | D6: =Dashboard!D5 | E6: =Dashboard!E5 | F6: =Dashboard!F5 | G6: =Dashboard!G5 | H6: =Dashboard!H5 | I6: =Dashboard!I5 | J6: V4 basis (CY2027F, no +5%) — NOT rebased | K6: N35 | L6: 281.6 | M6: 11444 | N6: =L6*M6 | Q6: =400*1.12 | R6: =Q6*M6 | U6: N35 | V6: 295.68 | W6: 12345 | X6: =V6*W6 | AA6: =400*1.12*1.03 | AB6: =AA6*W6 | AE6: N35 | AF6: =V6*(1+'Dashboard (2)'!$T$1) | AG6: =ROUND(24336*($W$6/($W$6+$W$7)),0) | AH6: =AF6*AG6 | AK6: =AA6*(1+'Dashboard (2)'!$T$1) | AL6: =AK6*AG6 | AO6: N35 | AP6: =AF6*(1+'Dashboard (2)'!$T$1) | AQ6: =ROUND(25294*($W$6/($W$6+$W$7)),0) | AR6: =AP6*AQ6 | AU6: =AK6*(1+'Dashboard (2)'!$T$1) | AV6: =AU6*AQ6 | AY6: N35 | AZ6: =AP6*(1+'Dashboard (2)'!$T$1) | BA6: =ROUND(26146*($W$6/($W$6+$W$7)),0) | BB6: =AZ6*BA6 | BE6: =AU6*(1+'Dashboard (2)'!$T$1) | BF6: =BE6*BA6 | BI6: N35 | BJ6: =AZ6*(1+'Dashboard (2)'!$T$1) | BK6: =ROUND(26923*($W$6/($W$6+$W$7)),0) | BL6: =BJ6*BK6 | BO6: =BE6*(1+'Dashboard (2)'!$T$1) | BP6: =BO6*BK6
K7: N75 | L7: 704 | M7: 10747 | N7: =L7*M7 | Q7: =1000*1.12 | R7: =Q7*M7 | U7: N75 | V7: 739.2 | W7: 10865 | X7: =V7*W7 | AA7: =1000*1.12*1.03 | AB7: =AA7*W7 | AE7: N75 | AF7: =V7*(1+'Dashboard (2)'!$T$1) | AG7: =24336-AG6 | AH7: =AF7*AG7 | AK7: =AA7*(1+'Dashboard (2)'!$T$1) | AL7: =AK7*AG7 | AO7: N75 | AP7: =AF7*(1+'Dashboard (2)'!$T$1) | AQ7: =25294-AQ6 | AR7: =AP7*AQ7 | AU7: =AK7*(1+'Dashboard (2)'!$T$1) | AV7: =AU7*AQ7 | AY7: N75 | AZ7: =AP7*(1+'Dashboard (2)'!$T$1) | BA7: =26146-BA6 | BB7: =AZ7*BA7 | BE7: =AU7*(1+'Dashboard (2)'!$T$1) | BF7: =BE7*BA7 | BI7: N75 | BJ7: =AZ7*(1+'Dashboard (2)'!$T$1) | BK7: =26923-BK6 | BL7: =BJ7*BK7 | BO7: =BE7*(1+'Dashboard (2)'!$T$1) | BP7: =BO7*BK7
K8: F | L8: 844.8 | M8: 877 | N8: =L8*M8 | Q8: =1200*1.12 | R8: =Q8*M8 | U8: F | V8: 887.04 | W8: 963 | X8: =V8*W8 | AA8: =1200*1.12*1.03 | AB8: =AA8*W8 | AE8: F | AF8: =V8*(1+'Dashboard (2)'!$T$1) | AG8: 1055 | AH8: =AF8*AG8 | AK8: =AA8*(1+'Dashboard (2)'!$T$1) | AL8: =AK8*AG8 | AO8: F | AP8: =AF8*(1+'Dashboard (2)'!$T$1) | AQ8: 1141 | AR8: =AP8*AQ8 | AU8: =AK8*(1+'Dashboard (2)'!$T$1) | AV8: =AU8*AQ8 | AY8: F | AZ8: =AP8*(1+'Dashboard (2)'!$T$1) | BA8: 1218 | BB8: =AZ8*BA8 | BE8: =AU8*(1+'Dashboard (2)'!$T$1) | BF8: =BE8*BA8 | BI8: F | BJ8: =AZ8*(1+'Dashboard (2)'!$T$1) | BK8: 1286 | BL8: =BJ8*BK8 | BO8: =BE8*(1+'Dashboard (2)'!$T$1) | BP8: =BO8*BK8
M9: =SUM(M6:M8) | N9: =SUM(N6:N8) | O9: 6805719.6 | P9: =O9/N9 | R9: =SUM(R6:R8) | S9: =12873997.67*1.12 | T9: =S9/R9 | W9: =SUM(W6:W8) | X9: =SUM(X6:X8) | Y9: =Z9/X9 | Z9: =Dashboard!I5 | AB9: =SUM(AB6:AB8) | AC9: =AB9*AD9 | AD9: =IF(T9>='Dashboard (2)'!$Q$1,T9,MIN(T9+'Dashboard (2)'!$N$1,'Dashboard (2)'!$Q$1)) | AG9: =SUM(AG6:AG8) | AH9: =SUM(AH6:AH8) | AI9: =IF(Y9>='Dashboard (2)'!$Q$1,Y9,MIN(Y9+'Dashboard (2)'!$N$2,'Dashboard (2)'!$Q$1)) | AJ9: =AH9*AI9 | AL9: =SUM(AL6:AL8) | AM9: =AL9*AN9 | AN9: =IF(AD9>='Dashboard (2)'!$Q$1,AD9,MIN(AD9+'Dashboard (2)'!$N$2,'Dashboard (2)'!$Q$1)) | AQ9: =SUM(AQ6:AQ8) | AR9: =SUM(AR6:AR8) | AS9: =IF(AI9>='Dashboard (2)'!$Q$1,AI9,MIN(AI9+'Dashboard (2)'!$N$2,'Dashboard (2)'!$Q$1)) | AT9: =AR9*AS9 | AV9: =SUM(AV6:AV8) | AW9: =AV9*AX9 | AX9: =IF(AN9>='Dashboard (2)'!$Q$1,AN9,MIN(AN9+'Dashboard (2)'!$N$2,'Dashboard (2)'!$Q$1)) | BA9: =SUM(BA6:BA8) | BB9: =SUM(BB6:BB8) | BC9: =IF(AS9>='Dashboard (2)'!$Q$1,AS9,MIN(AS9+'Dashboard (2)'!$N$2,'Dashboard (2)'!$Q$1)) | BD9: =BB9*BC9 | BF9: =SUM(BF6:BF8) | BG9: =BF9*BH9 | BH9: =IF(AX9>='Dashboard (2)'!$Q$1,AX9,MIN(AX9+'Dashboard (2)'!$N$2,'Dashboard (2)'!$Q$1)) | BK9: =SUM(BK6:BK8) | BL9: =SUM(BL6:BL8) | BM9: =IF(BC9>='Dashboard (2)'!$Q$1,BC9,MIN(BC9+'Dashboard (2)'!$N$2,'Dashboard (2)'!$Q$1)) | BN9: =BL9*BM9 | BP9: =SUM(BP6:BP8) | BQ9: =BP9*BR9 | BR9: =IF(BH9>='Dashboard (2)'!$Q$1,BH9,MIN(BH9+'Dashboard (2)'!$N$2,'Dashboard (2)'!$Q$1))
A10: UTI | B10: presented | C10: =Dashboard!C6 | D10: =Dashboard!D6 | E10: =Dashboard!E6 | F10: =Dashboard!F6 | G10: =Dashboard!G6 | H10: =Dashboard!H6 | I10: =Dashboard!I6 | J10: V4 basis (CY2027F, no +5%) — NOT rebased | K10: CV | L10: =V10/1.05 | M10: 10336 | N10: =L10*M10 | O10: 3056797.1 | P10: =O10/N10 | U10: CV | V10: =X10/W10 | W10: 10760 | X10: 8485129 | Y10: =Z10/X10 | Z10: =Dashboard!I6 | AE10: CV | AF10: =V10*(1+'Dashboard (2)'!$T$1) | AG10: 10972 | AH10: =AF10*AG10 | AI10: =IF(Y10>='Dashboard (2)'!$Q$1,Y10,MIN(Y10+'Dashboard (2)'!$N$2,'Dashboard (2)'!$Q$1)) | AJ10: =AH10*AI10 | AO10: CV | AP10: =AF10*(1+'Dashboard (2)'!$T$1) | AQ10: 11280 | AR10: =AP10*AQ10 | AS10: =IF(AI10>='Dashboard (2)'!$Q$1,AI10,MIN(AI10+'Dashboard (2)'!$N$2,'Dashboard (2)'!$Q$1)) | AT10: =AR10*AS10 | AY10: CV | AZ10: =AP10*(1+'Dashboard (2)'!$T$1) | BA10: 11581 | BB10: =AZ10*BA10 | BC10: =IF(AS10>='Dashboard (2)'!$Q$1,AS10,MIN(AS10+'Dashboard (2)'!$N$2,'Dashboard (2)'!$Q$1)) | BD10: =BB10*BC10 | BI10: CV | BJ10: =AZ10*(1+'Dashboard (2)'!$T$1) | BK10: 11882 | BL10: =BJ10*BK10 | BM10: =IF(BC10>='Dashboard (2)'!$Q$1,BC10,MIN(BC10+'Dashboard (2)'!$N$2,'Dashboard (2)'!$Q$1)) | BN10: =BL10*BM10
A11: IUK | B11: LCV | C11: =Dashboard!C7 | D11: =Dashboard!D7 | E11: =Dashboard!E7 | F11: =Dashboard!F7 | G11: =Dashboard!G7 | H11: =Dashboard!H7 | I11: =Dashboard!I7 | K11: LCV | L11: =IUK!D14 | M11: =IUK!D9 | N11: =L11*M11 | O11: =IUK!D20 | P11: =O11/N11 | U11: LCV | V11: =IUK!E14 | W11: =IUK!E9 | X11: =V11*W11 | Y11: =Z11/X11 | Z11: =IUK!E24 | AE11: LCV | AF11: =IUK!F14 | AG11: =IUK!F9 | AH11: =AF11*AG11 | AI11: =IF(Y11>='Dashboard (2)'!$Q$1,Y11,MIN(Y11+'Dashboard (2)'!$N$2,'Dashboard (2)'!$Q$1)) | AJ11: =AH11*AI11 | AO11: LCV | AP11: =IUK!G14 | AQ11: =IUK!G9 | AR11: =AP11*AQ11 | AS11: =IF(AI11>='Dashboard (2)'!$Q$1,AI11,MIN(AI11+'Dashboard (2)'!$N$2,'Dashboard (2)'!$Q$1)) | AT11: =AR11*AS11 | AY11: LCV | AZ11: =IUK!H14 | BA11: =IUK!H9 | BB11: =AZ11*BA11 | BC11: =IF(AS11>='Dashboard (2)'!$Q$1,AS11,MIN(AS11+'Dashboard (2)'!$N$2,'Dashboard (2)'!$Q$1)) | BD11: =BB11*BC11 | BI11: LCV | BJ11: =IUK!I14 | BK11: =IUK!I9 | BL11: =BJ11*BK11 | BM11: =IF(BC11>='Dashboard (2)'!$Q$1,BC11,MIN(BC11+'Dashboard (2)'!$N$2,'Dashboard (2)'!$Q$1)) | BN11: =BL11*BM11
A12: UMI | B12: LCV | C12: =Dashboard!C8 | D12: =Dashboard!D8 | E12: =Dashboard!E8 | F12: =Dashboard!F8 | G12: =Dashboard!G8 | H12: =Dashboard!H8 | I12: =Dashboard!I8 | K12: LCV | L12: =UMI!D14 | M12: =UMI!D9 | N12: =L12*M12 | O12: =UMI!D20 | P12: =O12/N12 | U12: LCV | V12: =UMI!E14 | W12: =UMI!E9 | X12: =V12*W12 | Y12: =Z12/X12 | Z12: =UMI!E24 | AE12: LCV | AF12: =UMI!F14 | AG12: =UMI!F9 | AH12: =AF12*AG12 | AI12: =IF(Y12>='Dashboard (2)'!$Q$1,Y12,MIN(Y12+'Dashboard (2)'!$N$2,'Dashboard (2)'!$Q$1)) | AJ12: =AH12*AI12 | AO12: LCV | AP12: =UMI!G14 | AQ12: =UMI!G9 | AR12: =AP12*AQ12 | AS12: =IF(AI12>='Dashboard (2)'!$Q$1,AI12,MIN(AI12+'Dashboard (2)'!$N$2,'Dashboard (2)'!$Q$1)) | AT12: =AR12*AS12 | AY12: LCV | AZ12: =UMI!H14 | BA12: =UMI!H9 | BB12: =AZ12*BA12 | BC12: =IF(AS12>='Dashboard (2)'!$Q$1,AS12,MIN(AS12+'Dashboard (2)'!$N$2,'Dashboard (2)'!$Q$1)) | BD12: =BB12*BC12 | BI12: LCV | BJ12: =UMI!I14 | BK12: =UMI!I9 | BL12: =BJ12*BK12 | BM12: =IF(BC12>='Dashboard (2)'!$Q$1,BC12,MIN(BC12+'Dashboard (2)'!$N$2,'Dashboard (2)'!$Q$1)) | BN12: =BL12*BM12
A13: NORWAY | B13: LCV | C13: =Dashboard!C9 | D13: =Dashboard!D9 | E13: =Dashboard!E9 | F13: =Dashboard!F9 | G13: =Dashboard!G9 | H13: =Dashboard!H9 | I13: =Dashboard!I9 | K13: LCV | L13: =NORWAY!D14 | M13: =NORWAY!D9 | N13: =L13*M13 | O13: =NORWAY!D20 | P13: =O13/N13 | U13: LCV | V13: =NORWAY!E14 | W13: =NORWAY!E9 | X13: =V13*W13 | Y13: =Z13/X13 | Z13: =NORWAY!E24 | AE13: LCV | AF13: =NORWAY!F14 | AG13: =NORWAY!F9 | AH13: =AF13*AG13 | AI13: =IF(Y13>='Dashboard (2)'!$Q$1,Y13,MIN(Y13+'Dashboard (2)'!$N$2,'Dashboard (2)'!$Q$1)) | AJ13: =AH13*AI13 | AO13: LCV | AP13: =NORWAY!G14 | AQ13: =NORWAY!G9 | AR13: =AP13*AQ13 | AS13: =IF(AI13>='Dashboard (2)'!$Q$1,AI13,MIN(AI13+'Dashboard (2)'!$N$2,'Dashboard (2)'!$Q$1)) | AT13: =AR13*AS13 | AY13: LCV | AZ13: =NORWAY!H14 | BA13: =NORWAY!H9 | BB13: =AZ13*BA13 | BC13: =IF(AS13>='Dashboard (2)'!$Q$1,AS13,MIN(AS13+'Dashboard (2)'!$N$2,'Dashboard (2)'!$Q$1)) | BD13: =BB13*BC13 | BI13: LCV | BJ13: =NORWAY!I14 | BK13: =NORWAY!I9 | BL13: =BJ13*BK13 | BM13: =IF(BC13>='Dashboard (2)'!$Q$1,BC13,MIN(BC13+'Dashboard (2)'!$N$2,'Dashboard (2)'!$Q$1)) | BN13: =BL13*BM13
A14: SWEDEN | B14: LCV | C14: =Dashboard!C10 | D14: =Dashboard!D10 | E14: =Dashboard!E10 | F14: =Dashboard!F10 | G14: =Dashboard!G10 | H14: =Dashboard!H10 | I14: =Dashboard!I10 | K14: LCV | L14: =SWEDEN!D14 | M14: =SWEDEN!D9 | N14: =L14*M14 | O14: =SWEDEN!D20 | P14: =O14/N14 | U14: LCV | V14: =SWEDEN!E14 | W14: =SWEDEN!E9 | X14: =V14*W14 | Y14: =Z14/X14 | Z14: =SWEDEN!E24 | AE14: LCV | AF14: =SWEDEN!F14 | AG14: =SWEDEN!F9 | AH14: =AF14*AG14 | AI14: =IF(Y14>='Dashboard (2)'!$Q$1,Y14,MIN(Y14+'Dashboard (2)'!$N$2,'Dashboard (2)'!$Q$1)) | AJ14: =AH14*AI14 | AO14: LCV | AP14: =SWEDEN!G14 | AQ14: =SWEDEN!G9 | AR14: =AP14*AQ14 | AS14: =IF(AI14>='Dashboard (2)'!$Q$1,AI14,MIN(AI14+'Dashboard (2)'!$N$2,'Dashboard (2)'!$Q$1)) | AT14: =AR14*AS14 | AY14: LCV | AZ14: =SWEDEN!H14 | BA14: =SWEDEN!H9 | BB14: =AZ14*BA14 | BC14: =IF(AS14>='Dashboard (2)'!$Q$1,AS14,MIN(AS14+'Dashboard (2)'!$N$2,'Dashboard (2)'!$Q$1)) | BD14: =BB14*BC14 | BI14: LCV | BJ14: =SWEDEN!I14 | BK14: =SWEDEN!I9 | BL14: =BJ14*BK14 | BM14: =IF(BC14>='Dashboard (2)'!$Q$1,BC14,MIN(BC14+'Dashboard (2)'!$N$2,'Dashboard (2)'!$Q$1)) | BN14: =BL14*BM14
A15: HUNGARY | B15: LCV | C15: =Dashboard!C11 | D15: =Dashboard!D11 | E15: =Dashboard!E11 | F15: =Dashboard!F11 | G15: =Dashboard!G11 | H15: =Dashboard!H11 | I15: =Dashboard!I11 | K15: LCV | L15: =HUNGARY!D14 | M15: =HUNGARY!D9 | N15: =L15*M15 | O15: =HUNGARY!D20 | P15: =O15/N15 | U15: LCV | V15: =HUNGARY!E14 | W15: =HUNGARY!E9 | X15: =V15*W15 | Y15: =Z15/X15 | Z15: =HUNGARY!E24 | AE15: LCV | AF15: =HUNGARY!F14 | AG15: =HUNGARY!F9 | AH15: =AF15*AG15 | AI15: =IF(Y15>='Dashboard (2)'!$Q$1,Y15,MIN(Y15+'Dashboard (2)'!$N$2,'Dashboard (2)'!$Q$1)) | AJ15: =AH15*AI15 | AO15: LCV | AP15: =HUNGARY!G14 | AQ15: =HUNGARY!G9 | AR15: =AP15*AQ15 | AS15: =IF(AI15>='Dashboard (2)'!$Q$1,AI15,MIN(AI15+'Dashboard (2)'!$N$2,'Dashboard (2)'!$Q$1)) | AT15: =AR15*AS15 | AY15: LCV | AZ15: =HUNGARY!H14 | BA15: =HUNGARY!H9 | BB15: =AZ15*BA15 | BC15: =IF(AS15>='Dashboard (2)'!$Q$1,AS15,MIN(AS15+'Dashboard (2)'!$N$2,'Dashboard (2)'!$Q$1)) | BD15: =BB15*BC15 | BI15: LCV | BJ15: =HUNGARY!I14 | BK15: =HUNGARY!I9 | BL15: =BJ15*BK15 | BM15: =IF(BC15>='Dashboard (2)'!$Q$1,BC15,MIN(BC15+'Dashboard (2)'!$N$2,'Dashboard (2)'!$Q$1)) | BN15: =BL15*BM15
A16: FINLAND | B16: LCV | C16: =Dashboard!C12 | D16: =Dashboard!D12 | E16: =Dashboard!E12 | F16: =Dashboard!F12 | G16: =Dashboard!G12 | H16: =Dashboard!H12 | I16: =Dashboard!I12 | K16: LCV | L16: =FINLAND!D14 | M16: =FINLAND!D9 | N16: =L16*M16 | O16: =FINLAND!D20 | P16: =O16/N16 | U16: LCV | V16: =FINLAND!E14 | W16: =FINLAND!E9 | X16: =V16*W16 | Y16: =Z16/X16 | Z16: =FINLAND!E24 | AE16: LCV | AF16: =FINLAND!F14 | AG16: =FINLAND!F9 | AH16: =AF16*AG16 | AI16: =IF(Y16>='Dashboard (2)'!$Q$1,Y16,MIN(Y16+'Dashboard (2)'!$N$2,'Dashboard (2)'!$Q$1)) | AJ16: =AH16*AI16 | AO16: LCV | AP16: =FINLAND!G14 | AQ16: =FINLAND!G9 | AR16: =AP16*AQ16 | AS16: =IF(AI16>='Dashboard (2)'!$Q$1,AI16,MIN(AI16+'Dashboard (2)'!$N$2,'Dashboard (2)'!$Q$1)) | AT16: =AR16*AS16 | AY16: LCV | AZ16: =FINLAND!H14 | BA16: =FINLAND!H9 | BB16: =AZ16*BA16 | BC16: =IF(AS16>='Dashboard (2)'!$Q$1,AS16,MIN(AS16+'Dashboard (2)'!$N$2,'Dashboard (2)'!$Q$1)) | BD16: =BB16*BC16 | BI16: LCV | BJ16: =FINLAND!I14 | BK16: =FINLAND!I9 | BL16: =BJ16*BK16 | BM16: =IF(BC16>='Dashboard (2)'!$Q$1,BC16,MIN(BC16+'Dashboard (2)'!$N$2,'Dashboard (2)'!$Q$1)) | BN16: =BL16*BM16
A17: ROMANIA | B17: LCV | C17: =Dashboard!C13 | D17: =Dashboard!D13 | E17: =Dashboard!E13 | F17: =Dashboard!F13 | G17: =Dashboard!G13 | H17: =Dashboard!H13 | I17: =Dashboard!I13 | K17: LCV | L17: =ROMANIA!D14 | M17: =ROMANIA!D9 | N17: =L17*M17 | O17: =ROMANIA!D20 | P17: =O17/N17 | U17: LCV | V17: =ROMANIA!E14 | W17: =ROMANIA!E9 | X17: =V17*W17 | Y17: =Z17/X17 | Z17: =ROMANIA!E24 | AE17: LCV | AF17: =ROMANIA!F14 | AG17: =ROMANIA!F9 | AH17: =AF17*AG17 | AI17: =IF(Y17>='Dashboard (2)'!$Q$1,Y17,MIN(Y17+'Dashboard (2)'!$N$2,'Dashboard (2)'!$Q$1)) | AJ17: =AH17*AI17 | AO17: LCV | AP17: =ROMANIA!G14 | AQ17: =ROMANIA!G9 | AR17: =AP17*AQ17 | AS17: =IF(AI17>='Dashboard (2)'!$Q$1,AI17,MIN(AI17+'Dashboard (2)'!$N$2,'Dashboard (2)'!$Q$1)) | AT17: =AR17*AS17 | AY17: LCV | AZ17: =ROMANIA!H14 | BA17: =ROMANIA!H9 | BB17: =AZ17*BA17 | BC17: =IF(AS17>='Dashboard (2)'!$Q$1,AS17,MIN(AS17+'Dashboard (2)'!$N$2,'Dashboard (2)'!$Q$1)) | BD17: =BB17*BC17 | BI17: LCV | BJ17: =ROMANIA!I14 | BK17: =ROMANIA!I9 | BL17: =BJ17*BK17 | BM17: =IF(BC17>='Dashboard (2)'!$Q$1,BC17,MIN(BC17+'Dashboard (2)'!$N$2,'Dashboard (2)'!$Q$1)) | BN17: =BL17*BM17
A18: DENMARK | B18: LCV | C18: =Dashboard!C14 | D18: =Dashboard!D14 | E18: =Dashboard!E14 | F18: =Dashboard!F14 | G18: =Dashboard!G14 | H18: =Dashboard!H14 | I18: =Dashboard!I14 | K18: LCV | L18: =DENMARK!D14 | M18: =DENMARK!D9 | N18: =L18*M18 | O18: =DENMARK!D20 | P18: =O18/N18 | U18: LCV | V18: =DENMARK!E14 | W18: =DENMARK!E9 | X18: =V18*W18 | Y18: =Z18/X18 | Z18: =DENMARK!E24 | AE18: LCV | AF18: =DENMARK!F14 | AG18: =DENMARK!F9 | AH18: =AF18*AG18 | AI18: =IF(Y18>='Dashboard (2)'!$Q$1,Y18,MIN(Y18+'Dashboard (2)'!$N$2,'Dashboard (2)'!$Q$1)) | AJ18: =AH18*AI18 | AO18: LCV | AP18: =DENMARK!G14 | AQ18: =DENMARK!G9 | AR18: =AP18*AQ18 | AS18: =IF(AI18>='Dashboard (2)'!$Q$1,AI18,MIN(AI18+'Dashboard (2)'!$N$2,'Dashboard (2)'!$Q$1)) | AT18: =AR18*AS18 | AY18: LCV | AZ18: =DENMARK!H14 | BA18: =DENMARK!H9 | BB18: =AZ18*BA18 | BC18: =IF(AS18>='Dashboard (2)'!$Q$1,AS18,MIN(AS18+'Dashboard (2)'!$N$2,'Dashboard (2)'!$Q$1)) | BD18: =BB18*BC18 | BI18: LCV | BJ18: =DENMARK!I14 | BK18: =DENMARK!I9 | BL18: =BJ18*BK18 | BM18: =IF(BC18>='Dashboard (2)'!$Q$1,BC18,MIN(BC18+'Dashboard (2)'!$N$2,'Dashboard (2)'!$Q$1)) | BN18: =BL18*BM18
A19: ICELAND | B19: LCV | C19: =Dashboard!C15 | D19: =Dashboard!D15 | E19: =Dashboard!E15 | F19: =Dashboard!F15 | G19: =Dashboard!G15 | H19: =Dashboard!H15 | I19: =Dashboard!I15 | K19: LCV | L19: =ICELAND!D14 | M19: =ICELAND!D9 | N19: =L19*M19 | O19: =ICELAND!D20 | P19: =O19/N19 | U19: LCV | V19: =ICELAND!E14 | W19: =ICELAND!E9 | X19: =V19*W19 | Y19: =Z19/X19 | Z19: =ICELAND!E24 | AE19: LCV | AF19: =ICELAND!F14 | AG19: =ICELAND!F9 | AH19: =AF19*AG19 | AI19: =IF(Y19>='Dashboard (2)'!$Q$1,Y19,MIN(Y19+'Dashboard (2)'!$N$2,'Dashboard (2)'!$Q$1)) | AJ19: =AH19*AI19 | AO19: LCV | AP19: =ICELAND!G14 | AQ19: =ICELAND!G9 | AR19: =AP19*AQ19 | AS19: =IF(AI19>='Dashboard (2)'!$Q$1,AI19,MIN(AI19+'Dashboard (2)'!$N$2,'Dashboard (2)'!$Q$1)) | AT19: =AR19*AS19 | AY19: LCV | AZ19: =ICELAND!H14 | BA19: =ICELAND!H9 | BB19: =AZ19*BA19 | BC19: =IF(AS19>='Dashboard (2)'!$Q$1,AS19,MIN(AS19+'Dashboard (2)'!$N$2,'Dashboard (2)'!$Q$1)) | BD19: =BB19*BC19 | BI19: LCV | BJ19: =ICELAND!I14 | BK19: =ICELAND!I9 | BL19: =BJ19*BK19 | BM19: =IF(BC19>='Dashboard (2)'!$Q$1,BC19,MIN(BC19+'Dashboard (2)'!$N$2,'Dashboard (2)'!$Q$1)) | BN19: =BL19*BM19
A20: GERMANY | B20: mixed | C20: =Dashboard!C16 | D20: =Dashboard!D16 | E20: =Dashboard!E16 | F20: =Dashboard!F16 | G20: =Dashboard!G16 | H20: =Dashboard!H16 | I20: =Dashboard!I16 | K20: CV LD | L20: =GERMANY!C17 | M20: =GERMANY!D9 | N20: =L20*M20 | U20: CV LD | V20: =GERMANY!D17 | W20: =GERMANY!E9 | X20: =V20*W20 | AE20: CV LD | AF20: =GERMANY!E17 | AG20: =GERMANY!F9 | AH20: =AF20*AG20 | AO20: CV LD | AP20: =GERMANY!F17 | AQ20: =GERMANY!G9 | AR20: =AP20*AQ20 | AY20: CV LD | AZ20: =GERMANY!G17 | BA20: =GERMANY!H9 | BB20: =AZ20*BA20 | BI20: CV LD | BJ20: =GERMANY!H17 | BK20: =GERMANY!I9 | BL20: =BJ20*BK20
K21: CV MD | L21: =GERMANY!C18 | M21: =GERMANY!D10 | N21: =L21*M21 | U21: CV MD | V21: =GERMANY!D18 | W21: =GERMANY!E10 | X21: =V21*W21 | AE21: CV MD | AF21: =GERMANY!E18 | AG21: =GERMANY!F10 | AH21: =AF21*AG21 | AO21: CV MD | AP21: =GERMANY!F18 | AQ21: =GERMANY!G10 | AR21: =AP21*AQ21 | AY21: CV MD | AZ21: =GERMANY!G18 | BA21: =GERMANY!H10 | BB21: =AZ21*BA21 | BI21: CV MD | BJ21: =GERMANY!H18 | BK21: =GERMANY!I10 | BL21: =BJ21*BK21
K22: LCV | L22: =GERMANY!C20 | M22: =GERMANY!D12 | N22: =L22*M22 | U22: LCV | V22: =GERMANY!D20 | W22: =GERMANY!E12 | X22: =V22*W22 | AE22: LCV | AF22: =GERMANY!E20 | AG22: =GERMANY!F12 | AH22: =AF22*AG22 | AO22: LCV | AP22: =GERMANY!F20 | AQ22: =GERMANY!G12 | AR22: =AP22*AQ22 | AY22: LCV | AZ22: =GERMANY!G20 | BA22: =GERMANY!H12 | BB22: =AZ22*BA22 | BI22: LCV | BJ22: =GERMANY!H20 | BK22: =GERMANY!I12 | BL22: =BJ22*BK22
M23: =SUM(M20:M22) | N23: =SUM(N20:N22) | O23: =GERMANY!D26 | P23: =O23/N23 | W23: =SUM(W20:W22) | X23: =SUM(X20:X22) | Y23: =Z23/X23 | Z23: =GERMANY!E30 | AG23: =SUM(AG20:AG22) | AH23: =SUM(AH20:AH22) | AI23: =IF(Y23>='Dashboard (2)'!$Q$1,Y23,MIN(Y23+'Dashboard (2)'!$N$2,'Dashboard (2)'!$Q$1)) | AJ23: =AH23*AI23 | AQ23: =SUM(AQ20:AQ22) | AR23: =SUM(AR20:AR22) | AS23: =IF(AI23>='Dashboard (2)'!$Q$1,AI23,MIN(AI23+'Dashboard (2)'!$N$2,'Dashboard (2)'!$Q$1)) | AT23: =AR23*AS23 | BA23: =SUM(BA20:BA22) | BB23: =SUM(BB20:BB22) | BC23: =IF(AS23>='Dashboard (2)'!$Q$1,AS23,MIN(AS23+'Dashboard (2)'!$N$2,'Dashboard (2)'!$Q$1)) | BD23: =BB23*BC23 | BK23: =SUM(BK20:BK22) | BL23: =SUM(BL20:BL22) | BM23: =IF(BC23>='Dashboard (2)'!$Q$1,BC23,MIN(BC23+'Dashboard (2)'!$N$2,'Dashboard (2)'!$Q$1)) | BN23: =BL23*BM23
A24: BELGIUM | B24: mixed | C24: =Dashboard!C17 | D24: =Dashboard!D17 | E24: =Dashboard!E17 | F24: =Dashboard!F17 | G24: =Dashboard!G17 | H24: =Dashboard!H17 | I24: =Dashboard!I17 | K24: CV LD | L24: =BELGIUM!C17 | M24: =BELGIUM!D9 | N24: =L24*M24 | U24: CV LD | V24: =BELGIUM!D17 | W24: =BELGIUM!E9 | X24: =V24*W24 | AE24: CV LD | AF24: =BELGIUM!E17 | AG24: =BELGIUM!F9 | AH24: =AF24*AG24 | AO24: CV LD | AP24: =BELGIUM!F17 | AQ24: =BELGIUM!G9 | AR24: =AP24*AQ24 | AY24: CV LD | AZ24: =BELGIUM!G17 | BA24: =BELGIUM!H9 | BB24: =AZ24*BA24 | BI24: CV LD | BJ24: =BELGIUM!H17 | BK24: =BELGIUM!I9 | BL24: =BJ24*BK24
K25: LCV | L25: =BELGIUM!C20 | M25: =BELGIUM!D12 | N25: =L25*M25 | U25: LCV | V25: =BELGIUM!D20 | W25: =BELGIUM!E12 | X25: =V25*W25 | AE25: LCV | AF25: =BELGIUM!E20 | AG25: =BELGIUM!F12 | AH25: =AF25*AG25 | AO25: LCV | AP25: =BELGIUM!F20 | AQ25: =BELGIUM!G12 | AR25: =AP25*AQ25 | AY25: LCV | AZ25: =BELGIUM!G20 | BA25: =BELGIUM!H12 | BB25: =AZ25*BA25 | BI25: LCV | BJ25: =BELGIUM!H20 | BK25: =BELGIUM!I12 | BL25: =BJ25*BK25
M26: =SUM(M24:M25) | N26: =SUM(N24:N25) | O26: =BELGIUM!D26 | P26: =O26/N26 | W26: =SUM(W24:W25) | X26: =SUM(X24:X25) | Y26: =Z26/X26 | Z26: =BELGIUM!E30 | AG26: =SUM(AG24:AG25) | AH26: =SUM(AH24:AH25) | AI26: =IF(Y26>='Dashboard (2)'!$Q$1,Y26,MIN(Y26+'Dashboard (2)'!$N$2,'Dashboard (2)'!$Q$1)) | AJ26: =AH26*AI26 | AQ26: =SUM(AQ24:AQ25) | AR26: =SUM(AR24:AR25) | AS26: =IF(AI26>='Dashboard (2)'!$Q$1,AI26,MIN(AI26+'Dashboard (2)'!$N$2,'Dashboard (2)'!$Q$1)) | AT26: =AR26*AS26 | BA26: =SUM(BA24:BA25) | BB26: =SUM(BB24:BB25) | BC26: =IF(AS26>='Dashboard (2)'!$Q$1,AS26,MIN(AS26+'Dashboard (2)'!$N$2,'Dashboard (2)'!$Q$1)) | BD26: =BB26*BC26 | BK26: =SUM(BK24:BK25) | BL26: =SUM(BL24:BL25) | BM26: =IF(BC26>='Dashboard (2)'!$Q$1,BC26,MIN(BC26+'Dashboard (2)'!$N$2,'Dashboard (2)'!$Q$1)) | BN26: =BL26*BM26
A27: PORTUGAL | B27: mixed | C27: =Dashboard!C18 | D27: =Dashboard!D18 | E27: =Dashboard!E18 | F27: =Dashboard!F18 | G27: =Dashboard!G18 | H27: =Dashboard!H18 | I27: =Dashboard!I18 | K27: CV N | L27: =PORTUGAL!C17 | M27: =PORTUGAL!D9 | N27: =L27*M27 | U27: CV N | V27: =PORTUGAL!D17 | W27: =PORTUGAL!E9 | X27: =V27*W27 | AE27: CV N | AF27: =PORTUGAL!E17 | AG27: =PORTUGAL!F9 | AH27: =AF27*AG27 | AO27: CV N | AP27: =PORTUGAL!F17 | AQ27: =PORTUGAL!G9 | AR27: =AP27*AQ27 | AY27: CV N | AZ27: =PORTUGAL!G17 | BA27: =PORTUGAL!H9 | BB27: =AZ27*BA27 | BI27: CV N | BJ27: =PORTUGAL!H17 | BK27: =PORTUGAL!I9 | BL27: =BJ27*BK27
K28: CV F | L28: =IFERROR(N28/M28,0) | M28: =PORTUGAL!D10+PORTUGAL!D11 | N28: =PORTUGAL!C18*PORTUGAL!D10+PORTUGAL!C19*PORTUGAL!D11 | U28: CV F | V28: =IFERROR(X28/W28,0) | W28: =PORTUGAL!E10+PORTUGAL!E11 | X28: =PORTUGAL!D18*PORTUGAL!E10+PORTUGAL!D19*PORTUGAL!E11 | AE28: CV F | AF28: =IFERROR(AH28/AG28,0) | AG28: =PORTUGAL!F10+PORTUGAL!F11 | AH28: =PORTUGAL!E18*PORTUGAL!F10+PORTUGAL!E19*PORTUGAL!F11 | AO28: CV F | AP28: =IFERROR(AR28/AQ28,0) | AQ28: =PORTUGAL!G10+PORTUGAL!G11 | AR28: =PORTUGAL!F18*PORTUGAL!G10+PORTUGAL!F19*PORTUGAL!G11 | AY28: CV F | AZ28: =IFERROR(BB28/BA28,0) | BA28: =PORTUGAL!H10+PORTUGAL!H11 | BB28: =PORTUGAL!G18*PORTUGAL!H10+PORTUGAL!G19*PORTUGAL!H11 | BI28: CV F | BJ28: =IFERROR(BL28/BK28,0) | BK28: =PORTUGAL!I10+PORTUGAL!I11 | BL28: =PORTUGAL!H18*PORTUGAL!I10+PORTUGAL!H19*PORTUGAL!I11
K29: LCV | L29: =PORTUGAL!C20 | M29: =PORTUGAL!D12 | N29: =L29*M29 | U29: LCV | V29: =PORTUGAL!D20 | W29: =PORTUGAL!E12 | X29: =V29*W29 | AE29: LCV | AF29: =PORTUGAL!E20 | AG29: =PORTUGAL!F12 | AH29: =AF29*AG29 | AO29: LCV | AP29: =PORTUGAL!F20 | AQ29: =PORTUGAL!G12 | AR29: =AP29*AQ29 | AY29: LCV | AZ29: =PORTUGAL!G20 | BA29: =PORTUGAL!H12 | BB29: =AZ29*BA29 | BI29: LCV | BJ29: =PORTUGAL!H20 | BK29: =PORTUGAL!I12 | BL29: =BJ29*BK29
M30: =SUM(M27:M29) | N30: =SUM(N27:N29) | O30: =PORTUGAL!D26 | P30: =O30/N30 | W30: =SUM(W27:W29) | X30: =SUM(X27:X29) | Y30: =Z30/X30 | Z30: =PORTUGAL!E30 | AG30: =SUM(AG27:AG29) | AH30: =SUM(AH27:AH29) | AI30: =IF(Y30>='Dashboard (2)'!$Q$1,Y30,MIN(Y30+'Dashboard (2)'!$N$2,'Dashboard (2)'!$Q$1)) | AJ30: =AH30*AI30 | AQ30: =SUM(AQ27:AQ29) | AR30: =SUM(AR27:AR29) | AS30: =IF(AI30>='Dashboard (2)'!$Q$1,AI30,MIN(AI30+'Dashboard (2)'!$N$2,'Dashboard (2)'!$Q$1)) | AT30: =AR30*AS30 | BA30: =SUM(BA27:BA29) | BB30: =SUM(BB27:BB29) | BC30: =IF(AS30>='Dashboard (2)'!$Q$1,AS30,MIN(AS30+'Dashboard (2)'!$N$2,'Dashboard (2)'!$Q$1)) | BD30: =BB30*BC30 | BK30: =SUM(BK27:BK29) | BL30: =SUM(BL27:BL29) | BM30: =IF(BC30>='Dashboard (2)'!$Q$1,BC30,MIN(BC30+'Dashboard (2)'!$N$2,'Dashboard (2)'!$Q$1)) | BN30: =BL30*BM30
A31: IRELAND | B31: mixed | C31: =Dashboard!C19 | D31: =Dashboard!D19 | E31: =Dashboard!E19 | F31: =Dashboard!F19 | G31: =Dashboard!G19 | H31: =Dashboard!H19 | I31: =Dashboard!I19 | K31: CV N | L31: =IRELAND!C17 | M31: =IRELAND!D9 | N31: =L31*M31 | U31: CV N | V31: =IRELAND!D17 | W31: =IRELAND!E9 | X31: =V31*W31 | AE31: CV N | AF31: =IRELAND!E17 | AG31: =IRELAND!F9 | AH31: =AF31*AG31 | AO31: CV N | AP31: =IRELAND!F17 | AQ31: =IRELAND!G9 | AR31: =AP31*AQ31 | AY31: CV N | AZ31: =IRELAND!G17 | BA31: =IRELAND!H9 | BB31: =AZ31*BA31 | BI31: CV N | BJ31: =IRELAND!H17 | BK31: =IRELAND!I9 | BL31: =BJ31*BK31
K32: CV F | L32: =IFERROR(N32/M32,0) | M32: =IRELAND!D10+IRELAND!D11 | N32: =IRELAND!C18*IRELAND!D10+IRELAND!C19*IRELAND!D11 | U32: CV F | V32: =IFERROR(X32/W32,0) | W32: =IRELAND!E10+IRELAND!E11 | X32: =IRELAND!D18*IRELAND!E10+IRELAND!D19*IRELAND!E11 | AE32: CV F | AF32: =IFERROR(AH32/AG32,0) | AG32: =IRELAND!F10+IRELAND!F11 | AH32: =IRELAND!E18*IRELAND!F10+IRELAND!E19*IRELAND!F11 | AO32: CV F | AP32: =IFERROR(AR32/AQ32,0) | AQ32: =IRELAND!G10+IRELAND!G11 | AR32: =IRELAND!F18*IRELAND!G10+IRELAND!F19*IRELAND!G11 | AY32: CV F | AZ32: =IFERROR(BB32/BA32,0) | BA32: =IRELAND!H10+IRELAND!H11 | BB32: =IRELAND!G18*IRELAND!H10+IRELAND!G19*IRELAND!H11 | BI32: CV F | BJ32: =IFERROR(BL32/BK32,0) | BK32: =IRELAND!I10+IRELAND!I11 | BL32: =IRELAND!H18*IRELAND!I10+IRELAND!H19*IRELAND!I11
K33: LCV | L33: =IRELAND!C20 | M33: =IRELAND!D12 | N33: =L33*M33 | U33: LCV | V33: =IRELAND!D20 | W33: =IRELAND!E12 | X33: =V33*W33 | AE33: LCV | AF33: =IRELAND!E20 | AG33: =IRELAND!F12 | AH33: =AF33*AG33 | AO33: LCV | AP33: =IRELAND!F20 | AQ33: =IRELAND!G12 | AR33: =AP33*AQ33 | AY33: LCV | AZ33: =IRELAND!G20 | BA33: =IRELAND!H12 | BB33: =AZ33*BA33 | BI33: LCV | BJ33: =IRELAND!H20 | BK33: =IRELAND!I12 | BL33: =BJ33*BK33
M34: =SUM(M31:M33) | N34: =SUM(N31:N33) | O34: =IRELAND!D26 | P34: =O34/N34 | W34: =SUM(W31:W33) | X34: =SUM(X31:X33) | Y34: =Z34/X34 | Z34: =IRELAND!E30 | AG34: =SUM(AG31:AG33) | AH34: =SUM(AH31:AH33) | AI34: =IF(Y34>='Dashboard (2)'!$Q$1,Y34,MIN(Y34+'Dashboard (2)'!$N$2,'Dashboard (2)'!$Q$1)) | AJ34: =AH34*AI34 | AQ34: =SUM(AQ31:AQ33) | AR34: =SUM(AR31:AR33) | AS34: =IF(AI34>='Dashboard (2)'!$Q$1,AI34,MIN(AI34+'Dashboard (2)'!$N$2,'Dashboard (2)'!$Q$1)) | AT34: =AR34*AS34 | BA34: =SUM(BA31:BA33) | BB34: =SUM(BB31:BB33) | BC34: =IF(AS34>='Dashboard (2)'!$Q$1,AS34,MIN(AS34+'Dashboard (2)'!$N$2,'Dashboard (2)'!$Q$1)) | BD34: =BB34*BC34 | BK34: =SUM(BK31:BK33) | BL34: =SUM(BL31:BL33) | BM34: =IF(BC34>='Dashboard (2)'!$Q$1,BC34,MIN(BC34+'Dashboard (2)'!$N$2,'Dashboard (2)'!$Q$1)) | BN34: =BL34*BM34
A35: GREECE | B35: mixed | C35: =Dashboard!C20 | D35: =Dashboard!D20 | E35: =Dashboard!E20 | F35: =Dashboard!F20 | G35: =Dashboard!G20 | H35: =Dashboard!H20 | I35: =Dashboard!I20 | K35: CV N+MD | L35: =IFERROR(N35/M35,0) | M35: =GREECE!D9+GREECE!D10 | N35: =GREECE!C17*GREECE!D9+GREECE!C18*GREECE!D10 | U35: CV N+MD | V35: =IFERROR(X35/W35,0) | W35: =GREECE!E9+GREECE!E10 | X35: =GREECE!D17*GREECE!E9+GREECE!D18*GREECE!E10 | AE35: CV N+MD | AF35: =IFERROR(AH35/AG35,0) | AG35: =GREECE!F9+GREECE!F10 | AH35: =GREECE!E17*GREECE!F9+GREECE!E18*GREECE!F10 | AO35: CV N+MD | AP35: =IFERROR(AR35/AQ35,0) | AQ35: =GREECE!G9+GREECE!G10 | AR35: =GREECE!F17*GREECE!G9+GREECE!F18*GREECE!G10 | AY35: CV N+MD | AZ35: =IFERROR(BB35/BA35,0) | BA35: =GREECE!H9+GREECE!H10 | BB35: =GREECE!G17*GREECE!H9+GREECE!G18*GREECE!H10 | BI35: CV N+MD | BJ35: =IFERROR(BL35/BK35,0) | BK35: =GREECE!I9+GREECE!I10 | BL35: =GREECE!H17*GREECE!I9+GREECE!H18*GREECE!I10
K36: LCV | L36: =GREECE!C20 | M36: =GREECE!D12 | N36: =L36*M36 | U36: LCV | V36: =GREECE!D20 | W36: =GREECE!E12 | X36: =V36*W36 | AE36: LCV | AF36: =GREECE!E20 | AG36: =GREECE!F12 | AH36: =AF36*AG36 | AO36: LCV | AP36: =GREECE!F20 | AQ36: =GREECE!G12 | AR36: =AP36*AQ36 | AY36: LCV | AZ36: =GREECE!G20 | BA36: =GREECE!H12 | BB36: =AZ36*BA36 | BI36: LCV | BJ36: =GREECE!H20 | BK36: =GREECE!I12 | BL36: =BJ36*BK36
M37: =SUM(M35:M36) | N37: =SUM(N35:N36) | O37: =GREECE!D26 | P37: =O37/N37 | W37: =SUM(W35:W36) | X37: =SUM(X35:X36) | Y37: =Z37/X37 | Z37: =GREECE!E30 | AG37: =SUM(AG35:AG36) | AH37: =SUM(AH35:AH36) | AI37: =IF(Y37>='Dashboard (2)'!$Q$1,Y37,MIN(Y37+'Dashboard (2)'!$N$2,'Dashboard (2)'!$Q$1)) | AJ37: =AH37*AI37 | AQ37: =SUM(AQ35:AQ36) | AR37: =SUM(AR35:AR36) | AS37: =IF(AI37>='Dashboard (2)'!$Q$1,AI37,MIN(AI37+'Dashboard (2)'!$N$2,'Dashboard (2)'!$Q$1)) | AT37: =AR37*AS37 | BA37: =SUM(BA35:BA36) | BB37: =SUM(BB35:BB36) | BC37: =IF(AS37>='Dashboard (2)'!$Q$1,AS37,MIN(AS37+'Dashboard (2)'!$N$2,'Dashboard (2)'!$Q$1)) | BD37: =BB37*BC37 | BK37: =SUM(BK35:BK36) | BL37: =SUM(BL35:BL36) | BM37: =IF(BC37>='Dashboard (2)'!$Q$1,BC37,MIN(BC37+'Dashboard (2)'!$N$2,'Dashboard (2)'!$Q$1)) | BN37: =BL37*BM37
A38: CYPRUS | B38: mixed | C38: =Dashboard!C21 | D38: =Dashboard!D21 | E38: =Dashboard!E21 | F38: =Dashboard!F21 | G38: =Dashboard!G21 | H38: =Dashboard!H21 | I38: =Dashboard!I21 | K38: CV N+MD | L38: =IFERROR(N38/M38,0) | M38: =CYPRUS!D9+CYPRUS!D10 | N38: =CYPRUS!C17*CYPRUS!D9+CYPRUS!C18*CYPRUS!D10 | U38: CV N+MD | V38: =IFERROR(X38/W38,0) | W38: =CYPRUS!E9+CYPRUS!E10 | X38: =CYPRUS!D17*CYPRUS!E9+CYPRUS!D18*CYPRUS!E10 | AE38: CV N+MD | AF38: =IFERROR(AH38/AG38,0) | AG38: =CYPRUS!F9+CYPRUS!F10 | AH38: =CYPRUS!E17*CYPRUS!F9+CYPRUS!E18*CYPRUS!F10 | AO38: CV N+MD | AP38: =IFERROR(AR38/AQ38,0) | AQ38: =CYPRUS!G9+CYPRUS!G10 | AR38: =CYPRUS!F17*CYPRUS!G9+CYPRUS!F18*CYPRUS!G10 | AY38: CV N+MD | AZ38: =IFERROR(BB38/BA38,0) | BA38: =CYPRUS!H9+CYPRUS!H10 | BB38: =CYPRUS!G17*CYPRUS!H9+CYPRUS!G18*CYPRUS!H10 | BI38: CV N+MD | BJ38: =IFERROR(BL38/BK38,0) | BK38: =CYPRUS!I9+CYPRUS!I10 | BL38: =CYPRUS!H17*CYPRUS!I9+CYPRUS!H18*CYPRUS!I10
K39: LCV | L39: =CYPRUS!C20 | M39: =CYPRUS!D12 | N39: =L39*M39 | U39: LCV | V39: =CYPRUS!D20 | W39: =CYPRUS!E12 | X39: =V39*W39 | AE39: LCV | AF39: =CYPRUS!E20 | AG39: =CYPRUS!F12 | AH39: =AF39*AG39 | AO39: LCV | AP39: =CYPRUS!F20 | AQ39: =CYPRUS!G12 | AR39: =AP39*AQ39 | AY39: LCV | AZ39: =CYPRUS!G20 | BA39: =CYPRUS!H12 | BB39: =AZ39*BA39 | BI39: LCV | BJ39: =CYPRUS!H20 | BK39: =CYPRUS!I12 | BL39: =BJ39*BK39
M40: =SUM(M38:M39) | N40: =SUM(N38:N39) | O40: =CYPRUS!D26 | P40: =O40/N40 | W40: =SUM(W38:W39) | X40: =SUM(X38:X39) | Y40: =Z40/X40 | Z40: =CYPRUS!E30 | AG40: =SUM(AG38:AG39) | AH40: =SUM(AH38:AH39) | AI40: =IF(Y40>='Dashboard (2)'!$Q$1,Y40,MIN(Y40+'Dashboard (2)'!$N$2,'Dashboard (2)'!$Q$1)) | AJ40: =AH40*AI40 | AQ40: =SUM(AQ38:AQ39) | AR40: =SUM(AR38:AR39) | AS40: =IF(AI40>='Dashboard (2)'!$Q$1,AI40,MIN(AI40+'Dashboard (2)'!$N$2,'Dashboard (2)'!$Q$1)) | AT40: =AR40*AS40 | BA40: =SUM(BA38:BA39) | BB40: =SUM(BB38:BB39) | BC40: =IF(AS40>='Dashboard (2)'!$Q$1,AS40,MIN(AS40+'Dashboard (2)'!$N$2,'Dashboard (2)'!$Q$1)) | BD40: =BB40*BC40 | BK40: =SUM(BK38:BK39) | BL40: =SUM(BL38:BL39) | BM40: =IF(BC40>='Dashboard (2)'!$Q$1,BC40,MIN(BC40+'Dashboard (2)'!$N$2,'Dashboard (2)'!$Q$1)) | BN40: =BL40*BM40
...

Sheet Dashboard
A1: ISZE — FY2027 GPS Extended Target
A2: ISZE->DB level only (columns A:J). Stretch % lives on each DB tab. Everything here and on Waterfall VP is live. Dealer-level (DB->DLR) GPS% blend dropped — see WATCH. Two blocks added 22-07-2026, clearly separated by level: L:M = ISZE→DB billing actuals (reference only); O:U = DB→DLR Sales-to-Dealer, a SEPARATE track, NOT blended into A:J. See Method tab.
A3: ISZE → DB (billing / GPS% — unchanged, live) | M3: ISZE → DB (billing actuals, ref only) | P3: DB → DLR (Sales to Dealer — separate track, NOT GPS)
A4: DB | B4: Segment | C4: BP FY27 | D4: Max spend | E4: GPS % | F4: Stretch% | G4: Stretch EUR | H4: New GPS | I4: EXT TARGET | J4: Note | M4: ISZE billing FY25 (EUR) | N4: ISZE billing FY26 (EUR) | P4: Sales to Dealer FY25 (EUR) | Q4: Sales to Dealer FY26 (EUR) | R4: UIO growth FY26→FY27 | S4: Price increase FY27 | T4: Add'l growth (small, bounded 0.5–4%) | U4: Sales to Dealer FY27 TARGET (EUR) | V4: S2D Note (S2D = Sales-to-Dealer, i.e. this whole DB→DLR block) | W4: Rationale
A5: ITUK | B5: presented | C5: 6974170.1 | D5: 13051953 | E5: =C5/D5 | G5: 376073.91 | I5: =C5+G5 | J5: V4 basis (CY2027F, no +5%) — NOT rebased | L5: =G5*0.33/2 | M5: 5668549 | N5: 6658172 | P5: Skipped | W5: N/A — skipped for this round (see S2D Note).
A6: UTI | B6: presented | C6: 3098113.5 | D6: 8834692 | E6: =C6/D6 | G6: 159024.46 | I6: =C6+G6 | J6: V4 basis (CY2027F, no +5%) — NOT rebased | L6: =G6*0.33/2 | P6: Skipped | W6: N/A — skipped for this round (see S2D Note).
A7: IUK | B7: LCV | C7: =IUK!E20 | D7: =IUK!E19 | E7: =IUK!E21 | F7: =IUK!E22 | G7: =IUK!E23 | H7: =IUK!E25 | I7: =IUK!E24 | L7: =G7*0.33/2 | M7: 7154801 | N7: 5682505 | P7: 18843293 | Q7: 21418279 | R7: 0.031329134 | S7: 0.05 | T7: 0.018 | U7: 22981703 | V7: full 12/12 monthly coverage both FY25 and FY26 | W7: Historical non-UIO growth signal was +16% (above peers), ranking 7/10 strongest among the 10 comparable DBs. Banded across the peer range (0.5%-4%) by rank, floored to nearest 0.5% -> 2.5% suggested. Jerome set 2.0% instead (22-07-2026) — used as final.
A8: UMI | B8: LCV | C8: =UMI!E20 | D8: =UMI!E19 | E8: =UMI!E21 | F8: =UMI!E22 | G8: =UMI!E23 | H8: =UMI!E25 | I8: =UMI!E24 | L8: =G8*0.33/2 | M8: 5755871 | N8: 5546944 | P8: Insufficient data | S8: 0.05 | T8: 0.018 | V8: Insufficient data — KPI marks UMI DB→DLR "Internal only", no figures. | W8: N/A — insufficient data, no target set (see S2D Note).
A9: NORWAY | B9: LCV | C9: =NORWAY!E20 | D9: =NORWAY!E19 | E9: =NORWAY!E21 | F9: =NORWAY!E22 | G9: =NORWAY!E23 | H9: =NORWAY!E25 | I9: =NORWAY!E24 | L9: =G9*0.33/2 | M9: 1156859 | N9: 1454525 | P9: 3367988 | Q9: 5248795 | R9: 0.022953714 | S9: 0.05 | T9: 0.018 | U9: 5640960 | V9: FY26 annualized from 11/12 months | W9: Historical non-UIO growth signal was +62% (above peers), ranking 10/10 strongest among the 10 comparable DBs. Banded across the peer range (0.5%-4%) by rank, floored to nearest 0.5% -> 4.0% suggested. Jerome set 3.0% instead (22-07-2026) — used as final.
A10: SWEDEN | B10: LCV | C10: =SWEDEN!E20 | D10: =SWEDEN!E19 | E10: =SWEDEN!E21 | F10: =SWEDEN!E22 | G10: =SWEDEN!E23 | H10: =SWEDEN!E25 | I10: =SWEDEN!E24 | L10: =G10*0.33/2 | M10: 1233980 | N10: 1282687 | P10: 2482560 | Q10: 3154222 | R10: 0.076631529 | S10: 0.05 | T10: 0.018 | U10: 3533131 | V10: full 12/12 monthly coverage both FY25 and FY26 | W10: Historical non-UIO growth signal was +9% (above peers), ranking 6/10 strongest among the 10 comparable DBs. Banded across the peer range (0.5%-4%) by rank, floored to nearest 0.5% -> 2.0% suggested.
A11: HUNGARY | B11: LCV | C11: =HUNGARY!E20 | D11: =HUNGARY!E19 | E11: =HUNGARY!E21 | F11: =HUNGARY!E22 | G11: =HUNGARY!E23 | H11: =HUNGARY!E25 | I11: =HUNGARY!E24 | L11: =G11*0.33/2 | M11: 365622 | N11: 347456 | P11: Insufficient data | S11: 0.05 | T11: 0.018 | V11: Insufficient data — no Hungary/AutoWallis row in the KPI DB→DLR block. | W11: N/A — insufficient data, no target set (see S2D Note).
A12: FINLAND | B12: LCV | C12: =FINLAND!E20 | D12: =FINLAND!E19 | E12: =FINLAND!E21 | F12: =FINLAND!E22 | G12: =FINLAND!E23 | H12: =FINLAND!E25 | I12: =FINLAND!E24 | J12: Above ceiling at BP — no stretch | L12: =G12*0.33/2 | M12: 267986 | N12: 280753 | P12: Insufficient data | S12: 0.05 | T12: 0.018 | V12: Insufficient data — KPI DB→DLR (IMF/Nordic Auto.) stopped reporting Oct'25, 9 months stale. | W12: N/A — insufficient data, no target set (see S2D Note).
A13: ROMANIA | B13: LCV | C13: =ROMANIA!E20 | D13: =ROMANIA!E19 | E13: =ROMANIA!E21 | F13: =ROMANIA!E22 | G13: =ROMANIA!E23 | H13: =ROMANIA!E25 | I13: =ROMANIA!E24 | L13: =G13*0.33/2 | M13: 155162 | N13: 180500 | P13: 382258 | Q13: 394597 | R13: 0.12885154 | S13: 0.05 | T13: 0.018 | U13: 458894 | V13: full 12/12 monthly coverage both FY25 and FY26 | W13: Historical non-UIO growth signal was -5% (below peers), ranking 2/10 strongest among the 10 comparable DBs. Banded across the peer range (0.5%-4%) by rank, floored to nearest 0.5% -> 0.5% suggested. Jerome set 1.0% instead (22-07-2026) — used as final.
A14: DENMARK | B14: LCV | C14: =DENMARK!E20 | D14: =DENMARK!E19 | E14: =DENMARK!E21 | F14: =DENMARK!E22 | G14: =DENMARK!E23 | H14: =DENMARK!E25 | I14: =DENMARK!E24 | L14: =G14*0.33/2 | M14: 125038 | N14: 155945 | P14: 356680 | Q14: 572864 | R14: 0.11058824 | S14: 0.05 | T14: 0.018 | U14: 671653 | V14: full 12/12 monthly coverage both FY25 and FY26 | W14: Historical non-UIO growth signal was +57% (above peers), ranking 9/10 strongest among the 10 comparable DBs. Banded across the peer range (0.5%-4%) by rank, floored to nearest 0.5% -> 3.5% suggested.
A15: ICELAND | B15: LCV | C15: =ICELAND!E20 | D15: =ICELAND!E19 | E15: =ICELAND!E21 | F15: =ICELAND!E22 | G15: =ICELAND!E23 | H15: =ICELAND!E25 | I15: =ICELAND!E24 | L15: =G15*0.33/2 | M15: 76214 | N15: 89209 | P15: 209944 | Q15: 195849 | R15: 0.081280788 | S15: 0.05 | T15: 0.018 | U15: 217083 | V15: full 12/12 monthly coverage both FY25 and FY26 | W15: Historical non-UIO growth signal was -21% (below peers), ranking 1/10 strongest among the 10 comparable DBs. Banded across the peer range (0.5%-4%) by rank, floored to nearest 0.5% -> 0.5% suggested.
A16: GERMANY | B16: mixed | C16: =GERMANY!E26 | D16: =GERMANY!E25 | E16: =GERMANY!E27 | F16: =GERMANY!E28 | G16: =GERMANY!E29 | H16: =GERMANY!E31 | I16: =GERMANY!E30 | L16: =G16*0.33/2 | M16: 2614731 | N16: 2661850 | P16: Insufficient data | S16: 0.05 | T16: 0.018 | V16: Insufficient data — KPI DB→DLR (ISD) stopped reporting Mar'25, 15+ months stale. | W16: N/A — insufficient data, no target set (see S2D Note).
A17: BELGIUM | B17: mixed | C17: =BELGIUM!E26 | D17: =BELGIUM!E25 | E17: =BELGIUM!E27 | F17: =BELGIUM!E28 | G17: =BELGIUM!E29 | H17: =BELGIUM!E31 | I17: =BELGIUM!E30 | J17: Belgian vehicles only (IBX also serves NL/PL/LU) | L17: =G17*0.33/2 | M17: 2286742 | N17: 2152712 | P17: 4867562 | Q17: 6834272 | R17: 0.061474124 | S17: 0.05 | T17: 0.018 | U17: 7621476 | V17: FY25 annualized from 10/12 months | W17: Historical non-UIO growth signal was +36% (above peers), ranking 8/10 strongest among the 10 comparable DBs. Banded across the peer range (0.5%-4%) by rank, floored to nearest 0.5% -> 3.0% suggested.
A18: PORTUGAL | B18: mixed | C18: =PORTUGAL!E26 | D18: =PORTUGAL!E25 | E18: =PORTUGAL!E27 | F18: =PORTUGAL!E28 | G18: =PORTUGAL!E29 | H18: =PORTUGAL!E31 | I18: =PORTUGAL!E30 | L18: =G18*0.33/2 | M18: 1551256 | N18: 1795020 | P18: 3821463 | Q18: 4047903 | R18: 0.17147614 | S18: 0.05 | T18: 0.018 | U18: 4933599 | V18: FY25 annualized from 7/12 months | W18: Historical non-UIO growth signal was +1% (above peers), ranking 5/10 strongest among the 10 comparable DBs. Banded across the peer range (0.5%-4%) by rank, floored to nearest 0.5% -> 2.0% suggested.
A19: IRELAND | B19: mixed | C19: =IRELAND!E26 | D19: =IRELAND!E25 | E19: =IRELAND!E27 | F19: =IRELAND!E28 | G19: =IRELAND!E29 | H19: =IRELAND!E31 | I19: =IRELAND!E30 | J19: Stretch capped at 100% share | L19: =G19*0.33/2 | M19: 1201537 | N19: 1118453 | P19: 2687539 | Q19: 2833637 | R19: 0.28551596 | S19: 0.05 | T19: 0.018 | U19: 3752695 | V19: full 12/12 monthly coverage both FY25 and FY26 | W19: Historical non-UIO growth signal was -5% (below peers), ranking 3/10 strongest among the 10 comparable DBs. Banded across the peer range (0.5%-4%) by rank, floored to nearest 0.5% -> 1.0% suggested.
A20: GREECE | B20: mixed | C20: =GREECE!E26 | D20: =GREECE!E25 | E20: =GREECE!E27 | F20: =GREECE!E28 | G20: =GREECE!E29 | H20: =GREECE!E31 | I20: =GREECE!E30 | L20: =G20*0.33/2 | M20: 467826 | N20: 471586 | P20: Insufficient data | S20: 0.05 | T20: 0.018 | V20: Insufficient data — Petros Petropoulos stale since Jun'25 (12+ months). | W20: N/A — insufficient data, no target set (see S2D Note).
A21: CYPRUS | B21: mixed | C21: =CYPRUS!E26 | D21: =CYPRUS!E25 | E21: =CYPRUS!E27 | F21: =CYPRUS!E28 | G21: =CYPRUS!E29 | H21: =CYPRUS!E31 | I21: =CYPRUS!E30 | L21: =G21*0.33/2 | P21: Insufficient data | S21: 0.05 | T21: 0.018 | V21: Insufficient data — Cyprus's real distributor (Loutsios & Sons) has zero KPI data. KPI's 'MIDI' row is Italy's, not Cyprus's — excluded. | W21: N/A — insufficient data, no target set (see S2D Note).
A22: MALTA | B22: mixed | C22: =MALTA!E26 | D22: =MALTA!E25 | E22: =MALTA!E27 | F22: =MALTA!E28 | G22: =MALTA!E29 | H22: =MALTA!E31 | I22: =MALTA!E30 | L22: =G22*0.33/2 | M22: 209033 | N22: 196245 | P22: 555482 | Q22: 553873 | R22: 0.065384615 | S22: 0.05 | T22: 0.018 | U22: 610918 | V22: full 12/12 monthly coverage both FY25 and FY26 | W22: Historical non-UIO growth signal was +1% (above peers), ranking 4/10 strongest among the 10 comparable DBs. Banded across the peer range (0.5%-4%) by rank, floored to nearest 0.5% -> 1.5% suggested.
A23: TOTAL | C23: =SUM(C5:C22) | D23: =SUM(D5:D22) | E23: =C23/D23 | G23: =SUM(G5:G22) | I23: =SUM(I5:I22) | M23: =SUM(M5:M22) | N23: =SUM(N5:N22) | P23: =SUM(P5:P22) | Q23: =SUM(Q5:Q22) | S23: 0.05 | T23: 0.018 | U23: =SUM(U5:U22)
A25: Remaining stretch BEFORE GPS | C25: 952037.42
A26: GPS contribution (18 DBs) | C26: =G23
A27: Remaining stretch AFTER GPS | C27: =C25-C26 | E27: negative = over-covered = buffer
A29: WATCH
A30: • DEALER-LEVEL BLOCK DROPPED (Jerome, 17-07-2026). The KPI 'Parts Sales DB to DLR' figure is 2.2x-3.7x ISZE billing (IUK 3.58x, Denmark 3.67x, Romania 2.19x). A 35% DB margin implies 1.54x. To reconcile you would need DB margins of 54-73%. It is not the same goods marked up, so the /0.65 gross-up was invalid — and it is the same reason the DB-to-DLR GPS exceeded 100%.
A31: • BASIS SPLIT: ITUK and UTI carry their AS-PRESENTED V4 figures. V4 (2026-07-06) maps FY27 to UIO CY2027F — the off-by-one MH corrected on 17-07 — and has no +5%. Every other row is on MH's corrected basis. OPEN: rebase, or ratify V4?
A32: • V4 IUK max spend = 50,202 (CY2027F) x EUR250 = 12,550,500. This file (v3.3): 49,280 (CY2026F) x 262.50 = 12,936,000.
A33: • CEILING (v3.3): stretch is capped per distributor at the share ceiling (input Q1). FINLAND is above 100% at BP (104.9%) — no stretch, share held flat. It is the BP, not the model.
A34: • GREECE billing = payer 66, labelled 'RSA' in gps_billing_fy_ALLCUSTOMERS.csv. It is Greece, not Norway. The warranty file uses 'RSA' for Norway — joining the two on that name merges Greece's sales into Norway. Live bug at source.
A35: • BELGIUM = ISUZU BENELUX NV covering BE/NL/PL/LUX, but only the BELGIUM UIO rows are in its max spend.

Sheet Waterfall VP
P4: =SUM(V13:V30) | Q4: =T7-C16-SUM(D5:S16)-P4 | T4: check:
O5: 210000 | P5: GPS extended target | Q5: remaining stretch / SURPLUS if negative | R5: -260000 | T5: =SUM(C3:S16)
O6: MOS ISA+RSA | S6: -350000
N7: =71575+307333 | R7: Shell oil decrease | T7: 35284444
K8: 93000 | N8: SPA | S8: negative impact on volume from price increase
M9: 55000 | U9: SURPLUS vs FY2027 Plan (GPS exceeds the gap) | V9: =-Q4
J10: 280000 | K10: local DPD | M10: Overstock campaign | N10: # Original: 1,015k | U10: Q4 stays negative — the bridge needs it to close to the Plan. This is the same number, stated positively.
H11: 46000 | I11: 11940 | J11: local brake | M11: All DB's 55K€ | N11: -> IUK 71,575
G12: 75000 | H12: Genuine Share | I12: PMS | N12: -> UTI 307333 | U12: GPS extended target — per customer
F13: 60000 | G13: L/B | H13: # Original: 46,000 | I13: # Original: 11,940 | N13: -> | U13: -> ITUK (as presented, V4 basis) | V13: 376073.91
E14: 96664.198 | F14: Cab | H14: -> ITUK 376,074 | I14: -> ITUK 8,000 | N14: -> | U14: -> UTI (as presented, V4 basis) | V14: 159024.46
D15: 691851.85 | E15: UIO up | H15: -> Ireland | I15: -> Portugal | U15: -> IUK | V15: =IUK!E23
C16: 32944043 | D16: Price up 2% | H16: -> Portugal | I16: -> Ireland | U16: -> UMI | V16: =UMI!E23
H17: -> | I17: -> IUK | U17: -> NORWAY | V17: =NORWAY!E23
H18: -> | I18: -> | U18: -> SWEDEN | V18: =SWEDEN!E23
H19: -> | I19: -> | U19: -> HUNGARY | V19: =HUNGARY!E23
U20: -> FINLAND | V20: =FINLAND!E23
U21: -> ROMANIA | V21: =ROMANIA!E23
U22: -> DENMARK | V22: =DENMARK!E23
U23: -> ICELAND | V23: =ICELAND!E23
U24: -> GERMANY | V24: =GERMANY!E29
C25: FY2026 Actual | T25: FY2027 Plan | U25: -> BELGIUM | V25: =BELGIUM!E29
U26: -> PORTUGAL | V26: =PORTUGAL!E29
U27: -> IRELAND | V27: =IRELAND!E29
U28: -> GREECE | V28: =GREECE!E29
U29: -> CYPRUS | V29: =CYPRUS!E29
U30: -> MALTA | V30: =MALTA!E29
U31: GPS total | V31: =SUM(V13:V30)

Sheet IUK
A1: IUK — GPS Extended Target FY2027 · I.M. PARTS & SERVICE Limited [LCV only]
A2: ISZE->DB level only. Blue = adjustable. Dealer-level (DB->DLR) block removed: the KPI dealer figure is 2.2-3.7x ISZE billing, which cannot be a 35% margin on the same goods.
F3: Colours
F4: Firm / actual
F5: Stretch
I6: In-house FX: EUR@181, GBP@210, EUR/GBP1.16 | J6: 1.16
A7: IUK UIO (LCV)
C8: FY25 (Apr'24-Mar'25) | D8: FY26 (Apr'25-Mar'26) | E8: FY27 (Apr'26-Mar'27) | F8: FY28 (CY2027F) | G8: FY29 (CY2028F) | H8: FY30 (CY2029F) | I8: FY31 (CY2030F)
A9: LCV | C9: 48876 | D9: 47783 | E9: 49280 | F9: 50202 | G9: 51096 | H9: 51963 | I9: 52804
A10: TTL | C10: =C9 | D10: =D9 | E10: =E9 | F10: =F9 | G10: =G9 | H10: =H9 | I10: =I9
A11: Source: UIO v19 '1.UIO Overview' row 25, LCV — CY2024 / CY2025E / CY2026F mapped to FY25 / FY26 / FY27 (UIO shifted one column right).
A13: Parts Sales / Unit (EUR) | B13: FY26 base | D13: FY26 | E13: FY27 (+5%) | F13: FY28 (+price) | G13: FY29 (+price) | H13: FY30 (+price) | I13: FY31 (+price)
A14: ISZE-net EUR/unit (= DB cost) | B14: 250 | D14: =B14 | E14: =D14*1.05 | F14: =E14*(1+'Dashboard (2)'!$T$1) | G14: =F14*(1+'Dashboard (2)'!$T$1) | H14: =G14*(1+'Dashboard (2)'!$T$1) | I14: =H14*(1+'Dashboard (2)'!$T$1)
A15: LCV rate: EUR 250 ISZE-net FY26 base (same rate as the fleet study), +5% FY27 = 262.50, then + price input per year. Replaces MH chain 291.2 x 1.16 x 0.65 = 219.56 (FX and margin applied twice).
A17: ISZE -> IUK wholesale (ISZE-net EUR) << EXTENDED TARGET IS SET HERE
C18: FY25 (Apr'24-Mar'25) | D18: FY26 (Apr'25-Mar'26) | E18: FY27 (Apr'26-Mar'27) | F18: FY28 | G18: FY29 | H18: FY30 | I18: FY31
A19: Max spend / potential (= UIO x ISZE-net rate) | C19: =C9*$D$14 | D19: =D9*$D$14 | E19: =E9*$E$14 | F19: =F9*F14 | G19: =G9*G14 | H19: =H9*H14 | I19: =I9*I14
A20: Actual (ISZE billing) · FY27 = BP target | C20: 7297065.7 | D20: 5895486.2 | E20: 6062956.5
A21: Share (GPS, ISZE level) | C21: =C20/C19 | D21: =D20/D19 | E21: =E20/E19
A22: Stretch (%) = global input, capped at ceiling | C22: 0 | D22: 0 | E22: =MAX(0,MIN('Dashboard (2)'!$N$1,'Dashboard (2)'!$Q$1-E21))
A23: Stretch amount (= max spend x stretch%) | C23: =C19*C22 | D23: =D19*D22 | E23: =E19*E22
A24: TTL amount (= actual + stretch) << EXTENDED TARGET | C24: =C20+C23 | D24: =D20+D23 | E24: =E20+E23
A25: Share (new) | C25: =C24/C19 | D25: =D24/D19 | E25: =E24/E19
A26: Source: 00_derived/gps_billing_fy_ALLCUSTOMERS.csv canonical 'IUK' (net_gps, GPS-audited, FY-aligned, lubricants included).
A27: FY28-FY31 max spend (row 19, cols F:I) feeds Dashboard (2). FY27 actual cell E20 = BP reviewed 24-04-2026.
A28: IUK -> DEALER level (DB->DLR) — MH method (35% DB margin gross-up)
C29: FY25 (Apr'24-Mar'25) | D29: FY26 (Apr'25-Mar'26) | E29: FY27 (Apr'26-Mar'27)
A30: Parts Sales DB-to-DLR (actual) · KPI Master File june 2026.xlsx | C30: 18843293 | D30: 21418279 | F30: FY25 12/12 mo · FY26 12/12 mo
A31: DB margin % (MH assumption — same as testcase B15) | B31: 0.35
A32: Stretch amount at dealer (= ISZE stretch / (1 − margin)) · MH E29 | E32: =-E23/(B31-1)
A33: FY27 AMOUNT TO REACH at dealer (= FY26 actual + dealer stretch) | E33: =IF(OR(D30="",D30="no KPI data"),"no KPI data",D30+E32)
A34: MH method (same factors as ISZE_IUK_Sales_Share_Stretch_TESTCASE): DB margin 35% → dealer stretch = ISZE stretch / (1−0.35) = ISZE stretch / 0.65 (identical to MH E29 = −E41/(0.35−1)). FY27 amount to reach = FY26 dealer actual + dealer stretch. Observed dealer/ISZE often ≠ 1.54x — not used for the conversion.
A37: GAPS / open items
A38: 1. LCV rate: MH's 291.2 chain ends at 219.5648. The identical GBP400 under the v9 CV convention ends at 296. Same source, two conventions — carried as instructed.

Sheet UMI
A1: UMI — GPS Extended Target FY2027 · UNIVERSAL MOTORS ISRAEL LTD [LCV only]
A2: ISZE->DB level only. Blue = adjustable. Dealer-level (DB->DLR) block removed: the KPI dealer figure is 2.2-3.7x ISZE billing, which cannot be a 35% margin on the same goods.
F3: Colours
F4: Firm / actual
F5: Stretch
I6: In-house FX: EUR@181, GBP@210, EUR/GBP1.16 | J6: 1.16
A7: UMI UIO (LCV)
C8: FY25 (Apr'24-Mar'25) | D8: FY26 (Apr'25-Mar'26) | E8: FY27 (Apr'26-Mar'27) | F8: FY28 (CY2027F) | G8: FY29 (CY2028F) | H8: FY30 (CY2029F) | I8: FY31 (CY2030F)
A9: LCV | C9: 18349 | D9: 18542 | E9: 18886 | F9: 19319 | G9: 19669 | H9: 20009 | I9: 20339
A10: TTL | C10: =C9 | D10: =D9 | E10: =E9 | F10: =F9 | G10: =G9 | H10: =H9 | I10: =I9
A11: Source: UIO v19 '1.UIO Overview' row 9, LCV — CY2024 / CY2025E / CY2026F mapped to FY25 / FY26 / FY27 (UIO shifted one column right).
A13: Parts Sales / Unit (EUR) | B13: FY26 base | D13: FY26 | E13: FY27 (+5%) | F13: FY28 (+price) | G13: FY29 (+price) | H13: FY30 (+price) | I13: FY31 (+price)
A14: ISZE-net EUR/unit (= DB cost) | B14: 250 | D14: =B14 | E14: =D14*1.05 | F14: =E14*(1+'Dashboard (2)'!$T$1) | G14: =F14*(1+'Dashboard (2)'!$T$1) | H14: =G14*(1+'Dashboard (2)'!$T$1) | I14: =H14*(1+'Dashboard (2)'!$T$1)
A15: LCV rate: EUR 250 ISZE-net FY26 base (same rate as the fleet study), +5% FY27 = 262.50, then + price input per year. Replaces MH chain 291.2 x 1.16 x 0.65 = 219.56 (FX and margin applied twice).
A17: ISZE -> UMI wholesale (ISZE-net EUR) << EXTENDED TARGET IS SET HERE
C18: FY25 (Apr'24-Mar'25) | D18: FY26 (Apr'25-Mar'26) | E18: FY27 (Apr'26-Mar'27) | F18: FY28 | G18: FY29 | H18: FY30 | I18: FY31
A19: Max spend / potential (= UIO x ISZE-net rate) | C19: =C9*$D$14 | D19: =D9*$D$14 | E19: =E9*$E$14 | F19: =F9*F14 | G19: =G9*G14 | H19: =H9*H14 | I19: =I9*I14
A20: Actual (ISZE billing) · FY27 = BP target | C20: 2739215.7 | D20: 2445335.2 | E20: 2973279.3
A21: Share (GPS, ISZE level) | C21: =C20/C19 | D21: =D20/D19 | E21: =E20/E19
A22: Stretch (%) = global input, capped at ceiling | C22: 0 | D22: 0 | E22: =MAX(0,MIN('Dashboard (2)'!$N$1,'Dashboard (2)'!$Q$1-E21))
A23: Stretch amount (= max spend x stretch%) | C23: =C19*C22 | D23: =D19*D22 | E23: =E19*E22
A24: TTL amount (= actual + stretch) << EXTENDED TARGET | C24: =C20+C23 | D24: =D20+D23 | E24: =E20+E23
A25: Share (new) | C25: =C24/C19 | D25: =D24/D19 | E25: =E24/E19
A26: Source: 00_derived/gps_billing_fy_ALLCUSTOMERS.csv canonical 'UMI' (net_gps, GPS-audited, FY-aligned, lubricants included).
A27: FY28-FY31 max spend (row 19, cols F:I) feeds Dashboard (2). FY27 actual cell E20 = BP reviewed 24-04-2026.
A28: UMI -> DEALER level (DB->DLR) — MH method (35% DB margin gross-up)
C29: FY25 (Apr'24-Mar'25) | D29: FY26 (Apr'25-Mar'26) | E29: FY27 (Apr'26-Mar'27)
A30: Parts Sales DB-to-DLR (actual) · KPI Master File june 2026.xlsx | F30: FY25 0/12 mo · FY26 0/12 mo
A31: DB margin % (MH assumption — same as testcase B15) | B31: 0.35
A32: Stretch amount at dealer (= ISZE stretch / (1 − margin)) · MH E29 | E32: =-E23/(B31-1)
A33: FY27 AMOUNT TO REACH at dealer (= FY26 actual + dealer stretch) | E33: =IF(OR(D30="",D30="no KPI data"),"no KPI data",D30+E32)
A34: MH method (same factors as ISZE_IUK_Sales_Share_Stretch_TESTCASE): DB margin 35% → dealer stretch = ISZE stretch / (1−0.35) = ISZE stretch / 0.65 (identical to MH E29 = −E41/(0.35−1)). FY27 amount to reach = FY26 dealer actual + dealer stretch. Observed dealer/ISZE often ≠ 1.54x — not used for the conversion.
A37: GAPS / open items
A38: 1. LCV rate: MH's 291.2 chain ends at 219.5648. The identical GBP400 under the v9 CV convention ends at 296. Same source, two conventions — carried as instructed.
A39: 2. Dealer-level data is 'Internal only' in the KPI Master — irrelevant now that the DB-to-DLR block is dropped.

Sheet NORWAY
A1: NORWAY — GPS Extended Target FY2027 · RUTEBILEIERNES STANDARDISERING AS [LCV only]
A2: ISZE->DB level only. Blue = adjustable. Dealer-level (DB->DLR) block removed: the KPI dealer figure is 2.2-3.7x ISZE billing, which cannot be a 35% margin on the same goods.
F3: Colours
F4: Firm / actual
F5: Stretch
I6: In-house FX: EUR@181, GBP@210, EUR/GBP1.16 | J6: 1.16
A7: NORWAY UIO (LCV)
C8: FY25 (Apr'24-Mar'25) | D8: FY26 (Apr'25-Mar'26) | E8: FY27 (Apr'26-Mar'27) | F8: FY28 (CY2027F) | G8: FY29 (CY2028F) | H8: FY30 (CY2029F) | I8: FY31 (CY2030F)
A9: LCV | C9: 8237 | D9: 7929 | E9: 8111 | F9: 8218 | G9: 8426 | H9: 8628 | I9: 8824
A10: TTL | C10: =C9 | D10: =D9 | E10: =E9 | F10: =F9 | G10: =G9 | H10: =H9 | I10: =I9
A11: Source: UIO v19 '1.UIO Overview' row 15, LCV — CY2024 / CY2025E / CY2026F mapped to FY25 / FY26 / FY27 (UIO shifted one column right).
A13: Parts Sales / Unit (EUR) | B13: FY26 base | D13: FY26 | E13: FY27 (+5%) | F13: FY28 (+price) | G13: FY29 (+price) | H13: FY30 (+price) | I13: FY31 (+price)
A14: ISZE-net EUR/unit (= DB cost) | B14: 250 | D14: =B14 | E14: =D14*1.05 | F14: =E14*(1+'Dashboard (2)'!$T$1) | G14: =F14*(1+'Dashboard (2)'!$T$1) | H14: =G14*(1+'Dashboard (2)'!$T$1) | I14: =H14*(1+'Dashboard (2)'!$T$1)
A15: LCV rate: EUR 250 ISZE-net FY26 base (same rate as the fleet study), +5% FY27 = 262.50, then + price input per year. Replaces MH chain 291.2 x 1.16 x 0.65 = 219.56 (FX and margin applied twice).
A17: ISZE -> NORWAY wholesale (ISZE-net EUR) << EXTENDED TARGET IS SET HERE
C18: FY25 (Apr'24-Mar'25) | D18: FY26 (Apr'25-Mar'26) | E18: FY27 (Apr'26-Mar'27) | F18: FY28 | G18: FY29 | H18: FY30 | I18: FY31
A19: Max spend / potential (= UIO x ISZE-net rate) | C19: =C9*$D$14 | D19: =D9*$D$14 | E19: =E9*$E$14 | F19: =F9*F14 | G19: =G9*G14 | H19: =H9*H14 | I19: =I9*I14
A20: Actual (ISZE billing) · FY27 = BP target | C20: 1162750.7 | D20: 1471434.2 | E20: 1764799.8
A21: Share (GPS, ISZE level) | C21: =C20/C19 | D21: =D20/D19 | E21: =E20/E19
A22: Stretch (%) = global input, capped at ceiling | C22: 0 | D22: 0 | E22: =MAX(0,MIN('Dashboard (2)'!$N$1,'Dashboard (2)'!$Q$1-E21))
A23: Stretch amount (= max spend x stretch%) | C23: =C19*C22 | D23: =D19*D22 | E23: =E19*E22
A24: TTL amount (= actual + stretch) << EXTENDED TARGET | C24: =C20+C23 | D24: =D20+D23 | E24: =E20+E23
A25: Share (new) | C25: =C24/C19 | D25: =D24/D19 | E25: =E24/E19
A26: Source: 00_derived/gps_billing_fy_ALLCUSTOMERS.csv canonical 'Norway' (net_gps, GPS-audited, FY-aligned, lubricants included).
A27: FY28-FY31 max spend (row 19, cols F:I) feeds Dashboard (2). FY27 actual cell E20 = BP reviewed 24-04-2026.
A28: NORWAY -> DEALER level (DB->DLR) — MH method (35% DB margin gross-up)
C29: FY25 (Apr'24-Mar'25) | D29: FY26 (Apr'25-Mar'26) | E29: FY27 (Apr'26-Mar'27)
A30: Parts Sales DB-to-DLR (actual) · KPI Master File june 2026.xlsx | C30: 3367988 | D30: 4811395 | F30: FY25 12/12 mo · FY26 11/12 mo
A31: DB margin % (MH assumption — same as testcase B15) | B31: 0.35
A32: Stretch amount at dealer (= ISZE stretch / (1 − margin)) · MH E29 | E32: =-E23/(B31-1)
A33: FY27 AMOUNT TO REACH at dealer (= FY26 actual + dealer stretch) | E33: =IF(OR(D30="",D30="no KPI data"),"no KPI data",D30+E32)
A34: MH method (same factors as ISZE_IUK_Sales_Share_Stretch_TESTCASE): DB margin 35% → dealer stretch = ISZE stretch / (1−0.35) = ISZE stretch / 0.65 (identical to MH E29 = −E41/(0.35−1)). FY27 amount to reach = FY26 dealer actual + dealer stretch. Observed dealer/ISZE often ≠ 1.54x — not used for the conversion.
A37: GAPS / open items
A38: 1. LCV rate: MH's 291.2 chain ends at 219.5648. The identical GBP400 under the v9 CV convention ends at 296. Same source, two conventions — carried as instructed.
A39: 2. Billing = payer 86 only. Payer 66 (labelled 'RSA' in the billing file) is GREECE, not Norway — confirmed by Jerome 17-07-2026. Do not join billing to warranty on the name 'RSA'.

Sheet SWEDEN
A1: SWEDEN — GPS Extended Target FY2027 · ISUZU SVERIGE AB [LCV only]
A2: ISZE->DB level only. Blue = adjustable. Dealer-level (DB->DLR) block removed: the KPI dealer figure is 2.2-3.7x ISZE billing, which cannot be a 35% margin on the same goods.
F3: Colours
F4: Firm / actual
F5: Stretch
I6: In-house FX: EUR@181, GBP@210, EUR/GBP1.16 | J6: 1.16
A7: SWEDEN UIO (LCV)
C8: FY25 (Apr'24-Mar'25) | D8: FY26 (Apr'25-Mar'26) | E8: FY27 (Apr'26-Mar'27) | F8: FY28 (CY2027F) | G8: FY29 (CY2028F) | H8: FY30 (CY2029F) | I8: FY31 (CY2030F)
A9: LCV | C9: 7221 | D9: 8443 | E9: 9090 | F9: 9737 | G9: 10320 | H9: 10885 | I9: 11433
A10: TTL | C10: =C9 | D10: =D9 | E10: =E9 | F10: =F9 | G10: =G9 | H10: =H9 | I10: =I9
A11: Source: UIO v19 '1.UIO Overview' row 18, LCV — CY2024 / CY2025E / CY2026F mapped to FY25 / FY26 / FY27 (UIO shifted one column right).
A13: Parts Sales / Unit (EUR) | B13: FY26 base | D13: FY26 | E13: FY27 (+5%) | F13: FY28 (+price) | G13: FY29 (+price) | H13: FY30 (+price) | I13: FY31 (+price)
A14: ISZE-net EUR/unit (= DB cost) | B14: 250 | D14: =B14 | E14: =D14*1.05 | F14: =E14*(1+'Dashboard (2)'!$T$1) | G14: =F14*(1+'Dashboard (2)'!$T$1) | H14: =G14*(1+'Dashboard (2)'!$T$1) | I14: =H14*(1+'Dashboard (2)'!$T$1)
A15: LCV rate: EUR 250 ISZE-net FY26 base (same rate as the fleet study), +5% FY27 = 262.50, then + price input per year. Replaces MH chain 291.2 x 1.16 x 0.65 = 219.56 (FX and margin applied twice).
A17: ISZE -> SWEDEN wholesale (ISZE-net EUR) << EXTENDED TARGET IS SET HERE
C18: FY25 (Apr'24-Mar'25) | D18: FY26 (Apr'25-Mar'26) | E18: FY27 (Apr'26-Mar'27) | F18: FY28 | G18: FY29 | H18: FY30 | I18: FY31
A19: Max spend / potential (= UIO x ISZE-net rate) | C19: =C9*$D$14 | D19: =D9*$D$14 | E19: =E9*$E$14 | F19: =F9*F14 | G19: =G9*G14 | H19: =H9*H14 | I19: =I9*I14
A20: Actual (ISZE billing) · FY27 = BP target | C20: 1215958.3 | D20: 1298276 | E20: 1464302.3
A21: Share (GPS, ISZE level) | C21: =C20/C19 | D21: =D20/D19 | E21: =E20/E19
A22: Stretch (%) = global input, capped at ceiling | C22: 0 | D22: 0 | E22: =MAX(0,MIN('Dashboard (2)'!$N$1,'Dashboard (2)'!$Q$1-E21))
A23: Stretch amount (= max spend x stretch%) | C23: =C19*C22 | D23: =D19*D22 | E23: =E19*E22
A24: TTL amount (= actual + stretch) << EXTENDED TARGET | C24: =C20+C23 | D24: =D20+D23 | E24: =E20+E23
A25: Share (new) | C25: =C24/C19 | D25: =D24/D19 | E25: =E24/E19
A26: Source: 00_derived/gps_billing_fy_ALLCUSTOMERS.csv canonical 'Sverige' (net_gps, GPS-audited, FY-aligned, lubricants included).
A27: FY28-FY31 max spend (row 19, cols F:I) feeds Dashboard (2). FY27 actual cell E20 = BP reviewed 24-04-2026.
A28: SWEDEN -> DEALER level (DB->DLR) — MH method (35% DB margin gross-up)
C29: FY25 (Apr'24-Mar'25) | D29: FY26 (Apr'25-Mar'26) | E29: FY27 (Apr'26-Mar'27)
